2018-11-15 10:53:19,979 root:main:195  > CRITICAL: 
 --- Application started & 'main' was called. This is not really Critical. --- 

2018-11-15 10:53:20,010 root:main:202  > INFO: PNS App Services IP Address White List:
2018-11-15 10:53:20,010 root:main:203  > INFO: ['35.162.219.50', '52.77.93.214', '13.228.1.86', '54.169.137.81', '127.0.0.1']
2018-11-15 10:53:21,057 werkzeug:_log:88   > INFO:  * Running on http://0.0.0.0:5001/ (Press CTRL+C to quit)
2018-11-15 10:53:33,621 root:push_plate_no:397  > ERROR: Failed to connect to ftp server using given info host=127.0.0.1 , username=hadi , password=hadi123 ,folder=vehicle_plate , 530-User cannot log in.
 Win32 error:   The user name or password is incorrect. 
 Error details: An error occurred during the authentication process.
530 End
2018-11-15 10:53:33,621 root:push_plate_no:402  > INFO: 
2018-11-15 10:53:33,621 root:push_plate_no:403  > INFO: --- v1_push plate no ---
2018-11-15 10:53:33,621 root:push_plate_no:404  > INFO: Plateno=PUTRAJAYA123<<>>Camera_sn=00000000-00000000<<>>Maxpark_camera_id=1000
2018-11-15 10:53:33,621 root:push_plate_no:406  > INFO: Communicating with Comms Module
2018-11-15 10:53:33,621 LA_Commons:calculate_checksum:43   > INFO: Checksum (numerical= 0x62
2018-11-15 10:53:38,629 PUSH_plate_no:push_plate_no:144  > WARNING: Timeout. Close connection
2018-11-15 10:53:38,629 flask.app:log_exception:1761 > ERROR: Exception on /localagent/v1/push_plate_no [POST]
Traceback (most recent call last):
  File "C:\Users\Abdul Hadi\PycharmProjects\LPRLA\venv\lib\site-packages\flask\app.py", line 2292, in wsgi_app
    response = self.full_dispatch_request()
  File "C:\Users\Abdul Hadi\PycharmProjects\LPRLA\venv\lib\site-packages\flask\app.py", line 1815, in full_dispatch_request
    rv = self.handle_user_exception(e)
  File "C:\Users\Abdul Hadi\PycharmProjects\LPRLA\venv\lib\site-packages\flask\app.py", line 1718, in handle_user_exception
    reraise(exc_type, exc_value, tb)
  File "C:\Users\Abdul Hadi\PycharmProjects\LPRLA\venv\lib\site-packages\flask\_compat.py", line 35, in reraise
    raise value
  File "C:\Users\Abdul Hadi\PycharmProjects\LPRLA\venv\lib\site-packages\flask\app.py", line 1813, in full_dispatch_request
    rv = self.dispatch_request()
  File "C:\Users\Abdul Hadi\PycharmProjects\LPRLA\venv\lib\site-packages\flask\app.py", line 1799, in dispatch_request
    return self.view_functions[rule.endpoint](**req.view_args)
  File "C:/Users/Abdul Hadi/PycharmProjects/LPRLA/lpr_localagent.py", line 412, in push_plate_no
    plate_no,maxpark_cam_id)
  File "C:\Users\Abdul Hadi\PycharmProjects\LPRLA\PUSH_plate_no.py", line 156, in push_plate_no
    RECV_MSG = [ord(c) for c in msg]
UnboundLocalError: local variable 'msg' referenced before assignment
2018-11-15 10:53:38,629 werkzeug:_log:88   > INFO: 127.0.0.1 - - [15/Nov/2018 10:53:38] "POST /localagent/v1/push_plate_no HTTP/1.1" 500 -
2018-11-15 10:56:00,245 root:main:195  > CRITICAL: 
 --- Application started & 'main' was called. This is not really Critical. --- 

2018-11-15 10:56:00,245 root:main:202  > INFO: PNS App Services IP Address White List:
2018-11-15 10:56:00,245 root:main:203  > INFO: ['35.162.219.50', '52.77.93.214', '13.228.1.86', '54.169.137.81', '127.0.0.1']
2018-11-15 10:56:01,304 werkzeug:_log:88   > INFO:  * Running on http://0.0.0.0:5001/ (Press CTRL+C to quit)
2018-11-15 10:56:08,691 root:push_plate_no:397  > ERROR: Failed to connect to ftp server using given info host=127.0.0.1 , username=hadi , password=hadi123 ,folder=vehicle_plate , 530-User cannot log in.
 Win32 error:   The user name or password is incorrect. 
 Error details: An error occurred during the authentication process.
530 End
2018-11-15 10:56:08,695 root:push_plate_no:402  > INFO: 
2018-11-15 10:56:08,695 root:push_plate_no:403  > INFO: --- v1_push plate no ---
2018-11-15 10:56:08,695 root:push_plate_no:404  > INFO: Plateno=PUTRAJAYA123<<>>Camera_sn=00000000-00000000<<>>Maxpark_camera_id=1000
2018-11-15 10:56:08,695 root:push_plate_no:406  > INFO: Communicating with Comms Module
2018-11-15 10:56:08,695 LA_Commons:calculate_checksum:43   > INFO: Checksum (numerical= 0x6a
2018-11-15 10:56:13,705 PUSH_plate_no:push_plate_no:144  > WARNING: Timeout. Close connection
2018-11-15 10:56:13,705 flask.app:log_exception:1761 > ERROR: Exception on /localagent/v1/push_plate_no [POST]
Traceback (most recent call last):
  File "C:\Users\Abdul Hadi\PycharmProjects\LPRLA\venv\lib\site-packages\flask\app.py", line 2292, in wsgi_app
    response = self.full_dispatch_request()
  File "C:\Users\Abdul Hadi\PycharmProjects\LPRLA\venv\lib\site-packages\flask\app.py", line 1815, in full_dispatch_request
    rv = self.handle_user_exception(e)
  File "C:\Users\Abdul Hadi\PycharmProjects\LPRLA\venv\lib\site-packages\flask\app.py", line 1718, in handle_user_exception
    reraise(exc_type, exc_value, tb)
  File "C:\Users\Abdul Hadi\PycharmProjects\LPRLA\venv\lib\site-packages\flask\_compat.py", line 35, in reraise
    raise value
  File "C:\Users\Abdul Hadi\PycharmProjects\LPRLA\venv\lib\site-packages\flask\app.py", line 1813, in full_dispatch_request
    rv = self.dispatch_request()
  File "C:\Users\Abdul Hadi\PycharmProjects\LPRLA\venv\lib\site-packages\flask\app.py", line 1799, in dispatch_request
    return self.view_functions[rule.endpoint](**req.view_args)
  File "C:/Users/Abdul Hadi/PycharmProjects/LPRLA/lpr_localagent.py", line 412, in push_plate_no
    plate_no,maxpark_cam_id)
  File "C:\Users\Abdul Hadi\PycharmProjects\LPRLA\PUSH_plate_no.py", line 156, in push_plate_no
    RECV_MSG = [ord(c) for c in msg]
UnboundLocalError: local variable 'msg' referenced before assignment
2018-11-15 10:56:13,709 werkzeug:_log:88   > INFO: 127.0.0.1 - - [15/Nov/2018 10:56:13] "POST /localagent/v1/push_plate_no HTTP/1.1" 500 -
2018-11-15 10:56:52,755 root:main:195  > CRITICAL: 
 --- Application started & 'main' was called. This is not really Critical. --- 

2018-11-15 10:56:52,755 root:main:202  > INFO: PNS App Services IP Address White List:
2018-11-15 10:56:52,755 root:main:203  > INFO: ['35.162.219.50', '52.77.93.214', '13.228.1.86', '54.169.137.81', '127.0.0.1']
2018-11-15 10:56:53,836 werkzeug:_log:88   > INFO:  * Running on http://0.0.0.0:5001/ (Press CTRL+C to quit)
2018-11-15 10:56:57,093 root:push_plate_no:397  > ERROR: Failed to connect to ftp server using given info host=127.0.0.1 , username=hadi , password=hadi123 ,folder=vehicle_plate , 530-User cannot log in.
 Win32 error:   The user name or password is incorrect. 
 Error details: An error occurred during the authentication process.
530 End
2018-11-15 10:56:57,093 root:push_plate_no:402  > INFO: 
2018-11-15 10:56:57,093 root:push_plate_no:403  > INFO: --- v1_push plate no ---
2018-11-15 10:56:57,093 root:push_plate_no:404  > INFO: Plateno=PUTRAJAYA123<<>>Camera_sn=00000000-00000000<<>>Maxpark_camera_id=1000
2018-11-15 10:56:57,093 root:push_plate_no:406  > INFO: Communicating with Comms Module
2018-11-15 10:56:57,093 LA_Commons:calculate_checksum:43   > INFO: Checksum (numerical= 0x6b
2018-11-15 10:57:02,097 PUSH_plate_no:push_plate_no:144  > WARNING: Timeout. Close connection
2018-11-15 10:57:02,097 flask.app:log_exception:1761 > ERROR: Exception on /localagent/v1/push_plate_no [POST]
Traceback (most recent call last):
  File "C:\Users\Abdul Hadi\PycharmProjects\LPRLA\venv\lib\site-packages\flask\app.py", line 2292, in wsgi_app
    response = self.full_dispatch_request()
  File "C:\Users\Abdul Hadi\PycharmProjects\LPRLA\venv\lib\site-packages\flask\app.py", line 1815, in full_dispatch_request
    rv = self.handle_user_exception(e)
  File "C:\Users\Abdul Hadi\PycharmProjects\LPRLA\venv\lib\site-packages\flask\app.py", line 1718, in handle_user_exception
    reraise(exc_type, exc_value, tb)
  File "C:\Users\Abdul Hadi\PycharmProjects\LPRLA\venv\lib\site-packages\flask\_compat.py", line 35, in reraise
    raise value
  File "C:\Users\Abdul Hadi\PycharmProjects\LPRLA\venv\lib\site-packages\flask\app.py", line 1813, in full_dispatch_request
    rv = self.dispatch_request()
  File "C:\Users\Abdul Hadi\PycharmProjects\LPRLA\venv\lib\site-packages\flask\app.py", line 1799, in dispatch_request
    return self.view_functions[rule.endpoint](**req.view_args)
  File "C:/Users/Abdul Hadi/PycharmProjects/LPRLA/lpr_localagent.py", line 412, in push_plate_no
    plate_no,maxpark_cam_id)
  File "C:\Users\Abdul Hadi\PycharmProjects\LPRLA\PUSH_plate_no.py", line 156, in push_plate_no
    RECV_MSG = [ord(c) for c in msg]
UnboundLocalError: local variable 'msg' referenced before assignment
2018-11-15 10:57:02,101 werkzeug:_log:88   > INFO: 127.0.0.1 - - [15/Nov/2018 10:57:02] "POST /localagent/v1/push_plate_no HTTP/1.1" 500 -
2018-11-15 10:57:39,509 root:main:195  > CRITICAL: 
 --- Application started & 'main' was called. This is not really Critical. --- 

2018-11-15 10:57:39,513 root:main:202  > INFO: PNS App Services IP Address White List:
2018-11-15 10:57:39,513 root:main:203  > INFO: ['35.162.219.50', '52.77.93.214', '13.228.1.86', '54.169.137.81', '127.0.0.1']
2018-11-15 10:57:40,625 werkzeug:_log:88   > INFO:  * Running on http://0.0.0.0:5001/ (Press CTRL+C to quit)
2018-11-15 10:57:43,220 root:push_plate_no:397  > ERROR: Failed to connect to ftp server using given info host=127.0.0.1 , username=hadi , password=hadi123 ,folder=vehicle_plate , 530-User cannot log in.
 Win32 error:   The user name or password is incorrect. 
 Error details: An error occurred during the authentication process.
530 End
2018-11-15 10:57:43,220 root:push_plate_no:402  > INFO: 
2018-11-15 10:57:43,220 root:push_plate_no:403  > INFO: --- v1_push plate no ---
2018-11-15 10:57:43,220 root:push_plate_no:404  > INFO: Plateno=PUTRAJAYA123<<>>Camera_sn=00000000-00000000<<>>Maxpark_camera_id=1000
2018-11-15 10:57:43,220 root:push_plate_no:406  > INFO: Communicating with Comms Module
2018-11-15 10:57:43,220 LA_Commons:calculate_checksum:43   > INFO: Checksum (numerical= 0x68
2018-11-15 10:57:48,227 PUSH_plate_no:push_plate_no:144  > WARNING: Timeout. Close connection
2018-11-15 10:57:48,227 flask.app:log_exception:1761 > ERROR: Exception on /localagent/v1/push_plate_no [POST]
Traceback (most recent call last):
  File "C:\Users\Abdul Hadi\PycharmProjects\LPRLA\venv\lib\site-packages\flask\app.py", line 2292, in wsgi_app
    response = self.full_dispatch_request()
  File "C:\Users\Abdul Hadi\PycharmProjects\LPRLA\venv\lib\site-packages\flask\app.py", line 1815, in full_dispatch_request
    rv = self.handle_user_exception(e)
  File "C:\Users\Abdul Hadi\PycharmProjects\LPRLA\venv\lib\site-packages\flask\app.py", line 1718, in handle_user_exception
    reraise(exc_type, exc_value, tb)
  File "C:\Users\Abdul Hadi\PycharmProjects\LPRLA\venv\lib\site-packages\flask\_compat.py", line 35, in reraise
    raise value
  File "C:\Users\Abdul Hadi\PycharmProjects\LPRLA\venv\lib\site-packages\flask\app.py", line 1813, in full_dispatch_request
    rv = self.dispatch_request()
  File "C:\Users\Abdul Hadi\PycharmProjects\LPRLA\venv\lib\site-packages\flask\app.py", line 1799, in dispatch_request
    return self.view_functions[rule.endpoint](**req.view_args)
  File "C:/Users/Abdul Hadi/PycharmProjects/LPRLA/lpr_localagent.py", line 412, in push_plate_no
    plate_no,maxpark_cam_id)
  File "C:\Users\Abdul Hadi\PycharmProjects\LPRLA\PUSH_plate_no.py", line 156, in push_plate_no
    RECV_MSG = [ord(c) for c in msg]
UnboundLocalError: local variable 'msg' referenced before assignment
2018-11-15 10:57:48,231 werkzeug:_log:88   > INFO: 127.0.0.1 - - [15/Nov/2018 10:57:48] "POST /localagent/v1/push_plate_no HTTP/1.1" 500 -
2018-11-15 10:58:40,743 root:main:195  > CRITICAL: 
 --- Application started & 'main' was called. This is not really Critical. --- 

2018-11-15 10:58:40,743 root:main:202  > INFO: PNS App Services IP Address White List:
2018-11-15 10:58:40,743 root:main:203  > INFO: ['35.162.219.50', '52.77.93.214', '13.228.1.86', '54.169.137.81', '127.0.0.1']
2018-11-15 10:58:42,085 werkzeug:_log:88   > INFO:  * Running on http://0.0.0.0:5001/ (Press CTRL+C to quit)
2018-11-15 10:58:46,707 root:main:195  > CRITICAL: 
 --- Application started & 'main' was called. This is not really Critical. --- 

2018-11-15 10:58:46,707 root:main:202  > INFO: PNS App Services IP Address White List:
2018-11-15 10:58:46,707 root:main:203  > INFO: ['35.162.219.50', '52.77.93.214', '13.228.1.86', '54.169.137.81', '127.0.0.1']
2018-11-15 10:58:47,746 werkzeug:_log:88   > INFO:  * Running on http://0.0.0.0:5001/ (Press CTRL+C to quit)
2018-11-15 10:58:49,950 root:push_plate_no:397  > ERROR: Failed to connect to ftp server using given info host=127.0.0.1 , username=hadi , password=hadi123 ,folder=vehicle_plate , 530-User cannot log in.
 Win32 error:   The user name or password is incorrect. 
 Error details: An error occurred during the authentication process.
530 End
2018-11-15 10:58:49,950 root:push_plate_no:402  > INFO: 
2018-11-15 10:58:49,950 root:push_plate_no:403  > INFO: --- v1_push plate no ---
2018-11-15 10:58:49,950 root:push_plate_no:404  > INFO: Plateno=PUTRAJAYA123<<>>Camera_sn=00000000-00000000<<>>Maxpark_camera_id=1000
2018-11-15 10:58:49,950 root:push_plate_no:406  > INFO: Communicating with Comms Module
2018-11-15 10:58:49,950 LA_Commons:calculate_checksum:43   > INFO: Checksum (numerical= 0x6b
2018-11-15 10:58:54,965 PUSH_plate_no:push_plate_no:144  > WARNING: Timeout. Close connection
2018-11-15 10:58:54,965 flask.app:log_exception:1761 > ERROR: Exception on /localagent/v1/push_plate_no [POST]
Traceback (most recent call last):
  File "C:\Users\Abdul Hadi\PycharmProjects\LPRLA\venv\lib\site-packages\flask\app.py", line 2292, in wsgi_app
    response = self.full_dispatch_request()
  File "C:\Users\Abdul Hadi\PycharmProjects\LPRLA\venv\lib\site-packages\flask\app.py", line 1815, in full_dispatch_request
    rv = self.handle_user_exception(e)
  File "C:\Users\Abdul Hadi\PycharmProjects\LPRLA\venv\lib\site-packages\flask\app.py", line 1718, in handle_user_exception
    reraise(exc_type, exc_value, tb)
  File "C:\Users\Abdul Hadi\PycharmProjects\LPRLA\venv\lib\site-packages\flask\_compat.py", line 35, in reraise
    raise value
  File "C:\Users\Abdul Hadi\PycharmProjects\LPRLA\venv\lib\site-packages\flask\app.py", line 1813, in full_dispatch_request
    rv = self.dispatch_request()
  File "C:\Users\Abdul Hadi\PycharmProjects\LPRLA\venv\lib\site-packages\flask\app.py", line 1799, in dispatch_request
    return self.view_functions[rule.endpoint](**req.view_args)
  File "C:/Users/Abdul Hadi/PycharmProjects/LPRLA/lpr_localagent.py", line 412, in push_plate_no
    plate_no,maxpark_cam_id)
  File "C:\Users\Abdul Hadi\PycharmProjects\LPRLA\PUSH_plate_no.py", line 156, in push_plate_no
    RECV_MSG = [ord(c) for c in msg]
UnboundLocalError: local variable 'msg' referenced before assignment
2018-11-15 10:58:54,965 werkzeug:_log:88   > INFO: 127.0.0.1 - - [15/Nov/2018 10:58:54] "POST /localagent/v1/push_plate_no HTTP/1.1" 500 -
2018-11-15 11:05:42,123 root:main:195  > CRITICAL: 
 --- Application started & 'main' was called. This is not really Critical. --- 

2018-11-15 11:05:42,123 root:main:202  > INFO: PNS App Services IP Address White List:
2018-11-15 11:05:42,123 root:main:203  > INFO: ['35.162.219.50', '52.77.93.214', '13.228.1.86', '54.169.137.81', '127.0.0.1']
2018-11-15 11:05:43,174 werkzeug:_log:88   > INFO:  * Running on http://0.0.0.0:5001/ (Press CTRL+C to quit)
2018-11-15 11:05:45,804 root:push_plate_no:397  > ERROR: Failed to connect to ftp server using given info host=127.0.0.1 , username=hadi , password=hadi123 ,folder=vehicle_plate , 530-User cannot log in.
 Win32 error:   The user name or password is incorrect. 
 Error details: An error occurred during the authentication process.
530 End
2018-11-15 11:05:45,804 root:push_plate_no:402  > INFO: 
2018-11-15 11:05:45,804 root:push_plate_no:403  > INFO: --- v1_push plate no ---
2018-11-15 11:05:45,804 root:push_plate_no:404  > INFO: Plateno=PUTRAJAYA123<<>>Camera_sn=00000000-00000000<<>>Maxpark_camera_id=1000
2018-11-15 11:05:45,804 root:push_plate_no:406  > INFO: Communicating with Comms Module
2018-11-15 11:05:45,804 LA_Commons:calculate_checksum:43   > INFO: Checksum (numerical= 0x6b
2018-11-15 11:05:50,809 PUSH_plate_no:push_plate_no:144  > WARNING: Timeout. Close connection
2018-11-15 11:05:50,809 flask.app:log_exception:1761 > ERROR: Exception on /localagent/v1/push_plate_no [POST]
Traceback (most recent call last):
  File "C:\Users\Abdul Hadi\PycharmProjects\LPRLA\venv\lib\site-packages\flask\app.py", line 2292, in wsgi_app
    response = self.full_dispatch_request()
  File "C:\Users\Abdul Hadi\PycharmProjects\LPRLA\venv\lib\site-packages\flask\app.py", line 1815, in full_dispatch_request
    rv = self.handle_user_exception(e)
  File "C:\Users\Abdul Hadi\PycharmProjects\LPRLA\venv\lib\site-packages\flask\app.py", line 1718, in handle_user_exception
    reraise(exc_type, exc_value, tb)
  File "C:\Users\Abdul Hadi\PycharmProjects\LPRLA\venv\lib\site-packages\flask\_compat.py", line 35, in reraise
    raise value
  File "C:\Users\Abdul Hadi\PycharmProjects\LPRLA\venv\lib\site-packages\flask\app.py", line 1813, in full_dispatch_request
    rv = self.dispatch_request()
  File "C:\Users\Abdul Hadi\PycharmProjects\LPRLA\venv\lib\site-packages\flask\app.py", line 1799, in dispatch_request
    return self.view_functions[rule.endpoint](**req.view_args)
  File "C:/Users/Abdul Hadi/PycharmProjects/LPRLA/lpr_localagent.py", line 412, in push_plate_no
    plate_no,maxpark_cam_id)
  File "C:\Users\Abdul Hadi\PycharmProjects\LPRLA\PUSH_plate_no.py", line 156, in push_plate_no
    RECV_MSG = [ord(c) for c in msg]
UnboundLocalError: local variable 'msg' referenced before assignment
2018-11-15 11:05:50,809 werkzeug:_log:88   > INFO: 127.0.0.1 - - [15/Nov/2018 11:05:50] "POST /localagent/v1/push_plate_no HTTP/1.1" 500 -
2018-11-15 11:11:10,513 root:main:195  > CRITICAL: 
 --- Application started & 'main' was called. This is not really Critical. --- 

2018-11-15 11:11:10,513 root:main:202  > INFO: PNS App Services IP Address White List:
2018-11-15 11:11:10,513 root:main:203  > INFO: ['35.162.219.50', '52.77.93.214', '13.228.1.86', '54.169.137.81', '127.0.0.1']
2018-11-15 11:11:11,642 werkzeug:_log:88   > INFO:  * Running on http://0.0.0.0:5001/ (Press CTRL+C to quit)
2018-11-15 11:11:16,796 root:push_plate_no:397  > ERROR: Failed to connect to ftp server using given info host=127.0.0.1 , username=hadi , password=hadi123 ,folder=vehicle_plate , 530-User cannot log in.
 Win32 error:   The user name or password is incorrect. 
 Error details: An error occurred during the authentication process.
530 End
2018-11-15 11:11:16,796 root:push_plate_no:402  > INFO: 
2018-11-15 11:11:16,796 root:push_plate_no:403  > INFO: --- v1_push plate no ---
2018-11-15 11:11:16,796 root:push_plate_no:404  > INFO: Plateno=PUTRAJAYA123<<>>Camera_sn=00000000-00000000<<>>Maxpark_camera_id=1000
2018-11-15 11:11:16,796 root:push_plate_no:406  > INFO: Communicating with Comms Module
2018-11-15 11:11:16,796 LA_Commons:calculate_checksum:43   > INFO: Checksum (numerical= 0x6b
2018-11-15 11:11:21,807 PUSH_plate_no:push_plate_no:144  > WARNING: Timeout. Close connection
2018-11-15 11:11:21,807 flask.app:log_exception:1761 > ERROR: Exception on /localagent/v1/push_plate_no [POST]
Traceback (most recent call last):
  File "C:\Users\Abdul Hadi\PycharmProjects\LPRLA\venv\lib\site-packages\flask\app.py", line 2292, in wsgi_app
    response = self.full_dispatch_request()
  File "C:\Users\Abdul Hadi\PycharmProjects\LPRLA\venv\lib\site-packages\flask\app.py", line 1815, in full_dispatch_request
    rv = self.handle_user_exception(e)
  File "C:\Users\Abdul Hadi\PycharmProjects\LPRLA\venv\lib\site-packages\flask\app.py", line 1718, in handle_user_exception
    reraise(exc_type, exc_value, tb)
  File "C:\Users\Abdul Hadi\PycharmProjects\LPRLA\venv\lib\site-packages\flask\_compat.py", line 35, in reraise
    raise value
  File "C:\Users\Abdul Hadi\PycharmProjects\LPRLA\venv\lib\site-packages\flask\app.py", line 1813, in full_dispatch_request
    rv = self.dispatch_request()
  File "C:\Users\Abdul Hadi\PycharmProjects\LPRLA\venv\lib\site-packages\flask\app.py", line 1799, in dispatch_request
    return self.view_functions[rule.endpoint](**req.view_args)
  File "C:/Users/Abdul Hadi/PycharmProjects/LPRLA/lpr_localagent.py", line 412, in push_plate_no
    plate_no,maxpark_cam_id)
  File "C:\Users\Abdul Hadi\PycharmProjects\LPRLA\PUSH_plate_no.py", line 156, in push_plate_no
    RECV_MSG = [ord(c) for c in msg]
UnboundLocalError: local variable 'msg' referenced before assignment
2018-11-15 11:11:21,807 werkzeug:_log:88   > INFO: 127.0.0.1 - - [15/Nov/2018 11:11:21] "POST /localagent/v1/push_plate_no HTTP/1.1" 500 -
2018-11-15 11:11:45,191 root:push_plate_no:397  > ERROR: Failed to connect to ftp server using given info host=127.0.0.1 , username=hadi , password=hadi123 ,folder=vehicle_plate , 530-User cannot log in.
 Win32 error:   The user name or password is incorrect. 
 Error details: An error occurred during the authentication process.
530 End
2018-11-15 11:11:45,191 root:push_plate_no:402  > INFO: 
2018-11-15 11:11:45,191 root:push_plate_no:403  > INFO: --- v1_push plate no ---
2018-11-15 11:11:45,191 root:push_plate_no:404  > INFO: Plateno=PUTRAJAYA123<<>>Camera_sn=00000000-00000000<<>>Maxpark_camera_id=1000
2018-11-15 11:11:45,191 root:push_plate_no:406  > INFO: Communicating with Comms Module
2018-11-15 11:11:45,191 LA_Commons:calculate_checksum:43   > INFO: Checksum (numerical= 0x6b
2018-11-15 11:11:50,194 PUSH_plate_no:push_plate_no:144  > WARNING: Timeout. Close connection
2018-11-15 11:11:50,194 flask.app:log_exception:1761 > ERROR: Exception on /localagent/v1/push_plate_no [POST]
Traceback (most recent call last):
  File "C:\Users\Abdul Hadi\PycharmProjects\LPRLA\venv\lib\site-packages\flask\app.py", line 2292, in wsgi_app
    response = self.full_dispatch_request()
  File "C:\Users\Abdul Hadi\PycharmProjects\LPRLA\venv\lib\site-packages\flask\app.py", line 1815, in full_dispatch_request
    rv = self.handle_user_exception(e)
  File "C:\Users\Abdul Hadi\PycharmProjects\LPRLA\venv\lib\site-packages\flask\app.py", line 1718, in handle_user_exception
    reraise(exc_type, exc_value, tb)
  File "C:\Users\Abdul Hadi\PycharmProjects\LPRLA\venv\lib\site-packages\flask\_compat.py", line 35, in reraise
    raise value
  File "C:\Users\Abdul Hadi\PycharmProjects\LPRLA\venv\lib\site-packages\flask\app.py", line 1813, in full_dispatch_request
    rv = self.dispatch_request()
  File "C:\Users\Abdul Hadi\PycharmProjects\LPRLA\venv\lib\site-packages\flask\app.py", line 1799, in dispatch_request
    return self.view_functions[rule.endpoint](**req.view_args)
  File "C:/Users/Abdul Hadi/PycharmProjects/LPRLA/lpr_localagent.py", line 412, in push_plate_no
    plate_no,maxpark_cam_id)
  File "C:\Users\Abdul Hadi\PycharmProjects\LPRLA\PUSH_plate_no.py", line 156, in push_plate_no
    RECV_MSG = [ord(c) for c in msg]
UnboundLocalError: local variable 'msg' referenced before assignment
2018-11-15 11:11:50,194 werkzeug:_log:88   > INFO: 127.0.0.1 - - [15/Nov/2018 11:11:50] "POST /localagent/v1/push_plate_no HTTP/1.1" 500 -
2018-11-15 11:11:58,544 root:main:195  > CRITICAL: 
 --- Application started & 'main' was called. This is not really Critical. --- 

2018-11-15 11:11:58,544 root:main:202  > INFO: PNS App Services IP Address White List:
2018-11-15 11:11:58,544 root:main:203  > INFO: ['35.162.219.50', '52.77.93.214', '13.228.1.86', '54.169.137.81', '127.0.0.1']
2018-11-15 11:11:59,573 werkzeug:_log:88   > INFO:  * Running on http://0.0.0.0:5001/ (Press CTRL+C to quit)
2018-11-15 11:12:02,895 root:push_plate_no:397  > ERROR: Failed to connect to ftp server using given info host=127.0.0.1 , username=hadi , password=hadi123 ,folder=vehicle_plate , 530-User cannot log in.
 Win32 error:   The user name or password is incorrect. 
 Error details: An error occurred during the authentication process.
530 End
2018-11-15 11:12:02,895 root:push_plate_no:402  > INFO: 
2018-11-15 11:12:02,895 root:push_plate_no:403  > INFO: --- v1_push plate no ---
2018-11-15 11:12:02,895 root:push_plate_no:404  > INFO: Plateno=PUTRAJAYA123<<>>Camera_sn=00000000-00000000<<>>Maxpark_camera_id=1000
2018-11-15 11:12:02,895 root:push_plate_no:406  > INFO: Communicating with Comms Module
2018-11-15 11:12:02,895 LA_Commons:calculate_checksum:43   > INFO: Checksum (numerical= 0x6b
2018-11-15 11:12:07,917 PUSH_plate_no:push_plate_no:144  > WARNING: Timeout. Close connection
2018-11-15 11:12:07,917 flask.app:log_exception:1761 > ERROR: Exception on /localagent/v1/push_plate_no [POST]
Traceback (most recent call last):
  File "C:\Users\Abdul Hadi\PycharmProjects\LPRLA\venv\lib\site-packages\flask\app.py", line 2292, in wsgi_app
    response = self.full_dispatch_request()
  File "C:\Users\Abdul Hadi\PycharmProjects\LPRLA\venv\lib\site-packages\flask\app.py", line 1815, in full_dispatch_request
    rv = self.handle_user_exception(e)
  File "C:\Users\Abdul Hadi\PycharmProjects\LPRLA\venv\lib\site-packages\flask\app.py", line 1718, in handle_user_exception
    reraise(exc_type, exc_value, tb)
  File "C:\Users\Abdul Hadi\PycharmProjects\LPRLA\venv\lib\site-packages\flask\_compat.py", line 35, in reraise
    raise value
  File "C:\Users\Abdul Hadi\PycharmProjects\LPRLA\venv\lib\site-packages\flask\app.py", line 1813, in full_dispatch_request
    rv = self.dispatch_request()
  File "C:\Users\Abdul Hadi\PycharmProjects\LPRLA\venv\lib\site-packages\flask\app.py", line 1799, in dispatch_request
    return self.view_functions[rule.endpoint](**req.view_args)
  File "C:/Users/Abdul Hadi/PycharmProjects/LPRLA/lpr_localagent.py", line 412, in push_plate_no
    plate_no,maxpark_cam_id)
  File "C:\Users\Abdul Hadi\PycharmProjects\LPRLA\PUSH_plate_no.py", line 156, in push_plate_no
    RECV_MSG = [ord(c) for c in msg]
UnboundLocalError: local variable 'msg' referenced before assignment
2018-11-15 11:12:07,917 werkzeug:_log:88   > INFO: 127.0.0.1 - - [15/Nov/2018 11:12:07] "POST /localagent/v1/push_plate_no HTTP/1.1" 500 -
2018-11-15 11:12:20,515 root:main:195  > CRITICAL: 
 --- Application started & 'main' was called. This is not really Critical. --- 

2018-11-15 11:12:20,515 root:main:202  > INFO: PNS App Services IP Address White List:
2018-11-15 11:12:20,515 root:main:203  > INFO: ['35.162.219.50', '52.77.93.214', '13.228.1.86', '54.169.137.81', '127.0.0.1']
2018-11-15 11:12:21,548 werkzeug:_log:88   > INFO:  * Running on http://0.0.0.0:5001/ (Press CTRL+C to quit)
2018-11-15 11:12:24,259 root:push_plate_no:397  > ERROR: Failed to connect to ftp server using given info host=127.0.0.1 , username=hadi , password=hadi123 ,folder=vehicle_plate , 530-User cannot log in.
 Win32 error:   The user name or password is incorrect. 
 Error details: An error occurred during the authentication process.
530 End
2018-11-15 11:12:24,259 root:push_plate_no:402  > INFO: 
2018-11-15 11:12:24,259 root:push_plate_no:403  > INFO: --- v1_push plate no ---
2018-11-15 11:12:24,259 root:push_plate_no:404  > INFO: Plateno=PUTRAJAYA123<<>>Camera_sn=00000000-00000000<<>>Maxpark_camera_id=1000
2018-11-15 11:12:24,259 root:push_plate_no:406  > INFO: Communicating with Comms Module
2018-11-15 11:12:24,259 LA_Commons:calculate_checksum:43   > INFO: Checksum (numerical= 0x6b
2018-11-15 11:12:29,261 PUSH_plate_no:push_plate_no:144  > WARNING: Timeout. Close connection
2018-11-15 11:12:29,261 flask.app:log_exception:1761 > ERROR: Exception on /localagent/v1/push_plate_no [POST]
Traceback (most recent call last):
  File "C:\Users\Abdul Hadi\PycharmProjects\LPRLA\venv\lib\site-packages\flask\app.py", line 2292, in wsgi_app
    response = self.full_dispatch_request()
  File "C:\Users\Abdul Hadi\PycharmProjects\LPRLA\venv\lib\site-packages\flask\app.py", line 1815, in full_dispatch_request
    rv = self.handle_user_exception(e)
  File "C:\Users\Abdul Hadi\PycharmProjects\LPRLA\venv\lib\site-packages\flask\app.py", line 1718, in handle_user_exception
    reraise(exc_type, exc_value, tb)
  File "C:\Users\Abdul Hadi\PycharmProjects\LPRLA\venv\lib\site-packages\flask\_compat.py", line 35, in reraise
    raise value
  File "C:\Users\Abdul Hadi\PycharmProjects\LPRLA\venv\lib\site-packages\flask\app.py", line 1813, in full_dispatch_request
    rv = self.dispatch_request()
  File "C:\Users\Abdul Hadi\PycharmProjects\LPRLA\venv\lib\site-packages\flask\app.py", line 1799, in dispatch_request
    return self.view_functions[rule.endpoint](**req.view_args)
  File "C:/Users/Abdul Hadi/PycharmProjects/LPRLA/lpr_localagent.py", line 412, in push_plate_no
    plate_no,maxpark_cam_id)
  File "C:\Users\Abdul Hadi\PycharmProjects\LPRLA\PUSH_plate_no.py", line 156, in push_plate_no
    RECV_MSG = [ord(c) for c in msg]
UnboundLocalError: local variable 'msg' referenced before assignment
2018-11-15 11:12:29,261 werkzeug:_log:88   > INFO: 127.0.0.1 - - [15/Nov/2018 11:12:29] "POST /localagent/v1/push_plate_no HTTP/1.1" 500 -
2018-11-15 11:13:43,529 root:main:195  > CRITICAL: 
 --- Application started & 'main' was called. This is not really Critical. --- 

2018-11-15 11:13:43,529 root:main:202  > INFO: PNS App Services IP Address White List:
2018-11-15 11:13:43,529 root:main:203  > INFO: ['35.162.219.50', '52.77.93.214', '13.228.1.86', '54.169.137.81', '127.0.0.1']
2018-11-15 11:13:44,565 werkzeug:_log:88   > INFO:  * Running on http://0.0.0.0:5001/ (Press CTRL+C to quit)
2018-11-15 11:13:47,610 root:push_plate_no:397  > ERROR: Failed to connect to ftp server using given info host=127.0.0.1 , username=hadi , password=hadi123 ,folder=vehicle_plate , 530-User cannot log in.
 Win32 error:   The user name or password is incorrect. 
 Error details: An error occurred during the authentication process.
530 End
2018-11-15 11:13:47,610 root:push_plate_no:402  > INFO: 
2018-11-15 11:13:47,610 root:push_plate_no:403  > INFO: --- v1_push plate no ---
2018-11-15 11:13:47,610 root:push_plate_no:404  > INFO: Plateno=PUTRAJAYA123<<>>Camera_sn=00000000-00000000<<>>Maxpark_camera_id=1000
2018-11-15 11:13:47,610 root:push_plate_no:406  > INFO: Communicating with Comms Module
2018-11-15 11:13:47,610 LA_Commons:calculate_checksum:43   > INFO: Checksum (numerical= 0x6b
2018-11-15 11:13:47,610 flask.app:log_exception:1761 > ERROR: Exception on /localagent/v1/push_plate_no [POST]
Traceback (most recent call last):
  File "C:\Users\Abdul Hadi\PycharmProjects\LPRLA\venv\lib\site-packages\flask\app.py", line 2292, in wsgi_app
    response = self.full_dispatch_request()
  File "C:\Users\Abdul Hadi\PycharmProjects\LPRLA\venv\lib\site-packages\flask\app.py", line 1815, in full_dispatch_request
    rv = self.handle_user_exception(e)
  File "C:\Users\Abdul Hadi\PycharmProjects\LPRLA\venv\lib\site-packages\flask\app.py", line 1718, in handle_user_exception
    reraise(exc_type, exc_value, tb)
  File "C:\Users\Abdul Hadi\PycharmProjects\LPRLA\venv\lib\site-packages\flask\_compat.py", line 35, in reraise
    raise value
  File "C:\Users\Abdul Hadi\PycharmProjects\LPRLA\venv\lib\site-packages\flask\app.py", line 1813, in full_dispatch_request
    rv = self.dispatch_request()
  File "C:\Users\Abdul Hadi\PycharmProjects\LPRLA\venv\lib\site-packages\flask\app.py", line 1799, in dispatch_request
    return self.view_functions[rule.endpoint](**req.view_args)
  File "C:/Users/Abdul Hadi/PycharmProjects/LPRLA/lpr_localagent.py", line 412, in push_plate_no
    plate_no,maxpark_cam_id)
  File "C:\Users\Abdul Hadi\PycharmProjects\LPRLA\PUSH_plate_no.py", line 60, in push_plate_no
    print('dererrere'+MESSAGE)
TypeError: can only concatenate str (not "list") to str
2018-11-15 11:13:47,613 werkzeug:_log:88   > INFO: 127.0.0.1 - - [15/Nov/2018 11:13:47] "POST /localagent/v1/push_plate_no HTTP/1.1" 500 -
2018-11-15 11:16:28,294 root:main:195  > CRITICAL: 
 --- Application started & 'main' was called. This is not really Critical. --- 

2018-11-15 11:16:28,294 root:main:202  > INFO: PNS App Services IP Address White List:
2018-11-15 11:16:28,294 root:main:203  > INFO: ['35.162.219.50', '52.77.93.214', '13.228.1.86', '54.169.137.81', '127.0.0.1']
2018-11-15 11:16:29,373 werkzeug:_log:88   > INFO:  * Running on http://0.0.0.0:5001/ (Press CTRL+C to quit)
2018-11-15 11:16:33,350 root:push_plate_no:397  > ERROR: Failed to connect to ftp server using given info host=127.0.0.1 , username=hadi , password=hadi123 ,folder=vehicle_plate , 530-User cannot log in.
 Win32 error:   The user name or password is incorrect. 
 Error details: An error occurred during the authentication process.
530 End
2018-11-15 11:16:33,350 root:push_plate_no:402  > INFO: 
2018-11-15 11:16:33,354 root:push_plate_no:403  > INFO: --- v1_push plate no ---
2018-11-15 11:16:33,354 root:push_plate_no:404  > INFO: Plateno=PUTRAJAYA123<<>>Camera_sn=00000000-00000000<<>>Maxpark_camera_id=1000
2018-11-15 11:16:33,354 root:push_plate_no:406  > INFO: Communicating with Comms Module
2018-11-15 11:16:33,354 LA_Commons:calculate_checksum:43   > INFO: Checksum (numerical= 0x6b
2018-11-15 11:16:33,354 flask.app:log_exception:1761 > ERROR: Exception on /localagent/v1/push_plate_no [POST]
Traceback (most recent call last):
  File "C:\Users\Abdul Hadi\PycharmProjects\LPRLA\venv\lib\site-packages\flask\app.py", line 2292, in wsgi_app
    response = self.full_dispatch_request()
  File "C:\Users\Abdul Hadi\PycharmProjects\LPRLA\venv\lib\site-packages\flask\app.py", line 1815, in full_dispatch_request
    rv = self.handle_user_exception(e)
  File "C:\Users\Abdul Hadi\PycharmProjects\LPRLA\venv\lib\site-packages\flask\app.py", line 1718, in handle_user_exception
    reraise(exc_type, exc_value, tb)
  File "C:\Users\Abdul Hadi\PycharmProjects\LPRLA\venv\lib\site-packages\flask\_compat.py", line 35, in reraise
    raise value
  File "C:\Users\Abdul Hadi\PycharmProjects\LPRLA\venv\lib\site-packages\flask\app.py", line 1813, in full_dispatch_request
    rv = self.dispatch_request()
  File "C:\Users\Abdul Hadi\PycharmProjects\LPRLA\venv\lib\site-packages\flask\app.py", line 1799, in dispatch_request
    return self.view_functions[rule.endpoint](**req.view_args)
  File "C:/Users/Abdul Hadi/PycharmProjects/LPRLA/lpr_localagent.py", line 412, in push_plate_no
    plate_no,maxpark_cam_id)
  File "C:\Users\Abdul Hadi\PycharmProjects\LPRLA\PUSH_plate_no.py", line 75, in push_plate_no
    str_CMD_G = str(CMD_G)
NameError: name 'CMD_G' is not defined
2018-11-15 11:16:33,354 werkzeug:_log:88   > INFO: 127.0.0.1 - - [15/Nov/2018 11:16:33] "POST /localagent/v1/push_plate_no HTTP/1.1" 500 -
2018-11-15 11:20:50,844 root:main:195  > CRITICAL: 
 --- Application started & 'main' was called. This is not really Critical. --- 

2018-11-15 11:20:50,849 root:main:202  > INFO: PNS App Services IP Address White List:
2018-11-15 11:20:50,849 root:main:203  > INFO: ['35.162.219.50', '52.77.93.214', '13.228.1.86', '54.169.137.81', '127.0.0.1']
2018-11-15 11:20:51,903 werkzeug:_log:88   > INFO:  * Running on http://0.0.0.0:5001/ (Press CTRL+C to quit)
2018-11-15 11:20:56,309 root:push_plate_no:397  > ERROR: Failed to connect to ftp server using given info host=127.0.0.1 , username=hadi , password=hadi123 ,folder=vehicle_plate , 530-User cannot log in.
 Win32 error:   The user name or password is incorrect. 
 Error details: An error occurred during the authentication process.
530 End
2018-11-15 11:20:56,309 root:push_plate_no:402  > INFO: 
2018-11-15 11:20:56,309 root:push_plate_no:403  > INFO: --- v1_push plate no ---
2018-11-15 11:20:56,309 root:push_plate_no:404  > INFO: Plateno=PUTRAJAYA123<<>>Camera_sn=00000000-00000000<<>>Maxpark_camera_id=1000
2018-11-15 11:20:56,309 root:push_plate_no:406  > INFO: Communicating with Comms Module
2018-11-15 11:20:56,309 LA_Commons:calculate_checksum:43   > INFO: Checksum (numerical= 0x6b
2018-11-15 11:20:56,309 flask.app:log_exception:1761 > ERROR: Exception on /localagent/v1/push_plate_no [POST]
Traceback (most recent call last):
  File "C:\Users\Abdul Hadi\PycharmProjects\LPRLA\venv\lib\site-packages\flask\app.py", line 2292, in wsgi_app
    response = self.full_dispatch_request()
  File "C:\Users\Abdul Hadi\PycharmProjects\LPRLA\venv\lib\site-packages\flask\app.py", line 1815, in full_dispatch_request
    rv = self.handle_user_exception(e)
  File "C:\Users\Abdul Hadi\PycharmProjects\LPRLA\venv\lib\site-packages\flask\app.py", line 1718, in handle_user_exception
    reraise(exc_type, exc_value, tb)
  File "C:\Users\Abdul Hadi\PycharmProjects\LPRLA\venv\lib\site-packages\flask\_compat.py", line 35, in reraise
    raise value
  File "C:\Users\Abdul Hadi\PycharmProjects\LPRLA\venv\lib\site-packages\flask\app.py", line 1813, in full_dispatch_request
    rv = self.dispatch_request()
  File "C:\Users\Abdul Hadi\PycharmProjects\LPRLA\venv\lib\site-packages\flask\app.py", line 1799, in dispatch_request
    return self.view_functions[rule.endpoint](**req.view_args)
  File "C:/Users/Abdul Hadi/PycharmProjects/LPRLA/lpr_localagent.py", line 412, in push_plate_no
    plate_no,maxpark_cam_id)
  File "C:\Users\Abdul Hadi\PycharmProjects\LPRLA\PUSH_plate_no.py", line 65, in push_plate_no
    pprint(vars(MESSAGE))
TypeError: vars() argument must have __dict__ attribute
2018-11-15 11:20:56,313 werkzeug:_log:88   > INFO: 127.0.0.1 - - [15/Nov/2018 11:20:56] "POST /localagent/v1/push_plate_no HTTP/1.1" 500 -
2018-11-15 11:26:27,025 root:main:195  > CRITICAL: 
 --- Application started & 'main' was called. This is not really Critical. --- 

2018-11-15 11:26:27,025 root:main:202  > INFO: PNS App Services IP Address White List:
2018-11-15 11:26:27,025 root:main:203  > INFO: ['35.162.219.50', '52.77.93.214', '13.228.1.86', '54.169.137.81', '127.0.0.1']
2018-11-15 11:26:28,071 werkzeug:_log:88   > INFO:  * Running on http://0.0.0.0:5001/ (Press CTRL+C to quit)
2018-11-15 11:26:30,028 root:push_plate_no:397  > ERROR: Failed to connect to ftp server using given info host=127.0.0.1 , username=hadi , password=hadi123 ,folder=vehicle_plate , 530-User cannot log in.
 Win32 error:   The user name or password is incorrect. 
 Error details: An error occurred during the authentication process.
530 End
2018-11-15 11:26:30,032 root:push_plate_no:402  > INFO: 
2018-11-15 11:26:30,032 root:push_plate_no:403  > INFO: --- v1_push plate no ---
2018-11-15 11:26:30,032 root:push_plate_no:404  > INFO: Plateno=PUTRAJAYA123<<>>Camera_sn=00000000-00000000<<>>Maxpark_camera_id=1000
2018-11-15 11:26:30,032 root:push_plate_no:406  > INFO: Communicating with Comms Module
2018-11-15 11:26:30,032 LA_Commons:calculate_checksum:43   > INFO: Checksum (numerical= 0x6b
2018-11-15 11:26:30,032 flask.app:log_exception:1761 > ERROR: Exception on /localagent/v1/push_plate_no [POST]
Traceback (most recent call last):
  File "C:\Users\Abdul Hadi\PycharmProjects\LPRLA\venv\lib\site-packages\flask\app.py", line 2292, in wsgi_app
    response = self.full_dispatch_request()
  File "C:\Users\Abdul Hadi\PycharmProjects\LPRLA\venv\lib\site-packages\flask\app.py", line 1815, in full_dispatch_request
    rv = self.handle_user_exception(e)
  File "C:\Users\Abdul Hadi\PycharmProjects\LPRLA\venv\lib\site-packages\flask\app.py", line 1718, in handle_user_exception
    reraise(exc_type, exc_value, tb)
  File "C:\Users\Abdul Hadi\PycharmProjects\LPRLA\venv\lib\site-packages\flask\_compat.py", line 35, in reraise
    raise value
  File "C:\Users\Abdul Hadi\PycharmProjects\LPRLA\venv\lib\site-packages\flask\app.py", line 1813, in full_dispatch_request
    rv = self.dispatch_request()
  File "C:\Users\Abdul Hadi\PycharmProjects\LPRLA\venv\lib\site-packages\flask\app.py", line 1799, in dispatch_request
    return self.view_functions[rule.endpoint](**req.view_args)
  File "C:/Users/Abdul Hadi/PycharmProjects/LPRLA/lpr_localagent.py", line 412, in push_plate_no
    plate_no,maxpark_cam_id)
  File "C:\Users\Abdul Hadi\PycharmProjects\LPRLA\PUSH_plate_no.py", line 65, in push_plate_no
    pprint(vars(MESSAGE))
TypeError: vars() argument must have __dict__ attribute
2018-11-15 11:26:30,044 werkzeug:_log:88   > INFO: 127.0.0.1 - - [15/Nov/2018 11:26:30] "POST /localagent/v1/push_plate_no HTTP/1.1" 500 -
2018-11-15 11:26:59,553 root:main:195  > CRITICAL: 
 --- Application started & 'main' was called. This is not really Critical. --- 

2018-11-15 11:26:59,553 root:main:202  > INFO: PNS App Services IP Address White List:
2018-11-15 11:26:59,553 root:main:203  > INFO: ['35.162.219.50', '52.77.93.214', '13.228.1.86', '54.169.137.81', '127.0.0.1']
2018-11-15 11:27:00,587 werkzeug:_log:88   > INFO:  * Running on http://0.0.0.0:5001/ (Press CTRL+C to quit)
2018-11-15 11:27:04,957 root:push_plate_no:397  > ERROR: Failed to connect to ftp server using given info host=127.0.0.1 , username=hadi , password=hadi123 ,folder=vehicle_plate , 530-User cannot log in.
 Win32 error:   The user name or password is incorrect. 
 Error details: An error occurred during the authentication process.
530 End
2018-11-15 11:27:04,957 root:push_plate_no:402  > INFO: 
2018-11-15 11:27:04,957 root:push_plate_no:403  > INFO: --- v1_push plate no ---
2018-11-15 11:27:04,957 root:push_plate_no:404  > INFO: Plateno=PUTRAJAYA123<<>>Camera_sn=00000000-00000000<<>>Maxpark_camera_id=1000
2018-11-15 11:27:04,957 root:push_plate_no:406  > INFO: Communicating with Comms Module
2018-11-15 11:27:04,957 LA_Commons:calculate_checksum:43   > INFO: Checksum (numerical= 0x6b
2018-11-15 11:27:09,978 PUSH_plate_no:push_plate_no:149  > WARNING: Timeout. Close connection
2018-11-15 11:27:09,978 flask.app:log_exception:1761 > ERROR: Exception on /localagent/v1/push_plate_no [POST]
Traceback (most recent call last):
  File "C:\Users\Abdul Hadi\PycharmProjects\LPRLA\venv\lib\site-packages\flask\app.py", line 2292, in wsgi_app
    response = self.full_dispatch_request()
  File "C:\Users\Abdul Hadi\PycharmProjects\LPRLA\venv\lib\site-packages\flask\app.py", line 1815, in full_dispatch_request
    rv = self.handle_user_exception(e)
  File "C:\Users\Abdul Hadi\PycharmProjects\LPRLA\venv\lib\site-packages\flask\app.py", line 1718, in handle_user_exception
    reraise(exc_type, exc_value, tb)
  File "C:\Users\Abdul Hadi\PycharmProjects\LPRLA\venv\lib\site-packages\flask\_compat.py", line 35, in reraise
    raise value
  File "C:\Users\Abdul Hadi\PycharmProjects\LPRLA\venv\lib\site-packages\flask\app.py", line 1813, in full_dispatch_request
    rv = self.dispatch_request()
  File "C:\Users\Abdul Hadi\PycharmProjects\LPRLA\venv\lib\site-packages\flask\app.py", line 1799, in dispatch_request
    return self.view_functions[rule.endpoint](**req.view_args)
  File "C:/Users/Abdul Hadi/PycharmProjects/LPRLA/lpr_localagent.py", line 412, in push_plate_no
    plate_no,maxpark_cam_id)
  File "C:\Users\Abdul Hadi\PycharmProjects\LPRLA\PUSH_plate_no.py", line 161, in push_plate_no
    RECV_MSG = [ord(c) for c in msg]
UnboundLocalError: local variable 'msg' referenced before assignment
2018-11-15 11:27:09,978 werkzeug:_log:88   > INFO: 127.0.0.1 - - [15/Nov/2018 11:27:09] "POST /localagent/v1/push_plate_no HTTP/1.1" 500 -
2018-11-15 11:27:41,930 root:main:195  > CRITICAL: 
 --- Application started & 'main' was called. This is not really Critical. --- 

2018-11-15 11:27:41,930 root:main:202  > INFO: PNS App Services IP Address White List:
2018-11-15 11:27:41,930 root:main:203  > INFO: ['35.162.219.50', '52.77.93.214', '13.228.1.86', '54.169.137.81', '127.0.0.1']
2018-11-15 11:27:42,964 werkzeug:_log:88   > INFO:  * Running on http://0.0.0.0:5001/ (Press CTRL+C to quit)
2018-11-15 11:27:45,442 root:push_plate_no:397  > ERROR: Failed to connect to ftp server using given info host=127.0.0.1 , username=hadi , password=hadi123 ,folder=vehicle_plate , 530-User cannot log in.
 Win32 error:   The user name or password is incorrect. 
 Error details: An error occurred during the authentication process.
530 End
2018-11-15 11:27:45,442 root:push_plate_no:402  > INFO: 
2018-11-15 11:27:45,442 root:push_plate_no:403  > INFO: --- v1_push plate no ---
2018-11-15 11:27:45,442 root:push_plate_no:404  > INFO: Plateno=PUTRAJAYA123<<>>Camera_sn=00000000-00000000<<>>Maxpark_camera_id=1000
2018-11-15 11:27:45,442 root:push_plate_no:406  > INFO: Communicating with Comms Module
2018-11-15 11:27:45,442 LA_Commons:calculate_checksum:43   > INFO: Checksum (numerical= 0x6b
2018-11-15 11:27:45,442 flask.app:log_exception:1761 > ERROR: Exception on /localagent/v1/push_plate_no [POST]
Traceback (most recent call last):
  File "C:\Users\Abdul Hadi\PycharmProjects\LPRLA\venv\lib\site-packages\flask\app.py", line 2292, in wsgi_app
    response = self.full_dispatch_request()
  File "C:\Users\Abdul Hadi\PycharmProjects\LPRLA\venv\lib\site-packages\flask\app.py", line 1815, in full_dispatch_request
    rv = self.handle_user_exception(e)
  File "C:\Users\Abdul Hadi\PycharmProjects\LPRLA\venv\lib\site-packages\flask\app.py", line 1718, in handle_user_exception
    reraise(exc_type, exc_value, tb)
  File "C:\Users\Abdul Hadi\PycharmProjects\LPRLA\venv\lib\site-packages\flask\_compat.py", line 35, in reraise
    raise value
  File "C:\Users\Abdul Hadi\PycharmProjects\LPRLA\venv\lib\site-packages\flask\app.py", line 1813, in full_dispatch_request
    rv = self.dispatch_request()
  File "C:\Users\Abdul Hadi\PycharmProjects\LPRLA\venv\lib\site-packages\flask\app.py", line 1799, in dispatch_request
    return self.view_functions[rule.endpoint](**req.view_args)
  File "C:/Users/Abdul Hadi/PycharmProjects/LPRLA/lpr_localagent.py", line 412, in push_plate_no
    plate_no,maxpark_cam_id)
  File "C:\Users\Abdul Hadi\PycharmProjects\LPRLA\PUSH_plate_no.py", line 65, in push_plate_no
    pprint(dir(MESSAGE.__getitem__()))
TypeError: __getitem__() takes exactly one argument (0 given)
2018-11-15 11:27:45,446 werkzeug:_log:88   > INFO: 127.0.0.1 - - [15/Nov/2018 11:27:45] "POST /localagent/v1/push_plate_no HTTP/1.1" 500 -
2018-11-15 11:28:04,070 root:main:195  > CRITICAL: 
 --- Application started & 'main' was called. This is not really Critical. --- 

2018-11-15 11:28:04,070 root:main:202  > INFO: PNS App Services IP Address White List:
2018-11-15 11:28:04,070 root:main:203  > INFO: ['35.162.219.50', '52.77.93.214', '13.228.1.86', '54.169.137.81', '127.0.0.1']
2018-11-15 11:28:05,478 werkzeug:_log:88   > INFO:  * Running on http://0.0.0.0:5001/ (Press CTRL+C to quit)
2018-11-15 11:28:08,343 root:push_plate_no:397  > ERROR: Failed to connect to ftp server using given info host=127.0.0.1 , username=hadi , password=hadi123 ,folder=vehicle_plate , 530-User cannot log in.
 Win32 error:   The user name or password is incorrect. 
 Error details: An error occurred during the authentication process.
530 End
2018-11-15 11:28:08,343 root:push_plate_no:402  > INFO: 
2018-11-15 11:28:08,343 root:push_plate_no:403  > INFO: --- v1_push plate no ---
2018-11-15 11:28:08,343 root:push_plate_no:404  > INFO: Plateno=PUTRAJAYA123<<>>Camera_sn=00000000-00000000<<>>Maxpark_camera_id=1000
2018-11-15 11:28:08,343 root:push_plate_no:406  > INFO: Communicating with Comms Module
2018-11-15 11:28:08,343 LA_Commons:calculate_checksum:43   > INFO: Checksum (numerical= 0x6b
2018-11-15 11:28:13,353 PUSH_plate_no:push_plate_no:149  > WARNING: Timeout. Close connection
2018-11-15 11:28:13,353 flask.app:log_exception:1761 > ERROR: Exception on /localagent/v1/push_plate_no [POST]
Traceback (most recent call last):
  File "C:\Users\Abdul Hadi\PycharmProjects\LPRLA\venv\lib\site-packages\flask\app.py", line 2292, in wsgi_app
    response = self.full_dispatch_request()
  File "C:\Users\Abdul Hadi\PycharmProjects\LPRLA\venv\lib\site-packages\flask\app.py", line 1815, in full_dispatch_request
    rv = self.handle_user_exception(e)
  File "C:\Users\Abdul Hadi\PycharmProjects\LPRLA\venv\lib\site-packages\flask\app.py", line 1718, in handle_user_exception
    reraise(exc_type, exc_value, tb)
  File "C:\Users\Abdul Hadi\PycharmProjects\LPRLA\venv\lib\site-packages\flask\_compat.py", line 35, in reraise
    raise value
  File "C:\Users\Abdul Hadi\PycharmProjects\LPRLA\venv\lib\site-packages\flask\app.py", line 1813, in full_dispatch_request
    rv = self.dispatch_request()
  File "C:\Users\Abdul Hadi\PycharmProjects\LPRLA\venv\lib\site-packages\flask\app.py", line 1799, in dispatch_request
    return self.view_functions[rule.endpoint](**req.view_args)
  File "C:/Users/Abdul Hadi/PycharmProjects/LPRLA/lpr_localagent.py", line 412, in push_plate_no
    plate_no,maxpark_cam_id)
  File "C:\Users\Abdul Hadi\PycharmProjects\LPRLA\PUSH_plate_no.py", line 161, in push_plate_no
    RECV_MSG = [ord(c) for c in msg]
UnboundLocalError: local variable 'msg' referenced before assignment
2018-11-15 11:28:13,353 werkzeug:_log:88   > INFO: 127.0.0.1 - - [15/Nov/2018 11:28:13] "POST /localagent/v1/push_plate_no HTTP/1.1" 500 -
2018-11-15 11:30:40,369 root:main:195  > CRITICAL: 
 --- Application started & 'main' was called. This is not really Critical. --- 

2018-11-15 11:30:40,369 root:main:202  > INFO: PNS App Services IP Address White List:
2018-11-15 11:30:40,369 root:main:203  > INFO: ['35.162.219.50', '52.77.93.214', '13.228.1.86', '54.169.137.81', '127.0.0.1']
2018-11-15 11:30:41,507 werkzeug:_log:88   > INFO:  * Running on http://0.0.0.0:5001/ (Press CTRL+C to quit)
2018-11-15 11:30:55,038 root:push_plate_no:397  > ERROR: Failed to connect to ftp server using given info host=127.0.0.1 , username=hadi , password=hadi123 ,folder=vehicle_plate , 530-User cannot log in.
 Win32 error:   The user name or password is incorrect. 
 Error details: An error occurred during the authentication process.
530 End
2018-11-15 11:30:55,038 root:push_plate_no:402  > INFO: 
2018-11-15 11:30:55,038 root:push_plate_no:403  > INFO: --- v1_push plate no ---
2018-11-15 11:30:55,038 root:push_plate_no:404  > INFO: Plateno=PUTRAJAYA123<<>>Camera_sn=00000000-00000000<<>>Maxpark_camera_id=1000
2018-11-15 11:30:55,038 root:push_plate_no:406  > INFO: Communicating with Comms Module
2018-11-15 11:30:55,038 LA_Commons:calculate_checksum:43   > INFO: Checksum (numerical= 0x6b
2018-11-15 11:30:55,038 flask.app:log_exception:1761 > ERROR: Exception on /localagent/v1/push_plate_no [POST]
Traceback (most recent call last):
  File "C:\Users\Abdul Hadi\PycharmProjects\LPRLA\venv\lib\site-packages\flask\app.py", line 2292, in wsgi_app
    response = self.full_dispatch_request()
  File "C:\Users\Abdul Hadi\PycharmProjects\LPRLA\venv\lib\site-packages\flask\app.py", line 1815, in full_dispatch_request
    rv = self.handle_user_exception(e)
  File "C:\Users\Abdul Hadi\PycharmProjects\LPRLA\venv\lib\site-packages\flask\app.py", line 1718, in handle_user_exception
    reraise(exc_type, exc_value, tb)
  File "C:\Users\Abdul Hadi\PycharmProjects\LPRLA\venv\lib\site-packages\flask\_compat.py", line 35, in reraise
    raise value
  File "C:\Users\Abdul Hadi\PycharmProjects\LPRLA\venv\lib\site-packages\flask\app.py", line 1813, in full_dispatch_request
    rv = self.dispatch_request()
  File "C:\Users\Abdul Hadi\PycharmProjects\LPRLA\venv\lib\site-packages\flask\app.py", line 1799, in dispatch_request
    return self.view_functions[rule.endpoint](**req.view_args)
  File "C:/Users/Abdul Hadi/PycharmProjects/LPRLA/lpr_localagent.py", line 412, in push_plate_no
    plate_no,maxpark_cam_id)
  File "C:\Users\Abdul Hadi\PycharmProjects\LPRLA\PUSH_plate_no.py", line 63, in push_plate_no
    print('dererrere'+MESSAGE)
TypeError: can only concatenate str (not "list") to str
2018-11-15 11:30:55,042 werkzeug:_log:88   > INFO: 127.0.0.1 - - [15/Nov/2018 11:30:55] "POST /localagent/v1/push_plate_no HTTP/1.1" 500 -
2018-11-15 11:32:34,227 root:main:195  > CRITICAL: 
 --- Application started & 'main' was called. This is not really Critical. --- 

2018-11-15 11:32:34,227 root:main:202  > INFO: PNS App Services IP Address White List:
2018-11-15 11:32:34,227 root:main:203  > INFO: ['35.162.219.50', '52.77.93.214', '13.228.1.86', '54.169.137.81', '127.0.0.1']
2018-11-15 11:32:35,261 werkzeug:_log:88   > INFO:  * Running on http://0.0.0.0:5001/ (Press CTRL+C to quit)
2018-11-15 11:32:38,410 root:push_plate_no:397  > ERROR: Failed to connect to ftp server using given info host=127.0.0.1 , username=hadi , password=hadi123 ,folder=vehicle_plate , 530-User cannot log in.
 Win32 error:   The user name or password is incorrect. 
 Error details: An error occurred during the authentication process.
530 End
2018-11-15 11:32:38,410 root:push_plate_no:402  > INFO: 
2018-11-15 11:32:38,410 root:push_plate_no:403  > INFO: --- v1_push plate no ---
2018-11-15 11:32:38,410 root:push_plate_no:404  > INFO: Plateno=PUTRAJAYA123<<>>Camera_sn=00000000-00000000<<>>Maxpark_camera_id=1000
2018-11-15 11:32:38,410 root:push_plate_no:406  > INFO: Communicating with Comms Module
2018-11-15 11:32:38,410 LA_Commons:calculate_checksum:43   > INFO: Checksum (numerical= 0x6b
2018-11-15 11:32:43,419 PUSH_plate_no:push_plate_no:149  > WARNING: Timeout. Close connection
2018-11-15 11:32:43,419 flask.app:log_exception:1761 > ERROR: Exception on /localagent/v1/push_plate_no [POST]
Traceback (most recent call last):
  File "C:\Users\Abdul Hadi\PycharmProjects\LPRLA\venv\lib\site-packages\flask\app.py", line 2292, in wsgi_app
    response = self.full_dispatch_request()
  File "C:\Users\Abdul Hadi\PycharmProjects\LPRLA\venv\lib\site-packages\flask\app.py", line 1815, in full_dispatch_request
    rv = self.handle_user_exception(e)
  File "C:\Users\Abdul Hadi\PycharmProjects\LPRLA\venv\lib\site-packages\flask\app.py", line 1718, in handle_user_exception
    reraise(exc_type, exc_value, tb)
  File "C:\Users\Abdul Hadi\PycharmProjects\LPRLA\venv\lib\site-packages\flask\_compat.py", line 35, in reraise
    raise value
  File "C:\Users\Abdul Hadi\PycharmProjects\LPRLA\venv\lib\site-packages\flask\app.py", line 1813, in full_dispatch_request
    rv = self.dispatch_request()
  File "C:\Users\Abdul Hadi\PycharmProjects\LPRLA\venv\lib\site-packages\flask\app.py", line 1799, in dispatch_request
    return self.view_functions[rule.endpoint](**req.view_args)
  File "C:/Users/Abdul Hadi/PycharmProjects/LPRLA/lpr_localagent.py", line 412, in push_plate_no
    plate_no,maxpark_cam_id)
  File "C:\Users\Abdul Hadi\PycharmProjects\LPRLA\PUSH_plate_no.py", line 161, in push_plate_no
    RECV_MSG = [ord(c) for c in msg]
UnboundLocalError: local variable 'msg' referenced before assignment
2018-11-15 11:32:43,419 werkzeug:_log:88   > INFO: 127.0.0.1 - - [15/Nov/2018 11:32:43] "POST /localagent/v1/push_plate_no HTTP/1.1" 500 -
2018-11-15 11:34:07,076 root:main:195  > CRITICAL: 
 --- Application started & 'main' was called. This is not really Critical. --- 

2018-11-15 11:34:07,076 root:main:202  > INFO: PNS App Services IP Address White List:
2018-11-15 11:34:07,076 root:main:203  > INFO: ['35.162.219.50', '52.77.93.214', '13.228.1.86', '54.169.137.81', '127.0.0.1']
2018-11-15 11:34:08,103 werkzeug:_log:88   > INFO:  * Running on http://0.0.0.0:5001/ (Press CTRL+C to quit)
2018-11-15 11:34:17,474 root:push_plate_no:397  > ERROR: Failed to connect to ftp server using given info host=127.0.0.1 , username=hadi , password=hadi123 ,folder=vehicle_plate , 530-User cannot log in.
 Win32 error:   The user name or password is incorrect. 
 Error details: An error occurred during the authentication process.
530 End
2018-11-15 11:34:17,474 root:push_plate_no:402  > INFO: 
2018-11-15 11:34:17,474 root:push_plate_no:403  > INFO: --- v1_push plate no ---
2018-11-15 11:34:17,474 root:push_plate_no:404  > INFO: Plateno=PUTRAJAYA123<<>>Camera_sn=00000000-00000000<<>>Maxpark_camera_id=1000
2018-11-15 11:34:17,474 root:push_plate_no:406  > INFO: Communicating with Comms Module
2018-11-15 11:34:17,474 LA_Commons:calculate_checksum:43   > INFO: Checksum (numerical= 0x6b
2018-11-15 11:34:22,495 PUSH_plate_no:push_plate_no:149  > WARNING: Timeout. Close connection
2018-11-15 11:34:22,495 flask.app:log_exception:1761 > ERROR: Exception on /localagent/v1/push_plate_no [POST]
Traceback (most recent call last):
  File "C:\Users\Abdul Hadi\PycharmProjects\LPRLA\venv\lib\site-packages\flask\app.py", line 2292, in wsgi_app
    response = self.full_dispatch_request()
  File "C:\Users\Abdul Hadi\PycharmProjects\LPRLA\venv\lib\site-packages\flask\app.py", line 1815, in full_dispatch_request
    rv = self.handle_user_exception(e)
  File "C:\Users\Abdul Hadi\PycharmProjects\LPRLA\venv\lib\site-packages\flask\app.py", line 1718, in handle_user_exception
    reraise(exc_type, exc_value, tb)
  File "C:\Users\Abdul Hadi\PycharmProjects\LPRLA\venv\lib\site-packages\flask\_compat.py", line 35, in reraise
    raise value
  File "C:\Users\Abdul Hadi\PycharmProjects\LPRLA\venv\lib\site-packages\flask\app.py", line 1813, in full_dispatch_request
    rv = self.dispatch_request()
  File "C:\Users\Abdul Hadi\PycharmProjects\LPRLA\venv\lib\site-packages\flask\app.py", line 1799, in dispatch_request
    return self.view_functions[rule.endpoint](**req.view_args)
  File "C:/Users/Abdul Hadi/PycharmProjects/LPRLA/lpr_localagent.py", line 412, in push_plate_no
    plate_no,maxpark_cam_id)
  File "C:\Users\Abdul Hadi\PycharmProjects\LPRLA\PUSH_plate_no.py", line 161, in push_plate_no
    RECV_MSG = [ord(c) for c in msg]
UnboundLocalError: local variable 'msg' referenced before assignment
2018-11-15 11:34:22,495 werkzeug:_log:88   > INFO: 127.0.0.1 - - [15/Nov/2018 11:34:22] "POST /localagent/v1/push_plate_no HTTP/1.1" 500 -
2018-11-15 11:36:26,430 root:main:195  > CRITICAL: 
 --- Application started & 'main' was called. This is not really Critical. --- 

2018-11-15 11:36:26,430 root:main:202  > INFO: PNS App Services IP Address White List:
2018-11-15 11:36:26,430 root:main:203  > INFO: ['35.162.219.50', '52.77.93.214', '13.228.1.86', '54.169.137.81', '127.0.0.1']
2018-11-15 11:36:27,522 werkzeug:_log:88   > INFO:  * Running on http://0.0.0.0:5001/ (Press CTRL+C to quit)
2018-11-15 11:36:30,466 root:push_plate_no:397  > ERROR: Failed to connect to ftp server using given info host=127.0.0.1 , username=hadi , password=hadi123 ,folder=vehicle_plate , 530-User cannot log in.
 Win32 error:   The user name or password is incorrect. 
 Error details: An error occurred during the authentication process.
530 End
2018-11-15 11:36:30,466 root:push_plate_no:402  > INFO: 
2018-11-15 11:36:30,466 root:push_plate_no:403  > INFO: --- v1_push plate no ---
2018-11-15 11:36:30,466 root:push_plate_no:404  > INFO: Plateno=PUTRAJAYA123<<>>Camera_sn=00000000-00000000<<>>Maxpark_camera_id=1000
2018-11-15 11:36:30,470 root:push_plate_no:406  > INFO: Communicating with Comms Module
2018-11-15 11:36:30,470 LA_Commons:calculate_checksum:43   > INFO: Checksum (numerical= 0x6b
2018-11-15 11:36:35,478 PUSH_plate_no:push_plate_no:152  > WARNING: Timeout. Close connection
2018-11-15 11:36:35,478 flask.app:log_exception:1761 > ERROR: Exception on /localagent/v1/push_plate_no [POST]
Traceback (most recent call last):
  File "C:\Users\Abdul Hadi\PycharmProjects\LPRLA\venv\lib\site-packages\flask\app.py", line 2292, in wsgi_app
    response = self.full_dispatch_request()
  File "C:\Users\Abdul Hadi\PycharmProjects\LPRLA\venv\lib\site-packages\flask\app.py", line 1815, in full_dispatch_request
    rv = self.handle_user_exception(e)
  File "C:\Users\Abdul Hadi\PycharmProjects\LPRLA\venv\lib\site-packages\flask\app.py", line 1718, in handle_user_exception
    reraise(exc_type, exc_value, tb)
  File "C:\Users\Abdul Hadi\PycharmProjects\LPRLA\venv\lib\site-packages\flask\_compat.py", line 35, in reraise
    raise value
  File "C:\Users\Abdul Hadi\PycharmProjects\LPRLA\venv\lib\site-packages\flask\app.py", line 1813, in full_dispatch_request
    rv = self.dispatch_request()
  File "C:\Users\Abdul Hadi\PycharmProjects\LPRLA\venv\lib\site-packages\flask\app.py", line 1799, in dispatch_request
    return self.view_functions[rule.endpoint](**req.view_args)
  File "C:/Users/Abdul Hadi/PycharmProjects/LPRLA/lpr_localagent.py", line 412, in push_plate_no
    plate_no,maxpark_cam_id)
  File "C:\Users\Abdul Hadi\PycharmProjects\LPRLA\PUSH_plate_no.py", line 164, in push_plate_no
    RECV_MSG = [ord(c) for c in msg]
UnboundLocalError: local variable 'msg' referenced before assignment
2018-11-15 11:36:35,478 werkzeug:_log:88   > INFO: 127.0.0.1 - - [15/Nov/2018 11:36:35] "POST /localagent/v1/push_plate_no HTTP/1.1" 500 -
2018-11-15 11:36:51,161 root:main:195  > CRITICAL: 
 --- Application started & 'main' was called. This is not really Critical. --- 

2018-11-15 11:36:51,161 root:main:202  > INFO: PNS App Services IP Address White List:
2018-11-15 11:36:51,161 root:main:203  > INFO: ['35.162.219.50', '52.77.93.214', '13.228.1.86', '54.169.137.81', '127.0.0.1']
2018-11-15 11:36:52,245 werkzeug:_log:88   > INFO:  * Running on http://0.0.0.0:5001/ (Press CTRL+C to quit)
2018-11-15 11:36:55,276 root:push_plate_no:397  > ERROR: Failed to connect to ftp server using given info host=127.0.0.1 , username=hadi , password=hadi123 ,folder=vehicle_plate , 530-User cannot log in.
 Win32 error:   The user name or password is incorrect. 
 Error details: An error occurred during the authentication process.
530 End
2018-11-15 11:36:55,276 root:push_plate_no:402  > INFO: 
2018-11-15 11:36:55,276 root:push_plate_no:403  > INFO: --- v1_push plate no ---
2018-11-15 11:36:55,276 root:push_plate_no:404  > INFO: Plateno=PUTRAJAYA123<<>>Camera_sn=00000000-00000000<<>>Maxpark_camera_id=1000
2018-11-15 11:36:55,276 root:push_plate_no:406  > INFO: Communicating with Comms Module
2018-11-15 11:36:55,276 LA_Commons:calculate_checksum:43   > INFO: Checksum (numerical= 0x6b
2018-11-15 11:37:00,293 PUSH_plate_no:push_plate_no:152  > WARNING: Timeout. Close connection
2018-11-15 11:37:00,293 flask.app:log_exception:1761 > ERROR: Exception on /localagent/v1/push_plate_no [POST]
Traceback (most recent call last):
  File "C:\Users\Abdul Hadi\PycharmProjects\LPRLA\venv\lib\site-packages\flask\app.py", line 2292, in wsgi_app
    response = self.full_dispatch_request()
  File "C:\Users\Abdul Hadi\PycharmProjects\LPRLA\venv\lib\site-packages\flask\app.py", line 1815, in full_dispatch_request
    rv = self.handle_user_exception(e)
  File "C:\Users\Abdul Hadi\PycharmProjects\LPRLA\venv\lib\site-packages\flask\app.py", line 1718, in handle_user_exception
    reraise(exc_type, exc_value, tb)
  File "C:\Users\Abdul Hadi\PycharmProjects\LPRLA\venv\lib\site-packages\flask\_compat.py", line 35, in reraise
    raise value
  File "C:\Users\Abdul Hadi\PycharmProjects\LPRLA\venv\lib\site-packages\flask\app.py", line 1813, in full_dispatch_request
    rv = self.dispatch_request()
  File "C:\Users\Abdul Hadi\PycharmProjects\LPRLA\venv\lib\site-packages\flask\app.py", line 1799, in dispatch_request
    return self.view_functions[rule.endpoint](**req.view_args)
  File "C:/Users/Abdul Hadi/PycharmProjects/LPRLA/lpr_localagent.py", line 412, in push_plate_no
    plate_no,maxpark_cam_id)
  File "C:\Users\Abdul Hadi\PycharmProjects\LPRLA\PUSH_plate_no.py", line 164, in push_plate_no
    RECV_MSG = [ord(c) for c in msg]
UnboundLocalError: local variable 'msg' referenced before assignment
2018-11-15 11:37:00,293 werkzeug:_log:88   > INFO: 127.0.0.1 - - [15/Nov/2018 11:37:00] "POST /localagent/v1/push_plate_no HTTP/1.1" 500 -
2018-11-15 11:37:08,281 root:push_plate_no:397  > ERROR: Failed to connect to ftp server using given info host=127.0.0.1 , username=hadi , password=hadi123 ,folder=vehicle_plate , 530-User cannot log in.
 Win32 error:   The user name or password is incorrect. 
 Error details: An error occurred during the authentication process.
530 End
2018-11-15 11:37:08,281 root:push_plate_no:402  > INFO: 
2018-11-15 11:37:08,281 root:push_plate_no:403  > INFO: --- v1_push plate no ---
2018-11-15 11:37:08,281 root:push_plate_no:404  > INFO: Plateno=PUTRAJAYA123<<>>Camera_sn=00000000-00000000<<>>Maxpark_camera_id=1000
2018-11-15 11:37:08,281 root:push_plate_no:406  > INFO: Communicating with Comms Module
2018-11-15 11:37:08,281 LA_Commons:calculate_checksum:43   > INFO: Checksum (numerical= 0x6b
2018-11-15 11:37:13,292 PUSH_plate_no:push_plate_no:152  > WARNING: Timeout. Close connection
2018-11-15 11:37:13,292 flask.app:log_exception:1761 > ERROR: Exception on /localagent/v1/push_plate_no [POST]
Traceback (most recent call last):
  File "C:\Users\Abdul Hadi\PycharmProjects\LPRLA\venv\lib\site-packages\flask\app.py", line 2292, in wsgi_app
    response = self.full_dispatch_request()
  File "C:\Users\Abdul Hadi\PycharmProjects\LPRLA\venv\lib\site-packages\flask\app.py", line 1815, in full_dispatch_request
    rv = self.handle_user_exception(e)
  File "C:\Users\Abdul Hadi\PycharmProjects\LPRLA\venv\lib\site-packages\flask\app.py", line 1718, in handle_user_exception
    reraise(exc_type, exc_value, tb)
  File "C:\Users\Abdul Hadi\PycharmProjects\LPRLA\venv\lib\site-packages\flask\_compat.py", line 35, in reraise
    raise value
  File "C:\Users\Abdul Hadi\PycharmProjects\LPRLA\venv\lib\site-packages\flask\app.py", line 1813, in full_dispatch_request
    rv = self.dispatch_request()
  File "C:\Users\Abdul Hadi\PycharmProjects\LPRLA\venv\lib\site-packages\flask\app.py", line 1799, in dispatch_request
    return self.view_functions[rule.endpoint](**req.view_args)
  File "C:/Users/Abdul Hadi/PycharmProjects/LPRLA/lpr_localagent.py", line 412, in push_plate_no
    plate_no,maxpark_cam_id)
  File "C:\Users\Abdul Hadi\PycharmProjects\LPRLA\PUSH_plate_no.py", line 164, in push_plate_no
    RECV_MSG = [ord(c) for c in msg]
UnboundLocalError: local variable 'msg' referenced before assignment
2018-11-15 11:37:13,292 werkzeug:_log:88   > INFO: 127.0.0.1 - - [15/Nov/2018 11:37:13] "POST /localagent/v1/push_plate_no HTTP/1.1" 500 -
2018-11-15 11:37:49,659 root:main:195  > CRITICAL: 
 --- Application started & 'main' was called. This is not really Critical. --- 

2018-11-15 11:37:49,659 root:main:202  > INFO: PNS App Services IP Address White List:
2018-11-15 11:37:49,659 root:main:203  > INFO: ['35.162.219.50', '52.77.93.214', '13.228.1.86', '54.169.137.81', '127.0.0.1']
2018-11-15 11:37:50,686 werkzeug:_log:88   > INFO:  * Running on http://0.0.0.0:5001/ (Press CTRL+C to quit)
2018-11-15 11:37:54,120 root:push_plate_no:397  > ERROR: Failed to connect to ftp server using given info host=127.0.0.1 , username=hadi , password=hadi123 ,folder=vehicle_plate , 530-User cannot log in.
 Win32 error:   The user name or password is incorrect. 
 Error details: An error occurred during the authentication process.
530 End
2018-11-15 11:37:54,120 root:push_plate_no:402  > INFO: 
2018-11-15 11:37:54,120 root:push_plate_no:403  > INFO: --- v1_push plate no ---
2018-11-15 11:37:54,120 root:push_plate_no:404  > INFO: Plateno=PUTRAJAYA123<<>>Camera_sn=00000000-00000000<<>>Maxpark_camera_id=1000
2018-11-15 11:37:54,120 root:push_plate_no:406  > INFO: Communicating with Comms Module
2018-11-15 11:37:54,120 LA_Commons:calculate_checksum:43   > INFO: Checksum (numerical= 0x6b
2018-11-15 11:37:59,136 PUSH_plate_no:push_plate_no:152  > WARNING: Timeout. Close connection
2018-11-15 11:37:59,136 flask.app:log_exception:1761 > ERROR: Exception on /localagent/v1/push_plate_no [POST]
Traceback (most recent call last):
  File "C:\Users\Abdul Hadi\PycharmProjects\LPRLA\venv\lib\site-packages\flask\app.py", line 2292, in wsgi_app
    response = self.full_dispatch_request()
  File "C:\Users\Abdul Hadi\PycharmProjects\LPRLA\venv\lib\site-packages\flask\app.py", line 1815, in full_dispatch_request
    rv = self.handle_user_exception(e)
  File "C:\Users\Abdul Hadi\PycharmProjects\LPRLA\venv\lib\site-packages\flask\app.py", line 1718, in handle_user_exception
    reraise(exc_type, exc_value, tb)
  File "C:\Users\Abdul Hadi\PycharmProjects\LPRLA\venv\lib\site-packages\flask\_compat.py", line 35, in reraise
    raise value
  File "C:\Users\Abdul Hadi\PycharmProjects\LPRLA\venv\lib\site-packages\flask\app.py", line 1813, in full_dispatch_request
    rv = self.dispatch_request()
  File "C:\Users\Abdul Hadi\PycharmProjects\LPRLA\venv\lib\site-packages\flask\app.py", line 1799, in dispatch_request
    return self.view_functions[rule.endpoint](**req.view_args)
  File "C:/Users/Abdul Hadi/PycharmProjects/LPRLA/lpr_localagent.py", line 412, in push_plate_no
    plate_no,maxpark_cam_id)
  File "C:\Users\Abdul Hadi\PycharmProjects\LPRLA\PUSH_plate_no.py", line 164, in push_plate_no
    RECV_MSG = [ord(c) for c in msg]
UnboundLocalError: local variable 'msg' referenced before assignment
2018-11-15 11:37:59,136 werkzeug:_log:88   > INFO: 127.0.0.1 - - [15/Nov/2018 11:37:59] "POST /localagent/v1/push_plate_no HTTP/1.1" 500 -
2018-11-15 11:38:13,523 root:main:195  > CRITICAL: 
 --- Application started & 'main' was called. This is not really Critical. --- 

2018-11-15 11:38:13,523 root:main:202  > INFO: PNS App Services IP Address White List:
2018-11-15 11:38:13,523 root:main:203  > INFO: ['35.162.219.50', '52.77.93.214', '13.228.1.86', '54.169.137.81', '127.0.0.1']
2018-11-15 11:38:14,553 werkzeug:_log:88   > INFO:  * Running on http://0.0.0.0:5001/ (Press CTRL+C to quit)
2018-11-15 11:40:25,166 root:push_plate_no:397  > ERROR: Failed to connect to ftp server using given info host=127.0.0.1 , username=hadi , password=hadi123 ,folder=vehicle_plate , 530-User cannot log in.
 Win32 error:   The user name or password is incorrect. 
 Error details: An error occurred during the authentication process.
530 End
2018-11-15 11:40:25,166 root:push_plate_no:402  > INFO: 
2018-11-15 11:40:25,166 root:push_plate_no:403  > INFO: --- v1_push plate no ---
2018-11-15 11:40:25,166 root:push_plate_no:404  > INFO: Plateno=PUTRAJAYA123<<>>Camera_sn=00000000-00000000<<>>Maxpark_camera_id=1000
2018-11-15 11:40:25,166 root:push_plate_no:406  > INFO: Communicating with Comms Module
2018-11-15 11:40:25,166 LA_Commons:calculate_checksum:43   > INFO: Checksum (numerical= 0x62
2018-11-15 11:40:30,172 PUSH_plate_no:push_plate_no:152  > WARNING: Timeout. Close connection
2018-11-15 11:40:30,172 flask.app:log_exception:1761 > ERROR: Exception on /localagent/v1/push_plate_no [POST]
Traceback (most recent call last):
  File "C:\Users\Abdul Hadi\PycharmProjects\LPRLA\venv\lib\site-packages\flask\app.py", line 2292, in wsgi_app
    response = self.full_dispatch_request()
  File "C:\Users\Abdul Hadi\PycharmProjects\LPRLA\venv\lib\site-packages\flask\app.py", line 1815, in full_dispatch_request
    rv = self.handle_user_exception(e)
  File "C:\Users\Abdul Hadi\PycharmProjects\LPRLA\venv\lib\site-packages\flask\app.py", line 1718, in handle_user_exception
    reraise(exc_type, exc_value, tb)
  File "C:\Users\Abdul Hadi\PycharmProjects\LPRLA\venv\lib\site-packages\flask\_compat.py", line 35, in reraise
    raise value
  File "C:\Users\Abdul Hadi\PycharmProjects\LPRLA\venv\lib\site-packages\flask\app.py", line 1813, in full_dispatch_request
    rv = self.dispatch_request()
  File "C:\Users\Abdul Hadi\PycharmProjects\LPRLA\venv\lib\site-packages\flask\app.py", line 1799, in dispatch_request
    return self.view_functions[rule.endpoint](**req.view_args)
  File "C:/Users/Abdul Hadi/PycharmProjects/LPRLA/lpr_localagent.py", line 412, in push_plate_no
    plate_no,maxpark_cam_id)
  File "C:\Users\Abdul Hadi\PycharmProjects\LPRLA\PUSH_plate_no.py", line 164, in push_plate_no
    RECV_MSG = [ord(c) for c in msg]
UnboundLocalError: local variable 'msg' referenced before assignment
2018-11-15 11:40:30,172 werkzeug:_log:88   > INFO: 127.0.0.1 - - [15/Nov/2018 11:40:30] "POST /localagent/v1/push_plate_no HTTP/1.1" 500 -
2018-11-15 11:40:39,648 root:main:195  > CRITICAL: 
 --- Application started & 'main' was called. This is not really Critical. --- 

2018-11-15 11:40:39,648 root:main:202  > INFO: PNS App Services IP Address White List:
2018-11-15 11:40:39,648 root:main:203  > INFO: ['35.162.219.50', '52.77.93.214', '13.228.1.86', '54.169.137.81', '127.0.0.1']
2018-11-15 11:40:40,675 werkzeug:_log:88   > INFO:  * Running on http://0.0.0.0:5001/ (Press CTRL+C to quit)
2018-11-15 11:40:43,326 root:push_plate_no:397  > ERROR: Failed to connect to ftp server using given info host=127.0.0.1 , username=hadi , password=hadi123 ,folder=vehicle_plate , 530-User cannot log in.
 Win32 error:   The user name or password is incorrect. 
 Error details: An error occurred during the authentication process.
530 End
2018-11-15 11:40:43,326 root:push_plate_no:402  > INFO: 
2018-11-15 11:40:43,326 root:push_plate_no:403  > INFO: --- v1_push plate no ---
2018-11-15 11:40:43,326 root:push_plate_no:404  > INFO: Plateno=PUTRAJAYA123<<>>Camera_sn=00000000-00000000<<>>Maxpark_camera_id=1000
2018-11-15 11:40:43,326 root:push_plate_no:406  > INFO: Communicating with Comms Module
2018-11-15 11:40:43,326 LA_Commons:calculate_checksum:43   > INFO: Checksum (numerical= 0x63
2018-11-15 11:40:48,337 PUSH_plate_no:push_plate_no:152  > WARNING: Timeout. Close connection
2018-11-15 11:40:48,337 flask.app:log_exception:1761 > ERROR: Exception on /localagent/v1/push_plate_no [POST]
Traceback (most recent call last):
  File "C:\Users\Abdul Hadi\PycharmProjects\LPRLA\venv\lib\site-packages\flask\app.py", line 2292, in wsgi_app
    response = self.full_dispatch_request()
  File "C:\Users\Abdul Hadi\PycharmProjects\LPRLA\venv\lib\site-packages\flask\app.py", line 1815, in full_dispatch_request
    rv = self.handle_user_exception(e)
  File "C:\Users\Abdul Hadi\PycharmProjects\LPRLA\venv\lib\site-packages\flask\app.py", line 1718, in handle_user_exception
    reraise(exc_type, exc_value, tb)
  File "C:\Users\Abdul Hadi\PycharmProjects\LPRLA\venv\lib\site-packages\flask\_compat.py", line 35, in reraise
    raise value
  File "C:\Users\Abdul Hadi\PycharmProjects\LPRLA\venv\lib\site-packages\flask\app.py", line 1813, in full_dispatch_request
    rv = self.dispatch_request()
  File "C:\Users\Abdul Hadi\PycharmProjects\LPRLA\venv\lib\site-packages\flask\app.py", line 1799, in dispatch_request
    return self.view_functions[rule.endpoint](**req.view_args)
  File "C:/Users/Abdul Hadi/PycharmProjects/LPRLA/lpr_localagent.py", line 412, in push_plate_no
    plate_no,maxpark_cam_id)
  File "C:\Users\Abdul Hadi\PycharmProjects\LPRLA\PUSH_plate_no.py", line 164, in push_plate_no
    RECV_MSG = [ord(c) for c in msg]
UnboundLocalError: local variable 'msg' referenced before assignment
2018-11-15 11:40:48,337 werkzeug:_log:88   > INFO: 127.0.0.1 - - [15/Nov/2018 11:40:48] "POST /localagent/v1/push_plate_no HTTP/1.1" 500 -
2018-11-15 11:40:56,841 root:main:195  > CRITICAL: 
 --- Application started & 'main' was called. This is not really Critical. --- 

2018-11-15 11:40:56,841 root:main:202  > INFO: PNS App Services IP Address White List:
2018-11-15 11:40:56,841 root:main:203  > INFO: ['35.162.219.50', '52.77.93.214', '13.228.1.86', '54.169.137.81', '127.0.0.1']
2018-11-15 11:40:57,994 werkzeug:_log:88   > INFO:  * Running on http://0.0.0.0:5001/ (Press CTRL+C to quit)
2018-11-15 11:41:01,404 root:push_plate_no:397  > ERROR: Failed to connect to ftp server using given info host=127.0.0.1 , username=hadi , password=hadi123 ,folder=vehicle_plate , 530-User cannot log in.
 Win32 error:   The user name or password is incorrect. 
 Error details: An error occurred during the authentication process.
530 End
2018-11-15 11:41:01,404 root:push_plate_no:402  > INFO: 
2018-11-15 11:41:01,404 root:push_plate_no:403  > INFO: --- v1_push plate no ---
2018-11-15 11:41:01,404 root:push_plate_no:404  > INFO: Plateno=PUTRAJAYA123<<>>Camera_sn=00000000-00000000<<>>Maxpark_camera_id=1000
2018-11-15 11:41:01,404 root:push_plate_no:406  > INFO: Communicating with Comms Module
2018-11-15 11:41:01,404 LA_Commons:calculate_checksum:43   > INFO: Checksum (numerical= 0x6c
2018-11-15 11:41:06,416 PUSH_plate_no:push_plate_no:152  > WARNING: Timeout. Close connection
2018-11-15 11:41:06,416 flask.app:log_exception:1761 > ERROR: Exception on /localagent/v1/push_plate_no [POST]
Traceback (most recent call last):
  File "C:\Users\Abdul Hadi\PycharmProjects\LPRLA\venv\lib\site-packages\flask\app.py", line 2292, in wsgi_app
    response = self.full_dispatch_request()
  File "C:\Users\Abdul Hadi\PycharmProjects\LPRLA\venv\lib\site-packages\flask\app.py", line 1815, in full_dispatch_request
    rv = self.handle_user_exception(e)
  File "C:\Users\Abdul Hadi\PycharmProjects\LPRLA\venv\lib\site-packages\flask\app.py", line 1718, in handle_user_exception
    reraise(exc_type, exc_value, tb)
  File "C:\Users\Abdul Hadi\PycharmProjects\LPRLA\venv\lib\site-packages\flask\_compat.py", line 35, in reraise
    raise value
  File "C:\Users\Abdul Hadi\PycharmProjects\LPRLA\venv\lib\site-packages\flask\app.py", line 1813, in full_dispatch_request
    rv = self.dispatch_request()
  File "C:\Users\Abdul Hadi\PycharmProjects\LPRLA\venv\lib\site-packages\flask\app.py", line 1799, in dispatch_request
    return self.view_functions[rule.endpoint](**req.view_args)
  File "C:/Users/Abdul Hadi/PycharmProjects/LPRLA/lpr_localagent.py", line 412, in push_plate_no
    plate_no,maxpark_cam_id)
  File "C:\Users\Abdul Hadi\PycharmProjects\LPRLA\PUSH_plate_no.py", line 164, in push_plate_no
    RECV_MSG = [ord(c) for c in msg]
UnboundLocalError: local variable 'msg' referenced before assignment
2018-11-15 11:41:06,416 werkzeug:_log:88   > INFO: 127.0.0.1 - - [15/Nov/2018 11:41:06] "POST /localagent/v1/push_plate_no HTTP/1.1" 500 -
2018-11-15 11:42:30,106 root:push_plate_no:397  > ERROR: Failed to connect to ftp server using given info host=127.0.0.1 , username=hadi , password=hadi123 ,folder=vehicle_plate , 530-User cannot log in.
 Win32 error:   The user name or password is incorrect. 
 Error details: An error occurred during the authentication process.
530 End
2018-11-15 11:42:30,106 root:push_plate_no:402  > INFO: 
2018-11-15 11:42:30,106 root:push_plate_no:403  > INFO: --- v1_push plate no ---
2018-11-15 11:42:30,106 root:push_plate_no:404  > INFO: Plateno=PUTRAJAYA123<<>>Camera_sn=00000000-00000000<<>>Maxpark_camera_id=1000
2018-11-15 11:42:30,106 root:push_plate_no:406  > INFO: Communicating with Comms Module
2018-11-15 11:42:30,106 LA_Commons:calculate_checksum:43   > INFO: Checksum (numerical= 0x6c
2018-11-15 11:42:35,106 PUSH_plate_no:push_plate_no:152  > WARNING: Timeout. Close connection
2018-11-15 11:42:35,106 flask.app:log_exception:1761 > ERROR: Exception on /localagent/v1/push_plate_no [POST]
Traceback (most recent call last):
  File "C:\Users\Abdul Hadi\PycharmProjects\LPRLA\venv\lib\site-packages\flask\app.py", line 2292, in wsgi_app
    response = self.full_dispatch_request()
  File "C:\Users\Abdul Hadi\PycharmProjects\LPRLA\venv\lib\site-packages\flask\app.py", line 1815, in full_dispatch_request
    rv = self.handle_user_exception(e)
  File "C:\Users\Abdul Hadi\PycharmProjects\LPRLA\venv\lib\site-packages\flask\app.py", line 1718, in handle_user_exception
    reraise(exc_type, exc_value, tb)
  File "C:\Users\Abdul Hadi\PycharmProjects\LPRLA\venv\lib\site-packages\flask\_compat.py", line 35, in reraise
    raise value
  File "C:\Users\Abdul Hadi\PycharmProjects\LPRLA\venv\lib\site-packages\flask\app.py", line 1813, in full_dispatch_request
    rv = self.dispatch_request()
  File "C:\Users\Abdul Hadi\PycharmProjects\LPRLA\venv\lib\site-packages\flask\app.py", line 1799, in dispatch_request
    return self.view_functions[rule.endpoint](**req.view_args)
  File "C:/Users/Abdul Hadi/PycharmProjects/LPRLA/lpr_localagent.py", line 412, in push_plate_no
    plate_no,maxpark_cam_id)
  File "C:\Users\Abdul Hadi\PycharmProjects\LPRLA\PUSH_plate_no.py", line 164, in push_plate_no
    RECV_MSG = [ord(c) for c in msg]
UnboundLocalError: local variable 'msg' referenced before assignment
2018-11-15 11:42:35,106 werkzeug:_log:88   > INFO: 127.0.0.1 - - [15/Nov/2018 11:42:35] "POST /localagent/v1/push_plate_no HTTP/1.1" 500 -
2018-11-15 12:18:11,869 root:main:195  > CRITICAL: 
 --- Application started & 'main' was called. This is not really Critical. --- 

2018-11-15 12:18:11,869 root:main:202  > INFO: PNS App Services IP Address White List:
2018-11-15 12:18:11,869 root:main:203  > INFO: ['35.162.219.50', '52.77.93.214', '13.228.1.86', '54.169.137.81', '127.0.0.1']
2018-11-15 12:18:12,947 werkzeug:_log:88   > INFO:  * Running on http://0.0.0.0:5001/ (Press CTRL+C to quit)
2018-11-15 12:18:17,498 root:push_plate_no:397  > ERROR: Failed to connect to ftp server using given info host=127.0.0.1 , username=hadi , password=hadi123 ,folder=vehicle_plate , 530-User cannot log in.
 Win32 error:   The user name or password is incorrect. 
 Error details: An error occurred during the authentication process.
530 End
2018-11-15 12:18:17,498 root:push_plate_no:402  > INFO: 
2018-11-15 12:18:17,498 root:push_plate_no:403  > INFO: --- v1_push plate no ---
2018-11-15 12:18:17,498 root:push_plate_no:404  > INFO: Plateno=PUTRAJAYA123<<>>Camera_sn=00000000-00000000<<>>Maxpark_camera_id=1000
2018-11-15 12:18:17,498 root:push_plate_no:406  > INFO: Communicating with Comms Module
2018-11-15 12:18:17,498 LA_Commons:calculate_checksum:43   > INFO: Checksum (numerical= 0x6c
2018-11-15 12:18:22,511 PUSH_plate_no:push_plate_no:154  > WARNING: Timeout. Close connection
2018-11-15 12:18:22,511 flask.app:log_exception:1761 > ERROR: Exception on /localagent/v1/push_plate_no [POST]
Traceback (most recent call last):
  File "C:\Users\Abdul Hadi\PycharmProjects\LPRLA\venv\lib\site-packages\flask\app.py", line 2292, in wsgi_app
    response = self.full_dispatch_request()
  File "C:\Users\Abdul Hadi\PycharmProjects\LPRLA\venv\lib\site-packages\flask\app.py", line 1815, in full_dispatch_request
    rv = self.handle_user_exception(e)
  File "C:\Users\Abdul Hadi\PycharmProjects\LPRLA\venv\lib\site-packages\flask\app.py", line 1718, in handle_user_exception
    reraise(exc_type, exc_value, tb)
  File "C:\Users\Abdul Hadi\PycharmProjects\LPRLA\venv\lib\site-packages\flask\_compat.py", line 35, in reraise
    raise value
  File "C:\Users\Abdul Hadi\PycharmProjects\LPRLA\venv\lib\site-packages\flask\app.py", line 1813, in full_dispatch_request
    rv = self.dispatch_request()
  File "C:\Users\Abdul Hadi\PycharmProjects\LPRLA\venv\lib\site-packages\flask\app.py", line 1799, in dispatch_request
    return self.view_functions[rule.endpoint](**req.view_args)
  File "C:/Users/Abdul Hadi/PycharmProjects/LPRLA/lpr_localagent.py", line 412, in push_plate_no
    plate_no,maxpark_cam_id)
  File "C:\Users\Abdul Hadi\PycharmProjects\LPRLA\PUSH_plate_no.py", line 166, in push_plate_no
    RECV_MSG = [ord(c) for c in msg]
UnboundLocalError: local variable 'msg' referenced before assignment
2018-11-15 12:18:22,511 werkzeug:_log:88   > INFO: 127.0.0.1 - - [15/Nov/2018 12:18:22] "POST /localagent/v1/push_plate_no HTTP/1.1" 500 -
2018-11-15 12:19:08,142 root:main:195  > CRITICAL: 
 --- Application started & 'main' was called. This is not really Critical. --- 

2018-11-15 12:19:08,142 root:main:202  > INFO: PNS App Services IP Address White List:
2018-11-15 12:19:08,142 root:main:203  > INFO: ['35.162.219.50', '52.77.93.214', '13.228.1.86', '54.169.137.81', '127.0.0.1']
2018-11-15 12:19:09,595 werkzeug:_log:88   > INFO:  * Running on http://0.0.0.0:5001/ (Press CTRL+C to quit)
2018-11-15 12:19:12,626 root:push_plate_no:397  > ERROR: Failed to connect to ftp server using given info host=127.0.0.1 , username=hadi , password=hadi123 ,folder=vehicle_plate , 530-User cannot log in.
 Win32 error:   The user name or password is incorrect. 
 Error details: An error occurred during the authentication process.
530 End
2018-11-15 12:19:12,626 root:push_plate_no:402  > INFO: 
2018-11-15 12:19:12,626 root:push_plate_no:403  > INFO: --- v1_push plate no ---
2018-11-15 12:19:12,626 root:push_plate_no:404  > INFO: Plateno=PUTRAJAYA123<<>>Camera_sn=00000000-00000000<<>>Maxpark_camera_id=1000
2018-11-15 12:19:12,630 root:push_plate_no:406  > INFO: Communicating with Comms Module
2018-11-15 12:19:12,630 LA_Commons:calculate_checksum:43   > INFO: Checksum (numerical= 0x6c
2018-11-15 12:19:17,637 PUSH_plate_no:push_plate_no:154  > WARNING: Timeout. Close connection
2018-11-15 12:19:17,637 flask.app:log_exception:1761 > ERROR: Exception on /localagent/v1/push_plate_no [POST]
Traceback (most recent call last):
  File "C:\Users\Abdul Hadi\PycharmProjects\LPRLA\venv\lib\site-packages\flask\app.py", line 2292, in wsgi_app
    response = self.full_dispatch_request()
  File "C:\Users\Abdul Hadi\PycharmProjects\LPRLA\venv\lib\site-packages\flask\app.py", line 1815, in full_dispatch_request
    rv = self.handle_user_exception(e)
  File "C:\Users\Abdul Hadi\PycharmProjects\LPRLA\venv\lib\site-packages\flask\app.py", line 1718, in handle_user_exception
    reraise(exc_type, exc_value, tb)
  File "C:\Users\Abdul Hadi\PycharmProjects\LPRLA\venv\lib\site-packages\flask\_compat.py", line 35, in reraise
    raise value
  File "C:\Users\Abdul Hadi\PycharmProjects\LPRLA\venv\lib\site-packages\flask\app.py", line 1813, in full_dispatch_request
    rv = self.dispatch_request()
  File "C:\Users\Abdul Hadi\PycharmProjects\LPRLA\venv\lib\site-packages\flask\app.py", line 1799, in dispatch_request
    return self.view_functions[rule.endpoint](**req.view_args)
  File "C:/Users/Abdul Hadi/PycharmProjects/LPRLA/lpr_localagent.py", line 412, in push_plate_no
    plate_no,maxpark_cam_id)
  File "C:\Users\Abdul Hadi\PycharmProjects\LPRLA\PUSH_plate_no.py", line 166, in push_plate_no
    RECV_MSG = [ord(c) for c in msg]
UnboundLocalError: local variable 'msg' referenced before assignment
2018-11-15 12:19:17,637 werkzeug:_log:88   > INFO: 127.0.0.1 - - [15/Nov/2018 12:19:17] "POST /localagent/v1/push_plate_no HTTP/1.1" 500 -
2018-11-15 12:21:12,980 root:main:195  > CRITICAL: 
 --- Application started & 'main' was called. This is not really Critical. --- 

2018-11-15 12:21:12,980 root:main:202  > INFO: PNS App Services IP Address White List:
2018-11-15 12:21:12,980 root:main:203  > INFO: ['35.162.219.50', '52.77.93.214', '13.228.1.86', '54.169.137.81', '127.0.0.1']
2018-11-15 12:21:14,020 werkzeug:_log:88   > INFO:  * Running on http://0.0.0.0:5001/ (Press CTRL+C to quit)
2018-11-15 12:21:15,911 root:push_plate_no:397  > ERROR: Failed to connect to ftp server using given info host=127.0.0.1 , username=hadi , password=hadi123 ,folder=vehicle_plate , 530-User cannot log in.
 Win32 error:   The user name or password is incorrect. 
 Error details: An error occurred during the authentication process.
530 End
2018-11-15 12:21:15,911 root:push_plate_no:402  > INFO: 
2018-11-15 12:21:15,911 root:push_plate_no:403  > INFO: --- v1_push plate no ---
2018-11-15 12:21:15,911 root:push_plate_no:404  > INFO: Plateno=PUTRAJAYA123<<>>Camera_sn=00000000-00000000<<>>Maxpark_camera_id=1000
2018-11-15 12:21:15,911 root:push_plate_no:406  > INFO: Communicating with Comms Module
2018-11-15 12:21:15,915 LA_Commons:calculate_checksum:43   > INFO: Checksum (numerical= 0x6c
2018-11-15 12:21:20,920 PUSH_plate_no:push_plate_no:156  > WARNING: Timeout. Close connection
2018-11-15 12:21:20,920 flask.app:log_exception:1761 > ERROR: Exception on /localagent/v1/push_plate_no [POST]
Traceback (most recent call last):
  File "C:\Users\Abdul Hadi\PycharmProjects\LPRLA\venv\lib\site-packages\flask\app.py", line 2292, in wsgi_app
    response = self.full_dispatch_request()
  File "C:\Users\Abdul Hadi\PycharmProjects\LPRLA\venv\lib\site-packages\flask\app.py", line 1815, in full_dispatch_request
    rv = self.handle_user_exception(e)
  File "C:\Users\Abdul Hadi\PycharmProjects\LPRLA\venv\lib\site-packages\flask\app.py", line 1718, in handle_user_exception
    reraise(exc_type, exc_value, tb)
  File "C:\Users\Abdul Hadi\PycharmProjects\LPRLA\venv\lib\site-packages\flask\_compat.py", line 35, in reraise
    raise value
  File "C:\Users\Abdul Hadi\PycharmProjects\LPRLA\venv\lib\site-packages\flask\app.py", line 1813, in full_dispatch_request
    rv = self.dispatch_request()
  File "C:\Users\Abdul Hadi\PycharmProjects\LPRLA\venv\lib\site-packages\flask\app.py", line 1799, in dispatch_request
    return self.view_functions[rule.endpoint](**req.view_args)
  File "C:/Users/Abdul Hadi/PycharmProjects/LPRLA/lpr_localagent.py", line 412, in push_plate_no
    plate_no,maxpark_cam_id)
  File "C:\Users\Abdul Hadi\PycharmProjects\LPRLA\PUSH_plate_no.py", line 168, in push_plate_no
    RECV_MSG = [ord(c) for c in msg]
UnboundLocalError: local variable 'msg' referenced before assignment
2018-11-15 12:21:20,920 werkzeug:_log:88   > INFO: 127.0.0.1 - - [15/Nov/2018 12:21:20] "POST /localagent/v1/push_plate_no HTTP/1.1" 500 -
2018-11-15 12:21:43,744 root:main:195  > CRITICAL: 
 --- Application started & 'main' was called. This is not really Critical. --- 

2018-11-15 12:21:43,744 root:main:202  > INFO: PNS App Services IP Address White List:
2018-11-15 12:21:43,744 root:main:203  > INFO: ['35.162.219.50', '52.77.93.214', '13.228.1.86', '54.169.137.81', '127.0.0.1']
2018-11-15 12:21:44,840 werkzeug:_log:88   > INFO:  * Running on http://0.0.0.0:5001/ (Press CTRL+C to quit)
2018-11-15 12:21:47,648 root:push_plate_no:397  > ERROR: Failed to connect to ftp server using given info host=127.0.0.1 , username=hadi , password=hadi123 ,folder=vehicle_plate , 530-User cannot log in.
 Win32 error:   The user name or password is incorrect. 
 Error details: An error occurred during the authentication process.
530 End
2018-11-15 12:21:47,648 root:push_plate_no:402  > INFO: 
2018-11-15 12:21:47,648 root:push_plate_no:403  > INFO: --- v1_push plate no ---
2018-11-15 12:21:47,648 root:push_plate_no:404  > INFO: Plateno=PUTRAJAYA123<<>>Camera_sn=00000000-00000000<<>>Maxpark_camera_id=1000
2018-11-15 12:21:47,648 root:push_plate_no:406  > INFO: Communicating with Comms Module
2018-11-15 12:21:47,648 LA_Commons:calculate_checksum:43   > INFO: Checksum (numerical= 0x6c
2018-11-15 12:21:52,660 PUSH_plate_no:push_plate_no:156  > WARNING: Timeout. Close connection
2018-11-15 12:21:52,661 flask.app:log_exception:1761 > ERROR: Exception on /localagent/v1/push_plate_no [POST]
Traceback (most recent call last):
  File "C:\Users\Abdul Hadi\PycharmProjects\LPRLA\venv\lib\site-packages\flask\app.py", line 2292, in wsgi_app
    response = self.full_dispatch_request()
  File "C:\Users\Abdul Hadi\PycharmProjects\LPRLA\venv\lib\site-packages\flask\app.py", line 1815, in full_dispatch_request
    rv = self.handle_user_exception(e)
  File "C:\Users\Abdul Hadi\PycharmProjects\LPRLA\venv\lib\site-packages\flask\app.py", line 1718, in handle_user_exception
    reraise(exc_type, exc_value, tb)
  File "C:\Users\Abdul Hadi\PycharmProjects\LPRLA\venv\lib\site-packages\flask\_compat.py", line 35, in reraise
    raise value
  File "C:\Users\Abdul Hadi\PycharmProjects\LPRLA\venv\lib\site-packages\flask\app.py", line 1813, in full_dispatch_request
    rv = self.dispatch_request()
  File "C:\Users\Abdul Hadi\PycharmProjects\LPRLA\venv\lib\site-packages\flask\app.py", line 1799, in dispatch_request
    return self.view_functions[rule.endpoint](**req.view_args)
  File "C:/Users/Abdul Hadi/PycharmProjects/LPRLA/lpr_localagent.py", line 412, in push_plate_no
    plate_no,maxpark_cam_id)
  File "C:\Users\Abdul Hadi\PycharmProjects\LPRLA\PUSH_plate_no.py", line 168, in push_plate_no
    RECV_MSG = [ord(c) for c in msg]
UnboundLocalError: local variable 'msg' referenced before assignment
2018-11-15 12:21:52,665 werkzeug:_log:88   > INFO: 127.0.0.1 - - [15/Nov/2018 12:21:52] "POST /localagent/v1/push_plate_no HTTP/1.1" 500 -
2018-11-15 12:23:10,307 root:main:195  > CRITICAL: 
 --- Application started & 'main' was called. This is not really Critical. --- 

2018-11-15 12:23:10,307 root:main:202  > INFO: PNS App Services IP Address White List:
2018-11-15 12:23:10,307 root:main:203  > INFO: ['35.162.219.50', '52.77.93.214', '13.228.1.86', '54.169.137.81', '127.0.0.1']
2018-11-15 12:23:11,439 werkzeug:_log:88   > INFO:  * Running on http://0.0.0.0:5001/ (Press CTRL+C to quit)
2018-11-15 12:23:13,309 root:push_plate_no:397  > ERROR: Failed to connect to ftp server using given info host=127.0.0.1 , username=hadi , password=hadi123 ,folder=vehicle_plate , 530-User cannot log in.
 Win32 error:   The user name or password is incorrect. 
 Error details: An error occurred during the authentication process.
530 End
2018-11-15 12:23:13,309 root:push_plate_no:402  > INFO: 
2018-11-15 12:23:13,309 root:push_plate_no:403  > INFO: --- v1_push plate no ---
2018-11-15 12:23:13,309 root:push_plate_no:404  > INFO: Plateno=PUTRAJAYA123<<>>Camera_sn=00000000-00000000<<>>Maxpark_camera_id=1000
2018-11-15 12:23:13,309 root:push_plate_no:406  > INFO: Communicating with Comms Module
2018-11-15 12:23:13,309 LA_Commons:calculate_checksum:43   > INFO: Checksum (numerical= 0x6c
2018-11-15 12:23:38,025 root:main:195  > CRITICAL: 
 --- Application started & 'main' was called. This is not really Critical. --- 

2018-11-15 12:23:38,025 root:main:202  > INFO: PNS App Services IP Address White List:
2018-11-15 12:23:38,025 root:main:203  > INFO: ['35.162.219.50', '52.77.93.214', '13.228.1.86', '54.169.137.81', '127.0.0.1']
2018-11-15 12:23:39,095 werkzeug:_log:88   > INFO:  * Running on http://0.0.0.0:5001/ (Press CTRL+C to quit)
2018-11-15 12:23:40,758 root:push_plate_no:397  > ERROR: Failed to connect to ftp server using given info host=127.0.0.1 , username=hadi , password=hadi123 ,folder=vehicle_plate , 530-User cannot log in.
 Win32 error:   The user name or password is incorrect. 
 Error details: An error occurred during the authentication process.
530 End
2018-11-15 12:23:40,758 root:push_plate_no:402  > INFO: 
2018-11-15 12:23:40,758 root:push_plate_no:403  > INFO: --- v1_push plate no ---
2018-11-15 12:23:40,758 root:push_plate_no:404  > INFO: Plateno=PUTRAJAYA123<<>>Camera_sn=00000000-00000000<<>>Maxpark_camera_id=1000
2018-11-15 12:23:40,758 root:push_plate_no:406  > INFO: Communicating with Comms Module
2018-11-15 12:23:40,758 LA_Commons:calculate_checksum:43   > INFO: Checksum (numerical= 0x6c
2018-11-15 12:24:05,176 root:main:195  > CRITICAL: 
 --- Application started & 'main' was called. This is not really Critical. --- 

2018-11-15 12:24:05,176 root:main:202  > INFO: PNS App Services IP Address White List:
2018-11-15 12:24:05,176 root:main:203  > INFO: ['35.162.219.50', '52.77.93.214', '13.228.1.86', '54.169.137.81', '127.0.0.1']
2018-11-15 12:24:06,357 werkzeug:_log:88   > INFO:  * Running on http://0.0.0.0:5001/ (Press CTRL+C to quit)
2018-11-15 12:24:08,178 root:push_plate_no:397  > ERROR: Failed to connect to ftp server using given info host=127.0.0.1 , username=hadi , password=hadi123 ,folder=vehicle_plate , 530-User cannot log in.
 Win32 error:   The user name or password is incorrect. 
 Error details: An error occurred during the authentication process.
530 End
2018-11-15 12:24:08,182 root:push_plate_no:402  > INFO: 
2018-11-15 12:24:08,182 root:push_plate_no:403  > INFO: --- v1_push plate no ---
2018-11-15 12:24:08,182 root:push_plate_no:404  > INFO: Plateno=PUTRAJAYA123<<>>Camera_sn=00000000-00000000<<>>Maxpark_camera_id=1000
2018-11-15 12:24:08,182 root:push_plate_no:406  > INFO: Communicating with Comms Module
2018-11-15 12:24:08,182 LA_Commons:calculate_checksum:43   > INFO: Checksum (numerical= 0x6c
2018-11-15 12:24:09,185 PUSH_plate_no:push_plate_no:122  > WARNING: Connection error: [WinError 10061] No connection could be made because the target machine actively refused it
2018-11-15 12:24:09,185 flask.app:log_exception:1761 > ERROR: Exception on /localagent/v1/push_plate_no [POST]
Traceback (most recent call last):
  File "C:\Users\Abdul Hadi\PycharmProjects\LPRLA\venv\lib\site-packages\flask\app.py", line 2292, in wsgi_app
    response = self.full_dispatch_request()
  File "C:\Users\Abdul Hadi\PycharmProjects\LPRLA\venv\lib\site-packages\flask\app.py", line 1815, in full_dispatch_request
    rv = self.handle_user_exception(e)
  File "C:\Users\Abdul Hadi\PycharmProjects\LPRLA\venv\lib\site-packages\flask\app.py", line 1718, in handle_user_exception
    reraise(exc_type, exc_value, tb)
  File "C:\Users\Abdul Hadi\PycharmProjects\LPRLA\venv\lib\site-packages\flask\_compat.py", line 35, in reraise
    raise value
  File "C:\Users\Abdul Hadi\PycharmProjects\LPRLA\venv\lib\site-packages\flask\app.py", line 1813, in full_dispatch_request
    rv = self.dispatch_request()
  File "C:\Users\Abdul Hadi\PycharmProjects\LPRLA\venv\lib\site-packages\flask\app.py", line 1799, in dispatch_request
    return self.view_functions[rule.endpoint](**req.view_args)
  File "C:/Users/Abdul Hadi/PycharmProjects/LPRLA/lpr_localagent.py", line 412, in push_plate_no
    plate_no,maxpark_cam_id)
  File "C:\Users\Abdul Hadi\PycharmProjects\LPRLA\PUSH_plate_no.py", line 135, in push_plate_no
    cars = array(['b', xxx])
TypeError: array() argument 1 must be a unicode character, not list
2018-11-15 12:24:09,188 werkzeug:_log:88   > INFO: 127.0.0.1 - - [15/Nov/2018 12:24:09] "POST /localagent/v1/push_plate_no HTTP/1.1" 500 -
2018-11-15 14:25:13,982 root:main:195  > CRITICAL: 
 --- Application started & 'main' was called. This is not really Critical. --- 

2018-11-15 14:25:13,982 root:main:202  > INFO: PNS App Services IP Address White List:
2018-11-15 14:25:13,982 root:main:203  > INFO: ['35.162.219.50', '52.77.93.214', '13.228.1.86', '54.169.137.81', '127.0.0.1']
2018-11-15 14:25:15,058 werkzeug:_log:88   > INFO:  * Running on http://0.0.0.0:5001/ (Press CTRL+C to quit)
2018-11-15 14:25:18,043 root:push_plate_no:397  > ERROR: Failed to connect to ftp server using given info host=127.0.0.1 , username=hadi , password=hadi123 ,folder=vehicle_plate , 530-User cannot log in.
 Win32 error:   The user name or password is incorrect. 
 Error details: An error occurred during the authentication process.
530 End
2018-11-15 14:25:18,047 root:push_plate_no:402  > INFO: 
2018-11-15 14:25:18,047 root:push_plate_no:403  > INFO: --- v1_push plate no ---
2018-11-15 14:25:18,047 root:push_plate_no:404  > INFO: Plateno=PUTRAJAYA123<<>>Camera_sn=00000000-00000000<<>>Maxpark_camera_id=1000
2018-11-15 14:25:18,047 root:push_plate_no:406  > INFO: Communicating with Comms Module
2018-11-15 14:25:18,047 LA_Commons:calculate_checksum:43   > INFO: Checksum (numerical= 0x6c
2018-11-15 14:25:19,055 PUSH_plate_no:push_plate_no:122  > WARNING: Connection error: [WinError 10061] No connection could be made because the target machine actively refused it
2018-11-15 14:25:19,055 flask.app:log_exception:1761 > ERROR: Exception on /localagent/v1/push_plate_no [POST]
Traceback (most recent call last):
  File "C:\Users\Abdul Hadi\PycharmProjects\LPRLA\venv\lib\site-packages\flask\app.py", line 2292, in wsgi_app
    response = self.full_dispatch_request()
  File "C:\Users\Abdul Hadi\PycharmProjects\LPRLA\venv\lib\site-packages\flask\app.py", line 1815, in full_dispatch_request
    rv = self.handle_user_exception(e)
  File "C:\Users\Abdul Hadi\PycharmProjects\LPRLA\venv\lib\site-packages\flask\app.py", line 1718, in handle_user_exception
    reraise(exc_type, exc_value, tb)
  File "C:\Users\Abdul Hadi\PycharmProjects\LPRLA\venv\lib\site-packages\flask\_compat.py", line 35, in reraise
    raise value
  File "C:\Users\Abdul Hadi\PycharmProjects\LPRLA\venv\lib\site-packages\flask\app.py", line 1813, in full_dispatch_request
    rv = self.dispatch_request()
  File "C:\Users\Abdul Hadi\PycharmProjects\LPRLA\venv\lib\site-packages\flask\app.py", line 1799, in dispatch_request
    return self.view_functions[rule.endpoint](**req.view_args)
  File "C:/Users/Abdul Hadi/PycharmProjects/LPRLA/lpr_localagent.py", line 412, in push_plate_no
    plate_no,maxpark_cam_id)
  File "C:\Users\Abdul Hadi\PycharmProjects\LPRLA\PUSH_plate_no.py", line 132, in push_plate_no
    print(my_PACKET.decode("utf-8"))
AttributeError: 'array.array' object has no attribute 'decode'
2018-11-15 14:25:19,055 werkzeug:_log:88   > INFO: 127.0.0.1 - - [15/Nov/2018 14:25:19] "POST /localagent/v1/push_plate_no HTTP/1.1" 500 -
2018-11-15 14:25:43,373 root:main:195  > CRITICAL: 
 --- Application started & 'main' was called. This is not really Critical. --- 

2018-11-15 14:25:43,373 root:main:202  > INFO: PNS App Services IP Address White List:
2018-11-15 14:25:43,373 root:main:203  > INFO: ['35.162.219.50', '52.77.93.214', '13.228.1.86', '54.169.137.81', '127.0.0.1']
2018-11-15 14:25:44,469 werkzeug:_log:88   > INFO:  * Running on http://0.0.0.0:5001/ (Press CTRL+C to quit)
2018-11-15 14:25:45,421 root:push_plate_no:397  > ERROR: Failed to connect to ftp server using given info host=127.0.0.1 , username=hadi , password=hadi123 ,folder=vehicle_plate , 530-User cannot log in.
 Win32 error:   The user name or password is incorrect. 
 Error details: An error occurred during the authentication process.
530 End
2018-11-15 14:25:45,421 root:push_plate_no:402  > INFO: 
2018-11-15 14:25:45,421 root:push_plate_no:403  > INFO: --- v1_push plate no ---
2018-11-15 14:25:45,421 root:push_plate_no:404  > INFO: Plateno=PUTRAJAYA123<<>>Camera_sn=00000000-00000000<<>>Maxpark_camera_id=1000
2018-11-15 14:25:45,421 root:push_plate_no:406  > INFO: Communicating with Comms Module
2018-11-15 14:25:45,421 LA_Commons:calculate_checksum:43   > INFO: Checksum (numerical= 0x6c
2018-11-15 14:25:46,437 PUSH_plate_no:push_plate_no:122  > WARNING: Connection error: [WinError 10061] No connection could be made because the target machine actively refused it
2018-11-15 14:25:46,437 flask.app:log_exception:1761 > ERROR: Exception on /localagent/v1/push_plate_no [POST]
Traceback (most recent call last):
  File "C:\Users\Abdul Hadi\PycharmProjects\LPRLA\venv\lib\site-packages\flask\app.py", line 2292, in wsgi_app
    response = self.full_dispatch_request()
  File "C:\Users\Abdul Hadi\PycharmProjects\LPRLA\venv\lib\site-packages\flask\app.py", line 1815, in full_dispatch_request
    rv = self.handle_user_exception(e)
  File "C:\Users\Abdul Hadi\PycharmProjects\LPRLA\venv\lib\site-packages\flask\app.py", line 1718, in handle_user_exception
    reraise(exc_type, exc_value, tb)
  File "C:\Users\Abdul Hadi\PycharmProjects\LPRLA\venv\lib\site-packages\flask\_compat.py", line 35, in reraise
    raise value
  File "C:\Users\Abdul Hadi\PycharmProjects\LPRLA\venv\lib\site-packages\flask\app.py", line 1813, in full_dispatch_request
    rv = self.dispatch_request()
  File "C:\Users\Abdul Hadi\PycharmProjects\LPRLA\venv\lib\site-packages\flask\app.py", line 1799, in dispatch_request
    return self.view_functions[rule.endpoint](**req.view_args)
  File "C:/Users/Abdul Hadi/PycharmProjects/LPRLA/lpr_localagent.py", line 412, in push_plate_no
    plate_no,maxpark_cam_id)
  File "C:\Users\Abdul Hadi\PycharmProjects\LPRLA\PUSH_plate_no.py", line 135, in push_plate_no
    cars = array(['b', xxx])
TypeError: array() argument 1 must be a unicode character, not list
2018-11-15 14:25:46,437 werkzeug:_log:88   > INFO: 127.0.0.1 - - [15/Nov/2018 14:25:46] "POST /localagent/v1/push_plate_no HTTP/1.1" 500 -
2018-11-15 14:26:59,352 root:main:195  > CRITICAL: 
 --- Application started & 'main' was called. This is not really Critical. --- 

2018-11-15 14:26:59,352 root:main:202  > INFO: PNS App Services IP Address White List:
2018-11-15 14:26:59,352 root:main:203  > INFO: ['35.162.219.50', '52.77.93.214', '13.228.1.86', '54.169.137.81', '127.0.0.1']
2018-11-15 14:27:00,446 werkzeug:_log:88   > INFO:  * Running on http://0.0.0.0:5001/ (Press CTRL+C to quit)
2018-11-15 14:27:02,350 root:push_plate_no:397  > ERROR: Failed to connect to ftp server using given info host=127.0.0.1 , username=hadi , password=hadi123 ,folder=vehicle_plate , 530-User cannot log in.
 Win32 error:   The user name or password is incorrect. 
 Error details: An error occurred during the authentication process.
530 End
2018-11-15 14:27:02,350 root:push_plate_no:402  > INFO: 
2018-11-15 14:27:02,350 root:push_plate_no:403  > INFO: --- v1_push plate no ---
2018-11-15 14:27:02,350 root:push_plate_no:404  > INFO: Plateno=PUTRAJAYA123<<>>Camera_sn=00000000-00000000<<>>Maxpark_camera_id=1000
2018-11-15 14:27:02,350 root:push_plate_no:406  > INFO: Communicating with Comms Module
2018-11-15 14:27:02,350 LA_Commons:calculate_checksum:43   > INFO: Checksum (numerical= 0x6c
2018-11-15 14:27:03,371 PUSH_plate_no:push_plate_no:122  > WARNING: Connection error: [WinError 10061] No connection could be made because the target machine actively refused it
2018-11-15 14:27:08,380 PUSH_plate_no:push_plate_no:142  > ERROR: failed to sent packet to comm module
2018-11-15 14:27:08,380 root:push_plate_no:413  > INFO: response : false
2018-11-15 14:27:08,380 werkzeug:_log:88   > INFO: 127.0.0.1 - - [15/Nov/2018 14:27:08] "POST /localagent/v1/push_plate_no HTTP/1.1" 400 -
2018-11-15 14:27:29,406 root:push_plate_no:397  > ERROR: Failed to connect to ftp server using given info host=127.0.0.1 , username=hadi , password=hadi123 ,folder=vehicle_plate , 530-User cannot log in.
 Win32 error:   The user name or password is incorrect. 
 Error details: An error occurred during the authentication process.
530 End
2018-11-15 14:27:29,406 root:push_plate_no:402  > INFO: 
2018-11-15 14:27:29,406 root:push_plate_no:403  > INFO: --- v1_push plate no ---
2018-11-15 14:27:29,406 root:push_plate_no:404  > INFO: Plateno=PUTRAJAYA123<<>>Camera_sn=00000000-00000000<<>>Maxpark_camera_id=1000
2018-11-15 14:27:29,406 root:push_plate_no:406  > INFO: Communicating with Comms Module
2018-11-15 14:27:29,410 LA_Commons:calculate_checksum:43   > INFO: Checksum (numerical= 0x6c
2018-11-15 14:27:30,412 PUSH_plate_no:push_plate_no:122  > WARNING: Connection error: [WinError 10061] No connection could be made because the target machine actively refused it
2018-11-15 14:27:35,424 PUSH_plate_no:push_plate_no:142  > ERROR: failed to sent packet to comm module
2018-11-15 14:27:35,424 root:push_plate_no:413  > INFO: response : false
2018-11-15 14:27:35,424 werkzeug:_log:88   > INFO: 127.0.0.1 - - [15/Nov/2018 14:27:35] "POST /localagent/v1/push_plate_no HTTP/1.1" 400 -
2018-11-15 14:27:46,126 root:push_plate_no:397  > ERROR: Failed to connect to ftp server using given info host=127.0.0.1 , username=hadi , password=hadi123 ,folder=vehicle_plate , 530-User cannot log in.
 Win32 error:   The user name or password is incorrect. 
 Error details: An error occurred during the authentication process.
530 End
2018-11-15 14:27:46,126 root:push_plate_no:402  > INFO: 
2018-11-15 14:27:46,126 root:push_plate_no:403  > INFO: --- v1_push plate no ---
2018-11-15 14:27:46,126 root:push_plate_no:404  > INFO: Plateno=PUTRAJAYA123<<>>Camera_sn=00000000-00000000<<>>Maxpark_camera_id=1000
2018-11-15 14:27:46,126 root:push_plate_no:406  > INFO: Communicating with Comms Module
2018-11-15 14:27:46,126 LA_Commons:calculate_checksum:43   > INFO: Checksum (numerical= 0x6c
2018-11-15 14:27:51,161 PUSH_plate_no:push_plate_no:157  > WARNING: Timeout. Close connection
2018-11-15 14:27:51,161 flask.app:log_exception:1761 > ERROR: Exception on /localagent/v1/push_plate_no [POST]
Traceback (most recent call last):
  File "C:\Users\Abdul Hadi\PycharmProjects\LPRLA\venv\lib\site-packages\flask\app.py", line 2292, in wsgi_app
    response = self.full_dispatch_request()
  File "C:\Users\Abdul Hadi\PycharmProjects\LPRLA\venv\lib\site-packages\flask\app.py", line 1815, in full_dispatch_request
    rv = self.handle_user_exception(e)
  File "C:\Users\Abdul Hadi\PycharmProjects\LPRLA\venv\lib\site-packages\flask\app.py", line 1718, in handle_user_exception
    reraise(exc_type, exc_value, tb)
  File "C:\Users\Abdul Hadi\PycharmProjects\LPRLA\venv\lib\site-packages\flask\_compat.py", line 35, in reraise
    raise value
  File "C:\Users\Abdul Hadi\PycharmProjects\LPRLA\venv\lib\site-packages\flask\app.py", line 1813, in full_dispatch_request
    rv = self.dispatch_request()
  File "C:\Users\Abdul Hadi\PycharmProjects\LPRLA\venv\lib\site-packages\flask\app.py", line 1799, in dispatch_request
    return self.view_functions[rule.endpoint](**req.view_args)
  File "C:/Users/Abdul Hadi/PycharmProjects/LPRLA/lpr_localagent.py", line 412, in push_plate_no
    plate_no,maxpark_cam_id)
  File "C:\Users\Abdul Hadi\PycharmProjects\LPRLA\PUSH_plate_no.py", line 169, in push_plate_no
    RECV_MSG = [ord(c) for c in msg]
UnboundLocalError: local variable 'msg' referenced before assignment
2018-11-15 14:27:51,161 werkzeug:_log:88   > INFO: 127.0.0.1 - - [15/Nov/2018 14:27:51] "POST /localagent/v1/push_plate_no HTTP/1.1" 500 -
2018-11-15 14:28:20,148 root:main:195  > CRITICAL: 
 --- Application started & 'main' was called. This is not really Critical. --- 

2018-11-15 14:28:20,148 root:main:202  > INFO: PNS App Services IP Address White List:
2018-11-15 14:28:20,148 root:main:203  > INFO: ['35.162.219.50', '52.77.93.214', '13.228.1.86', '54.169.137.81', '127.0.0.1']
2018-11-15 14:28:21,229 werkzeug:_log:88   > INFO:  * Running on http://0.0.0.0:5001/ (Press CTRL+C to quit)
2018-11-15 14:28:26,457 root:push_plate_no:397  > ERROR: Failed to connect to ftp server using given info host=127.0.0.1 , username=hadi , password=hadi123 ,folder=vehicle_plate , 530-User cannot log in.
 Win32 error:   The user name or password is incorrect. 
 Error details: An error occurred during the authentication process.
530 End
2018-11-15 14:28:26,457 root:push_plate_no:402  > INFO: 
2018-11-15 14:28:26,457 root:push_plate_no:403  > INFO: --- v1_push plate no ---
2018-11-15 14:28:26,457 root:push_plate_no:404  > INFO: Plateno=PUTRAJAYA123<<>>Camera_sn=00000000-00000000<<>>Maxpark_camera_id=1000
2018-11-15 14:28:26,457 root:push_plate_no:406  > INFO: Communicating with Comms Module
2018-11-15 14:28:26,457 LA_Commons:calculate_checksum:43   > INFO: Checksum (numerical= 0x6c
2018-11-15 14:28:26,457 PUSH_plate_no:push_plate_no:142  > ERROR: failed to sent packet to comm module
2018-11-15 14:28:26,473 root:push_plate_no:413  > INFO: response : false
2018-11-15 14:28:26,473 werkzeug:_log:88   > INFO: 127.0.0.1 - - [15/Nov/2018 14:28:26] "POST /localagent/v1/push_plate_no HTTP/1.1" 400 -
2018-11-15 14:29:02,453 root:main:195  > CRITICAL: 
 --- Application started & 'main' was called. This is not really Critical. --- 

2018-11-15 14:29:02,453 root:main:202  > INFO: PNS App Services IP Address White List:
2018-11-15 14:29:02,453 root:main:203  > INFO: ['35.162.219.50', '52.77.93.214', '13.228.1.86', '54.169.137.81', '127.0.0.1']
2018-11-15 14:29:03,494 werkzeug:_log:88   > INFO:  * Running on http://0.0.0.0:5001/ (Press CTRL+C to quit)
2018-11-15 14:29:06,177 root:push_plate_no:397  > ERROR: Failed to connect to ftp server using given info host=127.0.0.1 , username=hadi , password=hadi123 ,folder=vehicle_plate , 530-User cannot log in.
 Win32 error:   The user name or password is incorrect. 
 Error details: An error occurred during the authentication process.
530 End
2018-11-15 14:29:06,177 root:push_plate_no:402  > INFO: 
2018-11-15 14:29:06,177 root:push_plate_no:403  > INFO: --- v1_push plate no ---
2018-11-15 14:29:06,177 root:push_plate_no:404  > INFO: Plateno=PUTRAJAYA123<<>>Camera_sn=00000000-00000000<<>>Maxpark_camera_id=1000
2018-11-15 14:29:06,177 root:push_plate_no:406  > INFO: Communicating with Comms Module
2018-11-15 14:29:06,177 LA_Commons:calculate_checksum:43   > INFO: Checksum (numerical= 0x6c
2018-11-15 14:29:11,193 PUSH_plate_no:push_plate_no:157  > WARNING: Timeout. Close connection
2018-11-15 14:29:11,193 flask.app:log_exception:1761 > ERROR: Exception on /localagent/v1/push_plate_no [POST]
Traceback (most recent call last):
  File "C:\Users\Abdul Hadi\PycharmProjects\LPRLA\venv\lib\site-packages\flask\app.py", line 2292, in wsgi_app
    response = self.full_dispatch_request()
  File "C:\Users\Abdul Hadi\PycharmProjects\LPRLA\venv\lib\site-packages\flask\app.py", line 1815, in full_dispatch_request
    rv = self.handle_user_exception(e)
  File "C:\Users\Abdul Hadi\PycharmProjects\LPRLA\venv\lib\site-packages\flask\app.py", line 1718, in handle_user_exception
    reraise(exc_type, exc_value, tb)
  File "C:\Users\Abdul Hadi\PycharmProjects\LPRLA\venv\lib\site-packages\flask\_compat.py", line 35, in reraise
    raise value
  File "C:\Users\Abdul Hadi\PycharmProjects\LPRLA\venv\lib\site-packages\flask\app.py", line 1813, in full_dispatch_request
    rv = self.dispatch_request()
  File "C:\Users\Abdul Hadi\PycharmProjects\LPRLA\venv\lib\site-packages\flask\app.py", line 1799, in dispatch_request
    return self.view_functions[rule.endpoint](**req.view_args)
  File "C:/Users/Abdul Hadi/PycharmProjects/LPRLA/lpr_localagent.py", line 412, in push_plate_no
    plate_no,maxpark_cam_id)
  File "C:\Users\Abdul Hadi\PycharmProjects\LPRLA\PUSH_plate_no.py", line 169, in push_plate_no
    RECV_MSG = [ord(c) for c in msg]
UnboundLocalError: local variable 'msg' referenced before assignment
2018-11-15 14:29:11,193 werkzeug:_log:88   > INFO: 127.0.0.1 - - [15/Nov/2018 14:29:11] "POST /localagent/v1/push_plate_no HTTP/1.1" 500 -
2018-11-15 14:29:45,885 root:main:195  > CRITICAL: 
 --- Application started & 'main' was called. This is not really Critical. --- 

2018-11-15 14:29:45,885 root:main:202  > INFO: PNS App Services IP Address White List:
2018-11-15 14:29:45,885 root:main:203  > INFO: ['35.162.219.50', '52.77.93.214', '13.228.1.86', '54.169.137.81', '127.0.0.1']
2018-11-15 14:29:46,956 werkzeug:_log:88   > INFO:  * Running on http://0.0.0.0:5001/ (Press CTRL+C to quit)
2018-11-15 14:29:53,671 root:push_plate_no:397  > ERROR: Failed to connect to ftp server using given info host=127.0.0.1 , username=hadi , password=hadi123 ,folder=vehicle_plate , 530-User cannot log in.
 Win32 error:   The user name or password is incorrect. 
 Error details: An error occurred during the authentication process.
530 End
2018-11-15 14:29:53,671 root:push_plate_no:402  > INFO: 
2018-11-15 14:29:53,671 root:push_plate_no:403  > INFO: --- v1_push plate no ---
2018-11-15 14:29:53,671 root:push_plate_no:404  > INFO: Plateno=PUTRAJAYA123<<>>Camera_sn=00000000-00000000<<>>Maxpark_camera_id=1000
2018-11-15 14:29:53,671 root:push_plate_no:406  > INFO: Communicating with Comms Module
2018-11-15 14:29:53,671 LA_Commons:calculate_checksum:43   > INFO: Checksum (numerical= 0x6c
2018-11-15 14:29:53,723 root:push_plate_no:413  > INFO: response : [2, 69, 82, 79, 82, 76, 68, 49, 48, 48, 48, 80, 85, 84, 82, 65, 74, 65, 89, 65, 49, 50, 51, 48, 48, 55, 75, 105, 112, 108, 101, 80, 97, 114, 107, 64, 108, 3, 13]
2018-11-15 14:29:53,727 werkzeug:_log:88   > INFO: 127.0.0.1 - - [15/Nov/2018 14:29:53] "POST /localagent/v1/push_plate_no HTTP/1.1" 200 -
2018-11-15 14:32:57,297 root:main:195  > CRITICAL: 
 --- Application started & 'main' was called. This is not really Critical. --- 

2018-11-15 14:32:57,297 root:main:202  > INFO: PNS App Services IP Address White List:
2018-11-15 14:32:57,297 root:main:203  > INFO: ['35.162.219.50', '52.77.93.214', '13.228.1.86', '54.169.137.81', '127.0.0.1']
2018-11-15 14:32:58,343 werkzeug:_log:88   > INFO:  * Running on http://0.0.0.0:5001/ (Press CTRL+C to quit)
2018-11-15 14:33:03,684 root:push_plate_no:397  > ERROR: Failed to connect to ftp server using given info host=127.0.0.1 , username=hadi , password=hadi123 ,folder=vehicle_plate , 530-User cannot log in.
 Win32 error:   The user name or password is incorrect. 
 Error details: An error occurred during the authentication process.
530 End
2018-11-15 14:33:03,684 root:push_plate_no:402  > INFO: 
2018-11-15 14:33:03,684 root:push_plate_no:403  > INFO: --- v1_push plate no ---
2018-11-15 14:33:03,684 root:push_plate_no:404  > INFO: Plateno=PUTRAJAYA123<<>>Camera_sn=00000000-00000000<<>>Maxpark_camera_id=1000
2018-11-15 14:33:03,684 root:push_plate_no:406  > INFO: Communicating with Comms Module
2018-11-15 14:33:03,688 LA_Commons:calculate_checksum:43   > INFO: Checksum (numerical= 0x6c
2018-11-15 14:33:24,602 root:push_plate_no:397  > ERROR: Failed to connect to ftp server using given info host=127.0.0.1 , username=hadi , password=hadi123 ,folder=vehicle_plate , 530-User cannot log in.
 Win32 error:   The user name or password is incorrect. 
 Error details: An error occurred during the authentication process.
530 End
2018-11-15 14:33:24,602 root:push_plate_no:402  > INFO: 
2018-11-15 14:33:24,602 root:push_plate_no:403  > INFO: --- v1_push plate no ---
2018-11-15 14:33:24,602 root:push_plate_no:404  > INFO: Plateno=PUTRAJAYA123<<>>Camera_sn=00000000-00000000<<>>Maxpark_camera_id=1000
2018-11-15 14:33:24,602 root:push_plate_no:406  > INFO: Communicating with Comms Module
2018-11-15 14:33:24,605 LA_Commons:calculate_checksum:43   > INFO: Checksum (numerical= 0x6c
2018-11-15 14:33:25,620 PUSH_plate_no:push_plate_no:122  > WARNING: Connection error: [WinError 10061] No connection could be made because the target machine actively refused it
2018-11-15 14:34:27,864 root:main:195  > CRITICAL: 
 --- Application started & 'main' was called. This is not really Critical. --- 

2018-11-15 14:34:27,864 root:main:202  > INFO: PNS App Services IP Address White List:
2018-11-15 14:34:27,864 root:main:203  > INFO: ['35.162.219.50', '52.77.93.214', '13.228.1.86', '54.169.137.81', '127.0.0.1']
2018-11-15 14:34:28,905 werkzeug:_log:88   > INFO:  * Running on http://0.0.0.0:5001/ (Press CTRL+C to quit)
2018-11-15 14:34:34,722 root:push_plate_no:397  > ERROR: Failed to connect to ftp server using given info host=127.0.0.1 , username=hadi , password=hadi123 ,folder=vehicle_plate , 530-User cannot log in.
 Win32 error:   The user name or password is incorrect. 
 Error details: An error occurred during the authentication process.
530 End
2018-11-15 14:34:34,722 root:push_plate_no:402  > INFO: 
2018-11-15 14:34:34,722 root:push_plate_no:403  > INFO: --- v1_push plate no ---
2018-11-15 14:34:34,722 root:push_plate_no:404  > INFO: Plateno=PUTRAJAYA123<<>>Camera_sn=00000000-00000000<<>>Maxpark_camera_id=1000
2018-11-15 14:34:34,722 root:push_plate_no:406  > INFO: Communicating with Comms Module
2018-11-15 14:34:34,722 LA_Commons:calculate_checksum:43   > INFO: Checksum (numerical= 0x6c
2018-11-15 14:35:12,104 root:main:195  > CRITICAL: 
 --- Application started & 'main' was called. This is not really Critical. --- 

2018-11-15 14:35:12,104 root:main:202  > INFO: PNS App Services IP Address White List:
2018-11-15 14:35:12,104 root:main:203  > INFO: ['35.162.219.50', '52.77.93.214', '13.228.1.86', '54.169.137.81', '127.0.0.1']
2018-11-15 14:35:13,177 werkzeug:_log:88   > INFO:  * Running on http://0.0.0.0:5001/ (Press CTRL+C to quit)
2018-11-15 14:35:15,328 root:push_plate_no:397  > ERROR: Failed to connect to ftp server using given info host=127.0.0.1 , username=hadi , password=hadi123 ,folder=vehicle_plate , 530-User cannot log in.
 Win32 error:   The user name or password is incorrect. 
 Error details: An error occurred during the authentication process.
530 End
2018-11-15 14:35:15,328 root:push_plate_no:402  > INFO: 
2018-11-15 14:35:15,328 root:push_plate_no:403  > INFO: --- v1_push plate no ---
2018-11-15 14:35:15,328 root:push_plate_no:404  > INFO: Plateno=PUTRAJAYA123<<>>Camera_sn=00000000-00000000<<>>Maxpark_camera_id=1000
2018-11-15 14:35:15,328 root:push_plate_no:406  > INFO: Communicating with Comms Module
2018-11-15 14:35:15,328 LA_Commons:calculate_checksum:43   > INFO: Checksum (numerical= 0x6c
2018-11-15 14:36:25,611 root:main:195  > CRITICAL: 
 --- Application started & 'main' was called. This is not really Critical. --- 

2018-11-15 14:36:25,611 root:main:202  > INFO: PNS App Services IP Address White List:
2018-11-15 14:36:25,611 root:main:203  > INFO: ['35.162.219.50', '52.77.93.214', '13.228.1.86', '54.169.137.81', '127.0.0.1']
2018-11-15 14:36:26,671 werkzeug:_log:88   > INFO:  * Running on http://0.0.0.0:5001/ (Press CTRL+C to quit)
2018-11-15 14:36:29,185 root:push_plate_no:397  > ERROR: Failed to connect to ftp server using given info host=127.0.0.1 , username=hadi , password=hadi123 ,folder=vehicle_plate , 530-User cannot log in.
 Win32 error:   The user name or password is incorrect. 
 Error details: An error occurred during the authentication process.
530 End
2018-11-15 14:36:29,185 root:push_plate_no:402  > INFO: 
2018-11-15 14:36:29,185 root:push_plate_no:403  > INFO: --- v1_push plate no ---
2018-11-15 14:36:29,185 root:push_plate_no:404  > INFO: Plateno=PUTRAJAYA123<<>>Camera_sn=00000000-00000000<<>>Maxpark_camera_id=1000
2018-11-15 14:36:29,185 root:push_plate_no:406  > INFO: Communicating with Comms Module
2018-11-15 14:36:29,185 LA_Commons:calculate_checksum:43   > INFO: Checksum (numerical= 0x6c
2018-11-15 14:37:08,941 root:push_plate_no:397  > ERROR: Failed to connect to ftp server using given info host=127.0.0.1 , username=hadi , password=hadi123 ,folder=vehicle_plate , 530-User cannot log in.
 Win32 error:   The user name or password is incorrect. 
 Error details: An error occurred during the authentication process.
530 End
2018-11-15 14:37:08,941 root:push_plate_no:402  > INFO: 
2018-11-15 14:37:08,941 root:push_plate_no:403  > INFO: --- v1_push plate no ---
2018-11-15 14:37:08,941 root:push_plate_no:404  > INFO: Plateno=PUTRAJAYA123<<>>Camera_sn=00000000-00000000<<>>Maxpark_camera_id=1000
2018-11-15 14:37:08,941 root:push_plate_no:406  > INFO: Communicating with Comms Module
2018-11-15 14:37:08,941 LA_Commons:calculate_checksum:43   > INFO: Checksum (numerical= 0x6c
2018-11-15 14:37:12,181 root:main:195  > CRITICAL: 
 --- Application started & 'main' was called. This is not really Critical. --- 

2018-11-15 14:37:12,181 root:main:202  > INFO: PNS App Services IP Address White List:
2018-11-15 14:37:12,181 root:main:203  > INFO: ['35.162.219.50', '52.77.93.214', '13.228.1.86', '54.169.137.81', '127.0.0.1']
2018-11-15 14:37:13,282 werkzeug:_log:88   > INFO:  * Running on http://0.0.0.0:5001/ (Press CTRL+C to quit)
2018-11-15 14:37:15,797 root:push_plate_no:397  > ERROR: Failed to connect to ftp server using given info host=127.0.0.1 , username=hadi , password=hadi123 ,folder=vehicle_plate , 530-User cannot log in.
 Win32 error:   The user name or password is incorrect. 
 Error details: An error occurred during the authentication process.
530 End
2018-11-15 14:37:15,797 root:push_plate_no:402  > INFO: 
2018-11-15 14:37:15,797 root:push_plate_no:403  > INFO: --- v1_push plate no ---
2018-11-15 14:37:15,797 root:push_plate_no:404  > INFO: Plateno=PUTRAJAYA123<<>>Camera_sn=00000000-00000000<<>>Maxpark_camera_id=1000
2018-11-15 14:37:15,797 root:push_plate_no:406  > INFO: Communicating with Comms Module
2018-11-15 14:37:15,797 LA_Commons:calculate_checksum:43   > INFO: Checksum (numerical= 0x6c
2018-11-15 14:37:16,824 PUSH_plate_no:push_plate_no:126  > WARNING: Connection error: [WinError 10061] No connection could be made because the target machine actively refused it
2018-11-15 14:37:21,830 PUSH_plate_no:push_plate_no:147  > ERROR: failed to sent packet to comm module
2018-11-15 14:37:21,830 root:push_plate_no:413  > INFO: response : false
2018-11-15 14:37:21,830 werkzeug:_log:88   > INFO: 127.0.0.1 - - [15/Nov/2018 14:37:21] "POST /localagent/v1/push_plate_no HTTP/1.1" 400 -
2018-11-15 14:37:31,872 root:push_plate_no:397  > ERROR: Failed to connect to ftp server using given info host=127.0.0.1 , username=hadi , password=hadi123 ,folder=vehicle_plate , 530-User cannot log in.
 Win32 error:   The user name or password is incorrect. 
 Error details: An error occurred during the authentication process.
530 End
2018-11-15 14:37:31,872 root:push_plate_no:402  > INFO: 
2018-11-15 14:37:31,872 root:push_plate_no:403  > INFO: --- v1_push plate no ---
2018-11-15 14:37:31,876 root:push_plate_no:404  > INFO: Plateno=PUTRAJAYA123<<>>Camera_sn=00000000-00000000<<>>Maxpark_camera_id=1000
2018-11-15 14:37:31,876 root:push_plate_no:406  > INFO: Communicating with Comms Module
2018-11-15 14:37:31,876 LA_Commons:calculate_checksum:43   > INFO: Checksum (numerical= 0x6c
2018-11-15 14:37:31,880 root:push_plate_no:413  > INFO: response : [2, 69, 82, 79, 82, 76, 68, 49, 48, 48, 48, 80, 85, 84, 82, 65, 74, 65, 89, 65, 49, 50, 51, 48, 48, 55, 75, 105, 112, 108, 101, 80, 97, 114, 107, 64, 108, 3, 13]
2018-11-15 14:37:31,880 werkzeug:_log:88   > INFO: 127.0.0.1 - - [15/Nov/2018 14:37:31] "POST /localagent/v1/push_plate_no HTTP/1.1" 200 -
2018-11-15 14:37:57,312 root:main:195  > CRITICAL: 
 --- Application started & 'main' was called. This is not really Critical. --- 

2018-11-15 14:37:57,312 root:main:202  > INFO: PNS App Services IP Address White List:
2018-11-15 14:37:57,312 root:main:203  > INFO: ['35.162.219.50', '52.77.93.214', '13.228.1.86', '54.169.137.81', '127.0.0.1']
2018-11-15 14:37:58,360 werkzeug:_log:88   > INFO:  * Running on http://0.0.0.0:5001/ (Press CTRL+C to quit)
2018-11-15 14:38:00,534 root:push_plate_no:397  > ERROR: Failed to connect to ftp server using given info host=127.0.0.1 , username=hadi , password=hadi123 ,folder=vehicle_plate , 530-User cannot log in.
 Win32 error:   The user name or password is incorrect. 
 Error details: An error occurred during the authentication process.
530 End
2018-11-15 14:38:00,538 root:push_plate_no:402  > INFO: 
2018-11-15 14:38:00,538 root:push_plate_no:403  > INFO: --- v1_push plate no ---
2018-11-15 14:38:00,538 root:push_plate_no:404  > INFO: Plateno=PUTRAJAYA123<<>>Camera_sn=00000000-00000000<<>>Maxpark_camera_id=1000
2018-11-15 14:38:00,538 root:push_plate_no:406  > INFO: Communicating with Comms Module
2018-11-15 14:38:00,538 LA_Commons:calculate_checksum:43   > INFO: Checksum (numerical= 0x6c
2018-11-15 14:38:00,550 root:push_plate_no:413  > INFO: response : [2, 69, 82, 79, 82, 76, 68, 49, 48, 48, 48, 80, 85, 84, 82, 65, 74, 65, 89, 65, 49, 50, 51, 48, 48, 55, 75, 105, 112, 108, 101, 80, 97, 114, 107, 64, 108, 3, 13]
2018-11-15 14:38:00,554 werkzeug:_log:88   > INFO: 127.0.0.1 - - [15/Nov/2018 14:38:00] "POST /localagent/v1/push_plate_no HTTP/1.1" 200 -
2018-11-15 14:38:49,735 root:main:195  > CRITICAL: 
 --- Application started & 'main' was called. This is not really Critical. --- 

2018-11-15 14:38:49,735 root:main:202  > INFO: PNS App Services IP Address White List:
2018-11-15 14:38:49,735 root:main:203  > INFO: ['35.162.219.50', '52.77.93.214', '13.228.1.86', '54.169.137.81', '127.0.0.1']
2018-11-15 14:38:50,828 werkzeug:_log:88   > INFO:  * Running on http://0.0.0.0:5001/ (Press CTRL+C to quit)
2018-11-15 14:38:53,715 root:push_plate_no:397  > ERROR: Failed to connect to ftp server using given info host=127.0.0.1 , username=hadi , password=hadi123 ,folder=vehicle_plate , 530-User cannot log in.
 Win32 error:   The user name or password is incorrect. 
 Error details: An error occurred during the authentication process.
530 End
2018-11-15 14:38:53,715 root:push_plate_no:402  > INFO: 
2018-11-15 14:38:53,715 root:push_plate_no:403  > INFO: --- v1_push plate no ---
2018-11-15 14:38:53,715 root:push_plate_no:404  > INFO: Plateno=PUTRAJAYA123<<>>Camera_sn=00000000-00000000<<>>Maxpark_camera_id=1000
2018-11-15 14:38:53,715 root:push_plate_no:406  > INFO: Communicating with Comms Module
2018-11-15 14:38:53,715 LA_Commons:calculate_checksum:43   > INFO: Checksum (numerical= 0x6c
2018-11-15 14:38:53,731 root:push_plate_no:413  > INFO: response : [2, 69, 82, 79, 82, 76, 68, 49, 48, 48, 48, 80, 85, 84, 82, 65, 74, 65, 89, 65, 49, 50, 51, 48, 48, 55, 75, 105, 112, 108, 101, 80, 97, 114, 107, 64, 3, 13]
2018-11-15 14:38:53,735 werkzeug:_log:88   > INFO: 127.0.0.1 - - [15/Nov/2018 14:38:53] "POST /localagent/v1/push_plate_no HTTP/1.1" 200 -
2018-11-15 14:39:14,837 root:main:195  > CRITICAL: 
 --- Application started & 'main' was called. This is not really Critical. --- 

2018-11-15 14:39:14,837 root:main:202  > INFO: PNS App Services IP Address White List:
2018-11-15 14:39:14,837 root:main:203  > INFO: ['35.162.219.50', '52.77.93.214', '13.228.1.86', '54.169.137.81', '127.0.0.1']
2018-11-15 14:39:15,887 werkzeug:_log:88   > INFO:  * Running on http://0.0.0.0:5001/ (Press CTRL+C to quit)
2018-11-15 14:39:19,108 root:push_plate_no:397  > ERROR: Failed to connect to ftp server using given info host=127.0.0.1 , username=hadi , password=hadi123 ,folder=vehicle_plate , 530-User cannot log in.
 Win32 error:   The user name or password is incorrect. 
 Error details: An error occurred during the authentication process.
530 End
2018-11-15 14:39:19,108 root:push_plate_no:402  > INFO: 
2018-11-15 14:39:19,108 root:push_plate_no:403  > INFO: --- v1_push plate no ---
2018-11-15 14:39:19,108 root:push_plate_no:404  > INFO: Plateno=PUTRAJAYA123<<>>Camera_sn=00000000-00000000<<>>Maxpark_camera_id=1000
2018-11-15 14:39:19,108 root:push_plate_no:406  > INFO: Communicating with Comms Module
2018-11-15 14:39:19,108 LA_Commons:calculate_checksum:43   > INFO: Checksum (numerical= 0x6c
2018-11-15 14:39:19,128 root:push_plate_no:413  > INFO: response : [2, 69, 82, 79, 82, 76, 68, 49, 48, 48, 48, 80, 85, 84, 82, 65, 74, 65, 89, 65, 49, 50, 51, 48, 48, 55, 75, 105, 112, 108, 101, 80, 97, 114, 107, 64, 3, 13]
2018-11-15 14:39:19,128 werkzeug:_log:88   > INFO: 127.0.0.1 - - [15/Nov/2018 14:39:19] "POST /localagent/v1/push_plate_no HTTP/1.1" 200 -
2018-11-15 14:39:41,175 root:main:195  > CRITICAL: 
 --- Application started & 'main' was called. This is not really Critical. --- 

2018-11-15 14:39:41,175 root:main:202  > INFO: PNS App Services IP Address White List:
2018-11-15 14:39:41,175 root:main:203  > INFO: ['35.162.219.50', '52.77.93.214', '13.228.1.86', '54.169.137.81', '127.0.0.1']
2018-11-15 14:39:42,211 werkzeug:_log:88   > INFO:  * Running on http://0.0.0.0:5001/ (Press CTRL+C to quit)
2018-11-15 14:39:44,932 root:push_plate_no:397  > ERROR: Failed to connect to ftp server using given info host=127.0.0.1 , username=hadi , password=hadi123 ,folder=vehicle_plate , 530-User cannot log in.
 Win32 error:   The user name or password is incorrect. 
 Error details: An error occurred during the authentication process.
530 End
2018-11-15 14:39:44,932 root:push_plate_no:402  > INFO: 
2018-11-15 14:39:44,932 root:push_plate_no:403  > INFO: --- v1_push plate no ---
2018-11-15 14:39:44,932 root:push_plate_no:404  > INFO: Plateno=PUTRAJAYA123<<>>Camera_sn=00000000-00000000<<>>Maxpark_camera_id=1000
2018-11-15 14:39:44,932 root:push_plate_no:406  > INFO: Communicating with Comms Module
2018-11-15 14:39:44,932 LA_Commons:calculate_checksum:43   > INFO: Checksum (numerical= 0x6c
2018-11-15 14:39:49,935 PUSH_plate_no:push_plate_no:163  > WARNING: Timeout. Close connection
2018-11-15 14:39:49,935 flask.app:log_exception:1761 > ERROR: Exception on /localagent/v1/push_plate_no [POST]
Traceback (most recent call last):
  File "C:\Users\Abdul Hadi\PycharmProjects\LPRLA\venv\lib\site-packages\flask\app.py", line 2292, in wsgi_app
    response = self.full_dispatch_request()
  File "C:\Users\Abdul Hadi\PycharmProjects\LPRLA\venv\lib\site-packages\flask\app.py", line 1815, in full_dispatch_request
    rv = self.handle_user_exception(e)
  File "C:\Users\Abdul Hadi\PycharmProjects\LPRLA\venv\lib\site-packages\flask\app.py", line 1718, in handle_user_exception
    reraise(exc_type, exc_value, tb)
  File "C:\Users\Abdul Hadi\PycharmProjects\LPRLA\venv\lib\site-packages\flask\_compat.py", line 35, in reraise
    raise value
  File "C:\Users\Abdul Hadi\PycharmProjects\LPRLA\venv\lib\site-packages\flask\app.py", line 1813, in full_dispatch_request
    rv = self.dispatch_request()
  File "C:\Users\Abdul Hadi\PycharmProjects\LPRLA\venv\lib\site-packages\flask\app.py", line 1799, in dispatch_request
    return self.view_functions[rule.endpoint](**req.view_args)
  File "C:/Users/Abdul Hadi/PycharmProjects/LPRLA/lpr_localagent.py", line 412, in push_plate_no
    plate_no,maxpark_cam_id)
  File "C:\Users\Abdul Hadi\PycharmProjects\LPRLA\PUSH_plate_no.py", line 175, in push_plate_no
    RECV_MSG = [ord(c) for c in msg]
UnboundLocalError: local variable 'msg' referenced before assignment
2018-11-15 14:39:49,935 werkzeug:_log:88   > INFO: 127.0.0.1 - - [15/Nov/2018 14:39:49] "POST /localagent/v1/push_plate_no HTTP/1.1" 500 -
2018-11-15 14:40:51,967 root:main:195  > CRITICAL: 
 --- Application started & 'main' was called. This is not really Critical. --- 

2018-11-15 14:40:51,967 root:main:202  > INFO: PNS App Services IP Address White List:
2018-11-15 14:40:51,967 root:main:203  > INFO: ['35.162.219.50', '52.77.93.214', '13.228.1.86', '54.169.137.81', '127.0.0.1']
2018-11-15 14:40:53,066 werkzeug:_log:88   > INFO:  * Running on http://0.0.0.0:5001/ (Press CTRL+C to quit)
2018-11-15 14:54:21,779 root:push_plate_no:397  > ERROR: Failed to connect to ftp server using given info host=127.0.0.1 , username=hadi , password=hadi123 ,folder=vehicle_plate , 530-User cannot log in.
 Win32 error:   The user name or password is incorrect. 
 Error details: An error occurred during the authentication process.
530 End
2018-11-15 14:54:21,779 root:push_plate_no:402  > INFO: 
2018-11-15 14:54:21,779 root:push_plate_no:403  > INFO: --- v1_push plate no ---
2018-11-15 14:54:21,779 root:push_plate_no:404  > INFO: Plateno=PUTRAJAYA123<<>>Camera_sn=00000000-00000000<<>>Maxpark_camera_id=1000
2018-11-15 14:54:21,779 root:push_plate_no:406  > INFO: Communicating with Comms Module
2018-11-15 14:54:21,779 LA_Commons:calculate_checksum:43   > INFO: Checksum (numerical= 0x6c
2018-11-15 14:54:26,790 PUSH_plate_no:push_plate_no:163  > WARNING: Timeout. Close connection
2018-11-15 14:54:26,790 flask.app:log_exception:1761 > ERROR: Exception on /localagent/v1/push_plate_no [POST]
Traceback (most recent call last):
  File "C:\Users\Abdul Hadi\PycharmProjects\LPRLA\venv\lib\site-packages\flask\app.py", line 2292, in wsgi_app
    response = self.full_dispatch_request()
  File "C:\Users\Abdul Hadi\PycharmProjects\LPRLA\venv\lib\site-packages\flask\app.py", line 1815, in full_dispatch_request
    rv = self.handle_user_exception(e)
  File "C:\Users\Abdul Hadi\PycharmProjects\LPRLA\venv\lib\site-packages\flask\app.py", line 1718, in handle_user_exception
    reraise(exc_type, exc_value, tb)
  File "C:\Users\Abdul Hadi\PycharmProjects\LPRLA\venv\lib\site-packages\flask\_compat.py", line 35, in reraise
    raise value
  File "C:\Users\Abdul Hadi\PycharmProjects\LPRLA\venv\lib\site-packages\flask\app.py", line 1813, in full_dispatch_request
    rv = self.dispatch_request()
  File "C:\Users\Abdul Hadi\PycharmProjects\LPRLA\venv\lib\site-packages\flask\app.py", line 1799, in dispatch_request
    return self.view_functions[rule.endpoint](**req.view_args)
  File "C:/Users/Abdul Hadi/PycharmProjects/LPRLA/lpr_localagent.py", line 412, in push_plate_no
    plate_no,maxpark_cam_id)
  File "C:\Users\Abdul Hadi\PycharmProjects\LPRLA\PUSH_plate_no.py", line 175, in push_plate_no
    RECV_MSG = [ord(c) for c in msg]
UnboundLocalError: local variable 'msg' referenced before assignment
2018-11-15 14:54:26,790 werkzeug:_log:88   > INFO: 127.0.0.1 - - [15/Nov/2018 14:54:26] "POST /localagent/v1/push_plate_no HTTP/1.1" 500 -
2018-11-15 14:56:22,492 root:main:195  > CRITICAL: 
 --- Application started & 'main' was called. This is not really Critical. --- 

2018-11-15 14:56:22,492 root:main:202  > INFO: PNS App Services IP Address White List:
2018-11-15 14:56:22,492 root:main:203  > INFO: ['35.162.219.50', '52.77.93.214', '13.228.1.86', '54.169.137.81', '127.0.0.1']
2018-11-15 14:56:23,667 werkzeug:_log:88   > INFO:  * Running on http://0.0.0.0:5001/ (Press CTRL+C to quit)
2018-11-15 14:56:28,453 root:push_plate_no:397  > ERROR: Failed to connect to ftp server using given info host=127.0.0.1 , username=hadi , password=hadi123 ,folder=vehicle_plate , 530-User cannot log in.
 Win32 error:   The user name or password is incorrect. 
 Error details: An error occurred during the authentication process.
530 End
2018-11-15 14:56:28,453 root:push_plate_no:402  > INFO: 
2018-11-15 14:56:28,453 root:push_plate_no:403  > INFO: --- v1_push plate no ---
2018-11-15 14:56:28,453 root:push_plate_no:404  > INFO: Plateno=PUTRAJAYA123<<>>Camera_sn=00000000-00000000<<>>Maxpark_camera_id=1000
2018-11-15 14:56:28,453 root:push_plate_no:406  > INFO: Communicating with Comms Module
2018-11-15 14:56:28,453 LA_Commons:calculate_checksum:43   > INFO: Checksum (numerical= 0x6c
2018-11-15 14:56:33,462 PUSH_plate_no:push_plate_no:163  > WARNING: Timeout. Close connection
2018-11-15 14:56:33,462 root:push_plate_no:413  > INFO: response : None
2018-11-15 14:56:33,462 werkzeug:_log:88   > INFO: 127.0.0.1 - - [15/Nov/2018 14:56:33] "POST /localagent/v1/push_plate_no HTTP/1.1" 200 -
2018-11-15 14:57:02,555 root:main:195  > CRITICAL: 
 --- Application started & 'main' was called. This is not really Critical. --- 

2018-11-15 14:57:02,555 root:main:202  > INFO: PNS App Services IP Address White List:
2018-11-15 14:57:02,555 root:main:203  > INFO: ['35.162.219.50', '52.77.93.214', '13.228.1.86', '54.169.137.81', '127.0.0.1']
2018-11-15 14:57:03,616 werkzeug:_log:88   > INFO:  * Running on http://0.0.0.0:5001/ (Press CTRL+C to quit)
2018-11-15 14:57:06,302 root:push_plate_no:397  > ERROR: Failed to connect to ftp server using given info host=127.0.0.1 , username=hadi , password=hadi123 ,folder=vehicle_plate , 530-User cannot log in.
 Win32 error:   The user name or password is incorrect. 
 Error details: An error occurred during the authentication process.
530 End
2018-11-15 14:57:06,302 root:push_plate_no:402  > INFO: 
2018-11-15 14:57:06,302 root:push_plate_no:403  > INFO: --- v1_push plate no ---
2018-11-15 14:57:06,302 root:push_plate_no:404  > INFO: Plateno=PUTRAJAYA123<<>>Camera_sn=00000000-00000000<<>>Maxpark_camera_id=1000
2018-11-15 14:57:06,302 root:push_plate_no:406  > INFO: Communicating with Comms Module
2018-11-15 14:57:06,302 LA_Commons:calculate_checksum:43   > INFO: Checksum (numerical= 0x6c
2018-11-15 14:57:11,304 PUSH_plate_no:push_plate_no:163  > WARNING: Timeout. Close connection
2018-11-15 14:57:11,304 root:push_plate_no:413  > INFO: response : None
2018-11-15 14:57:11,304 werkzeug:_log:88   > INFO: 127.0.0.1 - - [15/Nov/2018 14:57:11] "POST /localagent/v1/push_plate_no HTTP/1.1" 200 -
2018-11-15 15:01:35,204 root:main:195  > CRITICAL: 
 --- Application started & 'main' was called. This is not really Critical. --- 

2018-11-15 15:01:35,204 root:main:202  > INFO: PNS App Services IP Address White List:
2018-11-15 15:01:35,204 root:main:203  > INFO: ['35.162.219.50', '52.77.93.214', '13.228.1.86', '54.169.137.81', '127.0.0.1']
2018-11-15 15:01:36,270 werkzeug:_log:88   > INFO:  * Running on http://0.0.0.0:5001/ (Press CTRL+C to quit)
2018-11-15 15:01:41,036 root:push_plate_no:397  > ERROR: Failed to connect to ftp server using given info host=127.0.0.1 , username=hadi , password=hadi123 ,folder=vehicle_plate , 530-User cannot log in.
 Win32 error:   The user name or password is incorrect. 
 Error details: An error occurred during the authentication process.
530 End
2018-11-15 15:01:41,036 root:push_plate_no:402  > INFO: 
2018-11-15 15:01:41,036 root:push_plate_no:403  > INFO: --- v1_push plate no ---
2018-11-15 15:01:41,036 root:push_plate_no:404  > INFO: Plateno=PUTRAJAYA123<<>>Camera_sn=00000000-00000000<<>>Maxpark_camera_id=1000
2018-11-15 15:01:41,036 root:push_plate_no:406  > INFO: Communicating with Comms Module
2018-11-15 15:01:41,036 LA_Commons:calculate_checksum:43   > INFO: Checksum (numerical= 0x6c
2018-11-15 15:01:41,040 flask.app:log_exception:1761 > ERROR: Exception on /localagent/v1/push_plate_no [POST]
Traceback (most recent call last):
  File "C:\Users\Abdul Hadi\PycharmProjects\LPRLA\venv\lib\site-packages\flask\app.py", line 2292, in wsgi_app
    response = self.full_dispatch_request()
  File "C:\Users\Abdul Hadi\PycharmProjects\LPRLA\venv\lib\site-packages\flask\app.py", line 1815, in full_dispatch_request
    rv = self.handle_user_exception(e)
  File "C:\Users\Abdul Hadi\PycharmProjects\LPRLA\venv\lib\site-packages\flask\app.py", line 1718, in handle_user_exception
    reraise(exc_type, exc_value, tb)
  File "C:\Users\Abdul Hadi\PycharmProjects\LPRLA\venv\lib\site-packages\flask\_compat.py", line 35, in reraise
    raise value
  File "C:\Users\Abdul Hadi\PycharmProjects\LPRLA\venv\lib\site-packages\flask\app.py", line 1813, in full_dispatch_request
    rv = self.dispatch_request()
  File "C:\Users\Abdul Hadi\PycharmProjects\LPRLA\venv\lib\site-packages\flask\app.py", line 1799, in dispatch_request
    return self.view_functions[rule.endpoint](**req.view_args)
  File "C:/Users/Abdul Hadi/PycharmProjects/LPRLA/lpr_localagent.py", line 412, in push_plate_no
    plate_no,maxpark_cam_id)
  File "C:\Users\Abdul Hadi\PycharmProjects\LPRLA\PUSH_plate_no.py", line 152, in push_plate_no
    chunk = s.recv()
TypeError: recv() takes at least 1 argument (0 given)
2018-11-15 15:01:41,044 werkzeug:_log:88   > INFO: 127.0.0.1 - - [15/Nov/2018 15:01:41] "POST /localagent/v1/push_plate_no HTTP/1.1" 500 -
2018-11-15 15:09:59,856 root:main:195  > CRITICAL: 
 --- Application started & 'main' was called. This is not really Critical. --- 

2018-11-15 15:09:59,858 root:main:202  > INFO: PNS App Services IP Address White List:
2018-11-15 15:09:59,858 root:main:203  > INFO: ['35.162.219.50', '52.77.93.214', '13.228.1.86', '54.169.137.81', '127.0.0.1']
2018-11-15 15:10:01,342 werkzeug:_log:88   > INFO:  * Running on http://0.0.0.0:5001/ (Press CTRL+C to quit)
2018-11-15 15:10:09,923 root:push_plate_no:397  > ERROR: Failed to connect to ftp server using given info host=127.0.0.1 , username=hadi , password=hadi123 ,folder=vehicle_plate , 530-User cannot log in.
 Win32 error:   The user name or password is incorrect. 
 Error details: An error occurred during the authentication process.
530 End
2018-11-15 15:10:09,923 root:push_plate_no:402  > INFO: 
2018-11-15 15:10:09,923 root:push_plate_no:403  > INFO: --- v1_push plate no ---
2018-11-15 15:10:09,923 root:push_plate_no:404  > INFO: Plateno=PUTRAJAYA123<<>>Camera_sn=00000000-00000000<<>>Maxpark_camera_id=1000
2018-11-15 15:10:09,923 root:push_plate_no:406  > INFO: Communicating with Comms Module
2018-11-15 15:10:09,923 LA_Commons:calculate_checksum:43   > INFO: Checksum (numerical= 0x6c
2018-11-15 15:10:10,950 PUSH_plate_no:push_plate_no:128  > WARNING: Connection error: [WinError 10061] No connection could be made because the target machine actively refused it
2018-11-15 15:10:15,951 PUSH_plate_no:push_plate_no:149  > ERROR: failed to sent packet to comm module
2018-11-15 15:10:15,951 root:push_plate_no:413  > INFO: response : false
2018-11-15 15:10:15,951 werkzeug:_log:88   > INFO: 127.0.0.1 - - [15/Nov/2018 15:10:15] "POST /localagent/v1/push_plate_no HTTP/1.1" 400 -
2018-11-15 15:14:01,220 root:push_plate_no:397  > ERROR: Failed to connect to ftp server using given info host=127.0.0.1 , username=hadi , password=hadi123 ,folder=vehicle_plate , 530-User cannot log in.
 Win32 error:   The user name or password is incorrect. 
 Error details: An error occurred during the authentication process.
530 End
2018-11-15 15:14:01,220 root:push_plate_no:402  > INFO: 
2018-11-15 15:14:01,220 root:push_plate_no:403  > INFO: --- v1_push plate no ---
2018-11-15 15:14:01,220 root:push_plate_no:404  > INFO: Plateno=PUTRAJAYA123<<>>Camera_sn=00000000-00000000<<>>Maxpark_camera_id=1000
2018-11-15 15:14:01,220 root:push_plate_no:406  > INFO: Communicating with Comms Module
2018-11-15 15:14:01,220 LA_Commons:calculate_checksum:43   > INFO: Checksum (numerical= 0x6c
2018-11-15 15:14:06,222 flask.app:log_exception:1761 > ERROR: Exception on /localagent/v1/push_plate_no [POST]
Traceback (most recent call last):
  File "C:\Users\Abdul Hadi\PycharmProjects\LPRLA\venv\lib\site-packages\flask\app.py", line 2292, in wsgi_app
    response = self.full_dispatch_request()
  File "C:\Users\Abdul Hadi\PycharmProjects\LPRLA\venv\lib\site-packages\flask\app.py", line 1815, in full_dispatch_request
    rv = self.handle_user_exception(e)
  File "C:\Users\Abdul Hadi\PycharmProjects\LPRLA\venv\lib\site-packages\flask\app.py", line 1718, in handle_user_exception
    reraise(exc_type, exc_value, tb)
  File "C:\Users\Abdul Hadi\PycharmProjects\LPRLA\venv\lib\site-packages\flask\_compat.py", line 35, in reraise
    raise value
  File "C:\Users\Abdul Hadi\PycharmProjects\LPRLA\venv\lib\site-packages\flask\app.py", line 1813, in full_dispatch_request
    rv = self.dispatch_request()
  File "C:\Users\Abdul Hadi\PycharmProjects\LPRLA\venv\lib\site-packages\flask\app.py", line 1799, in dispatch_request
    return self.view_functions[rule.endpoint](**req.view_args)
  File "C:/Users/Abdul Hadi/PycharmProjects/LPRLA/lpr_localagent.py", line 412, in push_plate_no
    plate_no,maxpark_cam_id)
  File "C:\Users\Abdul Hadi\PycharmProjects\LPRLA\PUSH_plate_no.py", line 152, in push_plate_no
    chunk = s.recv(2048)
socket.timeout: timed out
2018-11-15 15:14:06,226 werkzeug:_log:88   > INFO: 127.0.0.1 - - [15/Nov/2018 15:14:06] "POST /localagent/v1/push_plate_no HTTP/1.1" 500 -
2018-11-15 15:14:47,714 root:main:195  > CRITICAL: 
 --- Application started & 'main' was called. This is not really Critical. --- 

2018-11-15 15:14:47,729 root:main:202  > INFO: PNS App Services IP Address White List:
2018-11-15 15:14:47,729 root:main:203  > INFO: ['35.162.219.50', '52.77.93.214', '13.228.1.86', '54.169.137.81', '127.0.0.1']
2018-11-15 15:14:48,765 werkzeug:_log:88   > INFO:  * Running on http://0.0.0.0:5001/ (Press CTRL+C to quit)
2018-11-15 15:14:50,955 root:push_plate_no:397  > ERROR: Failed to connect to ftp server using given info host=127.0.0.1 , username=hadi , password=hadi123 ,folder=vehicle_plate , 530-User cannot log in.
 Win32 error:   The user name or password is incorrect. 
 Error details: An error occurred during the authentication process.
530 End
2018-11-15 15:14:50,955 root:push_plate_no:402  > INFO: 
2018-11-15 15:14:50,955 root:push_plate_no:403  > INFO: --- v1_push plate no ---
2018-11-15 15:14:50,955 root:push_plate_no:404  > INFO: Plateno=PUTRAJAYA123<<>>Camera_sn=00000000-00000000<<>>Maxpark_camera_id=1000
2018-11-15 15:14:50,955 root:push_plate_no:406  > INFO: Communicating with Comms Module
2018-11-15 15:14:50,955 LA_Commons:calculate_checksum:43   > INFO: Checksum (numerical= 0x6c
2018-11-15 15:14:55,979 PUSH_plate_no:push_plate_no:167  > WARNING: Timeout. Close connection
2018-11-15 15:14:55,979 root:push_plate_no:413  > INFO: response : None
2018-11-15 15:14:55,979 werkzeug:_log:88   > INFO: 127.0.0.1 - - [15/Nov/2018 15:14:55] "POST /localagent/v1/push_plate_no HTTP/1.1" 200 -
2018-11-15 15:15:33,353 root:main:195  > CRITICAL: 
 --- Application started & 'main' was called. This is not really Critical. --- 

2018-11-15 15:15:33,353 root:main:202  > INFO: PNS App Services IP Address White List:
2018-11-15 15:15:33,353 root:main:203  > INFO: ['35.162.219.50', '52.77.93.214', '13.228.1.86', '54.169.137.81', '127.0.0.1']
2018-11-15 15:15:34,403 werkzeug:_log:88   > INFO:  * Running on http://0.0.0.0:5001/ (Press CTRL+C to quit)
2018-11-15 15:15:37,172 root:push_plate_no:397  > ERROR: Failed to connect to ftp server using given info host=127.0.0.1 , username=hadi , password=hadi123 ,folder=vehicle_plate , 530-User cannot log in.
 Win32 error:   The user name or password is incorrect. 
 Error details: An error occurred during the authentication process.
530 End
2018-11-15 15:15:37,172 root:push_plate_no:402  > INFO: 
2018-11-15 15:15:37,176 root:push_plate_no:403  > INFO: --- v1_push plate no ---
2018-11-15 15:15:37,176 root:push_plate_no:404  > INFO: Plateno=PUTRAJAYA123<<>>Camera_sn=00000000-00000000<<>>Maxpark_camera_id=1000
2018-11-15 15:15:37,176 root:push_plate_no:406  > INFO: Communicating with Comms Module
2018-11-15 15:15:37,176 LA_Commons:calculate_checksum:43   > INFO: Checksum (numerical= 0x6c
2018-11-15 15:15:37,188 flask.app:log_exception:1761 > ERROR: Exception on /localagent/v1/push_plate_no [POST]
Traceback (most recent call last):
  File "C:\Users\Abdul Hadi\PycharmProjects\LPRLA\venv\lib\site-packages\flask\app.py", line 2292, in wsgi_app
    response = self.full_dispatch_request()
  File "C:\Users\Abdul Hadi\PycharmProjects\LPRLA\venv\lib\site-packages\flask\app.py", line 1815, in full_dispatch_request
    rv = self.handle_user_exception(e)
  File "C:\Users\Abdul Hadi\PycharmProjects\LPRLA\venv\lib\site-packages\flask\app.py", line 1718, in handle_user_exception
    reraise(exc_type, exc_value, tb)
  File "C:\Users\Abdul Hadi\PycharmProjects\LPRLA\venv\lib\site-packages\flask\_compat.py", line 35, in reraise
    raise value
  File "C:\Users\Abdul Hadi\PycharmProjects\LPRLA\venv\lib\site-packages\flask\app.py", line 1813, in full_dispatch_request
    rv = self.dispatch_request()
  File "C:\Users\Abdul Hadi\PycharmProjects\LPRLA\venv\lib\site-packages\flask\app.py", line 1799, in dispatch_request
    return self.view_functions[rule.endpoint](**req.view_args)
  File "C:/Users/Abdul Hadi/PycharmProjects/LPRLA/lpr_localagent.py", line 412, in push_plate_no
    plate_no,maxpark_cam_id)
  File "C:\Users\Abdul Hadi\PycharmProjects\LPRLA\PUSH_plate_no.py", line 153, in push_plate_no
    print('chunk='+chunk)
TypeError: can only concatenate str (not "bytes") to str
2018-11-15 15:15:37,192 werkzeug:_log:88   > INFO: 127.0.0.1 - - [15/Nov/2018 15:15:37] "POST /localagent/v1/push_plate_no HTTP/1.1" 500 -
2018-11-15 15:15:49,068 root:main:195  > CRITICAL: 
 --- Application started & 'main' was called. This is not really Critical. --- 

2018-11-15 15:15:49,068 root:main:202  > INFO: PNS App Services IP Address White List:
2018-11-15 15:15:49,068 root:main:203  > INFO: ['35.162.219.50', '52.77.93.214', '13.228.1.86', '54.169.137.81', '127.0.0.1']
2018-11-15 15:15:50,108 werkzeug:_log:88   > INFO:  * Running on http://0.0.0.0:5001/ (Press CTRL+C to quit)
2018-11-15 15:15:53,174 root:push_plate_no:397  > ERROR: Failed to connect to ftp server using given info host=127.0.0.1 , username=hadi , password=hadi123 ,folder=vehicle_plate , 530-User cannot log in.
 Win32 error:   The user name or password is incorrect. 
 Error details: An error occurred during the authentication process.
530 End
2018-11-15 15:15:53,174 root:push_plate_no:402  > INFO: 
2018-11-15 15:15:53,178 root:push_plate_no:403  > INFO: --- v1_push plate no ---
2018-11-15 15:15:53,178 root:push_plate_no:404  > INFO: Plateno=PUTRAJAYA123<<>>Camera_sn=00000000-00000000<<>>Maxpark_camera_id=1000
2018-11-15 15:15:53,178 root:push_plate_no:406  > INFO: Communicating with Comms Module
2018-11-15 15:15:53,178 LA_Commons:calculate_checksum:43   > INFO: Checksum (numerical= 0x6c
2018-11-15 15:15:54,181 PUSH_plate_no:push_plate_no:128  > WARNING: Connection error: [WinError 10061] No connection could be made because the target machine actively refused it
2018-11-15 15:15:59,182 PUSH_plate_no:push_plate_no:149  > ERROR: failed to sent packet to comm module
2018-11-15 15:15:59,182 root:push_plate_no:413  > INFO: response : false
2018-11-15 15:15:59,182 werkzeug:_log:88   > INFO: 127.0.0.1 - - [15/Nov/2018 15:15:59] "POST /localagent/v1/push_plate_no HTTP/1.1" 400 -
2018-11-15 15:19:06,728 root:push_plate_no:397  > ERROR: Failed to connect to ftp server using given info host=127.0.0.1 , username=hadi , password=hadi123 ,folder=vehicle_plate , 530-User cannot log in.
 Win32 error:   The user name or password is incorrect. 
 Error details: An error occurred during the authentication process.
530 End
2018-11-15 15:19:06,728 root:push_plate_no:402  > INFO: 
2018-11-15 15:19:06,728 root:push_plate_no:403  > INFO: --- v1_push plate no ---
2018-11-15 15:19:06,728 root:push_plate_no:404  > INFO: Plateno=PUTRAJAYA123<<>>Camera_sn=00000000-00000000<<>>Maxpark_camera_id=1000
2018-11-15 15:19:06,728 root:push_plate_no:406  > INFO: Communicating with Comms Module
2018-11-15 15:19:06,728 LA_Commons:calculate_checksum:43   > INFO: Checksum (numerical= 0x6c
2018-11-15 15:19:06,740 flask.app:log_exception:1761 > ERROR: Exception on /localagent/v1/push_plate_no [POST]
Traceback (most recent call last):
  File "C:\Users\Abdul Hadi\PycharmProjects\LPRLA\venv\lib\site-packages\flask\app.py", line 2292, in wsgi_app
    response = self.full_dispatch_request()
  File "C:\Users\Abdul Hadi\PycharmProjects\LPRLA\venv\lib\site-packages\flask\app.py", line 1815, in full_dispatch_request
    rv = self.handle_user_exception(e)
  File "C:\Users\Abdul Hadi\PycharmProjects\LPRLA\venv\lib\site-packages\flask\app.py", line 1718, in handle_user_exception
    reraise(exc_type, exc_value, tb)
  File "C:\Users\Abdul Hadi\PycharmProjects\LPRLA\venv\lib\site-packages\flask\_compat.py", line 35, in reraise
    raise value
  File "C:\Users\Abdul Hadi\PycharmProjects\LPRLA\venv\lib\site-packages\flask\app.py", line 1813, in full_dispatch_request
    rv = self.dispatch_request()
  File "C:\Users\Abdul Hadi\PycharmProjects\LPRLA\venv\lib\site-packages\flask\app.py", line 1799, in dispatch_request
    return self.view_functions[rule.endpoint](**req.view_args)
  File "C:/Users/Abdul Hadi/PycharmProjects/LPRLA/lpr_localagent.py", line 412, in push_plate_no
    plate_no,maxpark_cam_id)
  File "C:\Users\Abdul Hadi\PycharmProjects\LPRLA\PUSH_plate_no.py", line 153, in push_plate_no
    print('chunk='+chunk)
TypeError: can only concatenate str (not "bytes") to str
2018-11-15 15:19:06,744 werkzeug:_log:88   > INFO: 127.0.0.1 - - [15/Nov/2018 15:19:06] "POST /localagent/v1/push_plate_no HTTP/1.1" 500 -
2018-11-15 15:20:52,265 root:main:195  > CRITICAL: 
 --- Application started & 'main' was called. This is not really Critical. --- 

2018-11-15 15:20:52,265 root:main:202  > INFO: PNS App Services IP Address White List:
2018-11-15 15:20:52,265 root:main:203  > INFO: ['35.162.219.50', '52.77.93.214', '13.228.1.86', '54.169.137.81', '127.0.0.1']
2018-11-15 15:20:53,327 werkzeug:_log:88   > INFO:  * Running on http://0.0.0.0:5001/ (Press CTRL+C to quit)
2018-11-15 15:20:56,289 root:push_plate_no:397  > ERROR: Failed to connect to ftp server using given info host=127.0.0.1 , username=hadi , password=hadi123 ,folder=vehicle_plate , 530-User cannot log in.
 Win32 error:   The user name or password is incorrect. 
 Error details: An error occurred during the authentication process.
530 End
2018-11-15 15:20:56,289 root:push_plate_no:402  > INFO: 
2018-11-15 15:20:56,289 root:push_plate_no:403  > INFO: --- v1_push plate no ---
2018-11-15 15:20:56,289 root:push_plate_no:404  > INFO: Plateno=PUTRAJAYA123<<>>Camera_sn=00000000-00000000<<>>Maxpark_camera_id=1000
2018-11-15 15:20:56,293 root:push_plate_no:406  > INFO: Communicating with Comms Module
2018-11-15 15:20:56,293 LA_Commons:calculate_checksum:43   > INFO: Checksum (numerical= 0x6c
2018-11-15 15:21:01,297 flask.app:log_exception:1761 > ERROR: Exception on /localagent/v1/push_plate_no [POST]
Traceback (most recent call last):
  File "C:\Users\Abdul Hadi\PycharmProjects\LPRLA\venv\lib\site-packages\flask\app.py", line 2292, in wsgi_app
    response = self.full_dispatch_request()
  File "C:\Users\Abdul Hadi\PycharmProjects\LPRLA\venv\lib\site-packages\flask\app.py", line 1815, in full_dispatch_request
    rv = self.handle_user_exception(e)
  File "C:\Users\Abdul Hadi\PycharmProjects\LPRLA\venv\lib\site-packages\flask\app.py", line 1718, in handle_user_exception
    reraise(exc_type, exc_value, tb)
  File "C:\Users\Abdul Hadi\PycharmProjects\LPRLA\venv\lib\site-packages\flask\_compat.py", line 35, in reraise
    raise value
  File "C:\Users\Abdul Hadi\PycharmProjects\LPRLA\venv\lib\site-packages\flask\app.py", line 1813, in full_dispatch_request
    rv = self.dispatch_request()
  File "C:\Users\Abdul Hadi\PycharmProjects\LPRLA\venv\lib\site-packages\flask\app.py", line 1799, in dispatch_request
    return self.view_functions[rule.endpoint](**req.view_args)
  File "C:/Users/Abdul Hadi/PycharmProjects/LPRLA/lpr_localagent.py", line 412, in push_plate_no
    plate_no,maxpark_cam_id)
  File "C:\Users\Abdul Hadi\PycharmProjects\LPRLA\PUSH_plate_no.py", line 152, in push_plate_no
    chunk = s.recv(4096)
socket.timeout: timed out
2018-11-15 15:21:01,297 werkzeug:_log:88   > INFO: 127.0.0.1 - - [15/Nov/2018 15:21:01] "POST /localagent/v1/push_plate_no HTTP/1.1" 500 -
2018-11-15 15:21:09,916 root:push_plate_no:397  > ERROR: Failed to connect to ftp server using given info host=127.0.0.1 , username=hadi , password=hadi123 ,folder=vehicle_plate , 530-User cannot log in.
 Win32 error:   The user name or password is incorrect. 
 Error details: An error occurred during the authentication process.
530 End
2018-11-15 15:21:09,916 root:push_plate_no:402  > INFO: 
2018-11-15 15:21:09,916 root:push_plate_no:403  > INFO: --- v1_push plate no ---
2018-11-15 15:21:09,916 root:push_plate_no:404  > INFO: Plateno=PUTRAJAYA123<<>>Camera_sn=00000000-00000000<<>>Maxpark_camera_id=1000
2018-11-15 15:21:09,916 root:push_plate_no:406  > INFO: Communicating with Comms Module
2018-11-15 15:21:09,916 LA_Commons:calculate_checksum:43   > INFO: Checksum (numerical= 0x6c
2018-11-15 15:21:10,926 PUSH_plate_no:push_plate_no:128  > WARNING: Connection error: [WinError 10061] No connection could be made because the target machine actively refused it
2018-11-15 15:21:15,938 PUSH_plate_no:push_plate_no:149  > ERROR: failed to sent packet to comm module
2018-11-15 15:21:15,938 root:push_plate_no:413  > INFO: response : false
2018-11-15 15:21:15,938 werkzeug:_log:88   > INFO: 127.0.0.1 - - [15/Nov/2018 15:21:15] "POST /localagent/v1/push_plate_no HTTP/1.1" 400 -
2018-11-15 15:21:35,859 root:main:195  > CRITICAL: 
 --- Application started & 'main' was called. This is not really Critical. --- 

2018-11-15 15:21:35,859 root:main:202  > INFO: PNS App Services IP Address White List:
2018-11-15 15:21:35,859 root:main:203  > INFO: ['35.162.219.50', '52.77.93.214', '13.228.1.86', '54.169.137.81', '127.0.0.1']
2018-11-15 15:21:36,922 werkzeug:_log:88   > INFO:  * Running on http://0.0.0.0:5001/ (Press CTRL+C to quit)
2018-11-15 15:21:39,867 root:push_plate_no:397  > ERROR: Failed to connect to ftp server using given info host=127.0.0.1 , username=hadi , password=hadi123 ,folder=vehicle_plate , 530-User cannot log in.
 Win32 error:   The user name or password is incorrect. 
 Error details: An error occurred during the authentication process.
530 End
2018-11-15 15:21:39,867 root:push_plate_no:402  > INFO: 
2018-11-15 15:21:39,867 root:push_plate_no:403  > INFO: --- v1_push plate no ---
2018-11-15 15:21:39,871 root:push_plate_no:404  > INFO: Plateno=PUTRAJAYA123<<>>Camera_sn=00000000-00000000<<>>Maxpark_camera_id=1000
2018-11-15 15:21:39,871 root:push_plate_no:406  > INFO: Communicating with Comms Module
2018-11-15 15:21:39,871 LA_Commons:calculate_checksum:43   > INFO: Checksum (numerical= 0x6c
2018-11-15 15:21:44,876 flask.app:log_exception:1761 > ERROR: Exception on /localagent/v1/push_plate_no [POST]
Traceback (most recent call last):
  File "C:\Users\Abdul Hadi\PycharmProjects\LPRLA\venv\lib\site-packages\flask\app.py", line 2292, in wsgi_app
    response = self.full_dispatch_request()
  File "C:\Users\Abdul Hadi\PycharmProjects\LPRLA\venv\lib\site-packages\flask\app.py", line 1815, in full_dispatch_request
    rv = self.handle_user_exception(e)
  File "C:\Users\Abdul Hadi\PycharmProjects\LPRLA\venv\lib\site-packages\flask\app.py", line 1718, in handle_user_exception
    reraise(exc_type, exc_value, tb)
  File "C:\Users\Abdul Hadi\PycharmProjects\LPRLA\venv\lib\site-packages\flask\_compat.py", line 35, in reraise
    raise value
  File "C:\Users\Abdul Hadi\PycharmProjects\LPRLA\venv\lib\site-packages\flask\app.py", line 1813, in full_dispatch_request
    rv = self.dispatch_request()
  File "C:\Users\Abdul Hadi\PycharmProjects\LPRLA\venv\lib\site-packages\flask\app.py", line 1799, in dispatch_request
    return self.view_functions[rule.endpoint](**req.view_args)
  File "C:/Users/Abdul Hadi/PycharmProjects/LPRLA/lpr_localagent.py", line 412, in push_plate_no
    plate_no,maxpark_cam_id)
  File "C:\Users\Abdul Hadi\PycharmProjects\LPRLA\PUSH_plate_no.py", line 152, in push_plate_no
    chunk = s.recv(4096)
socket.timeout: timed out
2018-11-15 15:21:44,876 werkzeug:_log:88   > INFO: 127.0.0.1 - - [15/Nov/2018 15:21:44] "POST /localagent/v1/push_plate_no HTTP/1.1" 500 -
2018-11-15 15:27:28,915 root:push_plate_no:397  > ERROR: Failed to connect to ftp server using given info host=127.0.0.1 , username=hadi , password=hadi123 ,folder=vehicle_plate , 530-User cannot log in.
 Win32 error:   The user name or password is incorrect. 
 Error details: An error occurred during the authentication process.
530 End
2018-11-15 15:27:28,915 root:push_plate_no:402  > INFO: 
2018-11-15 15:27:28,915 root:push_plate_no:403  > INFO: --- v1_push plate no ---
2018-11-15 15:27:28,915 root:push_plate_no:404  > INFO: Plateno=PUTRAJAYA123<<>>Camera_sn=00000000-00000000<<>>Maxpark_camera_id=1000
2018-11-15 15:27:28,915 root:push_plate_no:406  > INFO: Communicating with Comms Module
2018-11-15 15:27:28,915 LA_Commons:calculate_checksum:43   > INFO: Checksum (numerical= 0x6c
2018-11-15 15:27:33,918 flask.app:log_exception:1761 > ERROR: Exception on /localagent/v1/push_plate_no [POST]
Traceback (most recent call last):
  File "C:\Users\Abdul Hadi\PycharmProjects\LPRLA\venv\lib\site-packages\flask\app.py", line 2292, in wsgi_app
    response = self.full_dispatch_request()
  File "C:\Users\Abdul Hadi\PycharmProjects\LPRLA\venv\lib\site-packages\flask\app.py", line 1815, in full_dispatch_request
    rv = self.handle_user_exception(e)
  File "C:\Users\Abdul Hadi\PycharmProjects\LPRLA\venv\lib\site-packages\flask\app.py", line 1718, in handle_user_exception
    reraise(exc_type, exc_value, tb)
  File "C:\Users\Abdul Hadi\PycharmProjects\LPRLA\venv\lib\site-packages\flask\_compat.py", line 35, in reraise
    raise value
  File "C:\Users\Abdul Hadi\PycharmProjects\LPRLA\venv\lib\site-packages\flask\app.py", line 1813, in full_dispatch_request
    rv = self.dispatch_request()
  File "C:\Users\Abdul Hadi\PycharmProjects\LPRLA\venv\lib\site-packages\flask\app.py", line 1799, in dispatch_request
    return self.view_functions[rule.endpoint](**req.view_args)
  File "C:/Users/Abdul Hadi/PycharmProjects/LPRLA/lpr_localagent.py", line 412, in push_plate_no
    plate_no,maxpark_cam_id)
  File "C:\Users\Abdul Hadi\PycharmProjects\LPRLA\PUSH_plate_no.py", line 152, in push_plate_no
    chunk = s.recv(4096)
socket.timeout: timed out
2018-11-15 15:27:33,918 werkzeug:_log:88   > INFO: 127.0.0.1 - - [15/Nov/2018 15:27:33] "POST /localagent/v1/push_plate_no HTTP/1.1" 500 -
2018-11-15 15:27:49,856 root:main:195  > CRITICAL: 
 --- Application started & 'main' was called. This is not really Critical. --- 

2018-11-15 15:27:49,860 root:main:202  > INFO: PNS App Services IP Address White List:
2018-11-15 15:27:49,860 root:main:203  > INFO: ['35.162.219.50', '52.77.93.214', '13.228.1.86', '54.169.137.81', '127.0.0.1']
2018-11-15 15:27:50,900 werkzeug:_log:88   > INFO:  * Running on http://0.0.0.0:5001/ (Press CTRL+C to quit)
2018-11-15 15:27:53,737 root:push_plate_no:397  > ERROR: Failed to connect to ftp server using given info host=127.0.0.1 , username=hadi , password=hadi123 ,folder=vehicle_plate , 530-User cannot log in.
 Win32 error:   The user name or password is incorrect. 
 Error details: An error occurred during the authentication process.
530 End
2018-11-15 15:27:53,737 root:push_plate_no:402  > INFO: 
2018-11-15 15:27:53,737 root:push_plate_no:403  > INFO: --- v1_push plate no ---
2018-11-15 15:27:53,737 root:push_plate_no:404  > INFO: Plateno=PUTRAJAYA123<<>>Camera_sn=00000000-00000000<<>>Maxpark_camera_id=1000
2018-11-15 15:27:53,737 root:push_plate_no:406  > INFO: Communicating with Comms Module
2018-11-15 15:27:53,737 LA_Commons:calculate_checksum:43   > INFO: Checksum (numerical= 0x49
2018-11-15 15:27:54,745 PUSH_plate_no:push_plate_no:128  > WARNING: Connection error: [WinError 10061] No connection could be made because the target machine actively refused it
2018-11-15 15:27:59,745 PUSH_plate_no:push_plate_no:149  > ERROR: failed to sent packet to comm module
2018-11-15 15:27:59,745 root:push_plate_no:413  > INFO: response : false
2018-11-15 15:27:59,745 werkzeug:_log:88   > INFO: 127.0.0.1 - - [15/Nov/2018 15:27:59] "POST /localagent/v1/push_plate_no HTTP/1.1" 400 -
2018-11-15 15:28:10,593 root:main:195  > CRITICAL: 
 --- Application started & 'main' was called. This is not really Critical. --- 

2018-11-15 15:28:10,597 root:main:202  > INFO: PNS App Services IP Address White List:
2018-11-15 15:28:10,597 root:main:203  > INFO: ['35.162.219.50', '52.77.93.214', '13.228.1.86', '54.169.137.81', '127.0.0.1']
2018-11-15 15:28:11,621 werkzeug:_log:88   > INFO:  * Running on http://0.0.0.0:5001/ (Press CTRL+C to quit)
2018-11-15 15:28:19,486 root:push_plate_no:397  > ERROR: Failed to connect to ftp server using given info host=127.0.0.1 , username=hadi , password=hadi123 ,folder=vehicle_plate , 530-User cannot log in.
 Win32 error:   The user name or password is incorrect. 
 Error details: An error occurred during the authentication process.
530 End
2018-11-15 15:28:19,486 root:push_plate_no:402  > INFO: 
2018-11-15 15:28:19,486 root:push_plate_no:403  > INFO: --- v1_push plate no ---
2018-11-15 15:28:19,486 root:push_plate_no:404  > INFO: Plateno=PUTRAJAYA123<<>>Camera_sn=00000000-00000000<<>>Maxpark_camera_id=1000
2018-11-15 15:28:19,486 root:push_plate_no:406  > INFO: Communicating with Comms Module
2018-11-15 15:28:19,486 LA_Commons:calculate_checksum:43   > INFO: Checksum (numerical= 0x49
2018-11-15 15:28:24,502 flask.app:log_exception:1761 > ERROR: Exception on /localagent/v1/push_plate_no [POST]
Traceback (most recent call last):
  File "C:\Users\Abdul Hadi\PycharmProjects\LPRLA\venv\lib\site-packages\flask\app.py", line 2292, in wsgi_app
    response = self.full_dispatch_request()
  File "C:\Users\Abdul Hadi\PycharmProjects\LPRLA\venv\lib\site-packages\flask\app.py", line 1815, in full_dispatch_request
    rv = self.handle_user_exception(e)
  File "C:\Users\Abdul Hadi\PycharmProjects\LPRLA\venv\lib\site-packages\flask\app.py", line 1718, in handle_user_exception
    reraise(exc_type, exc_value, tb)
  File "C:\Users\Abdul Hadi\PycharmProjects\LPRLA\venv\lib\site-packages\flask\_compat.py", line 35, in reraise
    raise value
  File "C:\Users\Abdul Hadi\PycharmProjects\LPRLA\venv\lib\site-packages\flask\app.py", line 1813, in full_dispatch_request
    rv = self.dispatch_request()
  File "C:\Users\Abdul Hadi\PycharmProjects\LPRLA\venv\lib\site-packages\flask\app.py", line 1799, in dispatch_request
    return self.view_functions[rule.endpoint](**req.view_args)
  File "C:/Users/Abdul Hadi/PycharmProjects/LPRLA/lpr_localagent.py", line 412, in push_plate_no
    plate_no,maxpark_cam_id)
  File "C:\Users\Abdul Hadi\PycharmProjects\LPRLA\PUSH_plate_no.py", line 152, in push_plate_no
    chunk = s.recv(4096)
socket.timeout: timed out
2018-11-15 15:28:24,506 werkzeug:_log:88   > INFO: 127.0.0.1 - - [15/Nov/2018 15:28:24] "POST /localagent/v1/push_plate_no HTTP/1.1" 500 -
2018-11-15 15:29:52,405 root:main:195  > CRITICAL: 
 --- Application started & 'main' was called. This is not really Critical. --- 

2018-11-15 15:29:52,405 root:main:202  > INFO: PNS App Services IP Address White List:
2018-11-15 15:29:52,405 root:main:203  > INFO: ['35.162.219.50', '52.77.93.214', '13.228.1.86', '54.169.137.81', '127.0.0.1']
2018-11-15 15:29:53,453 werkzeug:_log:88   > INFO:  * Running on http://0.0.0.0:5001/ (Press CTRL+C to quit)
2018-11-15 16:44:58,484 root:push_plate_no:397  > ERROR: Failed to connect to ftp server using given info host=127.0.0.1 , username=hadi , password=hadi123 ,folder=vehicle_plate , 530-User cannot log in.
 Win32 error:   The user name or password is incorrect. 
 Error details: An error occurred during the authentication process.
530 End
2018-11-15 16:44:58,485 root:push_plate_no:402  > INFO: 
2018-11-15 16:44:58,485 root:push_plate_no:403  > INFO: --- v1_push plate no ---
2018-11-15 16:44:58,485 root:push_plate_no:404  > INFO: Plateno=PUTRAJAYA1231234<<>>Camera_sn=00000000-00000000<<>>Maxpark_camera_id=1000
2018-11-15 16:44:58,485 root:push_plate_no:406  > INFO: Communicating with Comms Module
2018-11-15 16:44:58,486 LA_Commons:calculate_checksum:43   > INFO: Checksum (numerical= 0x4d
2018-11-15 16:45:03,490 flask.app:log_exception:1761 > ERROR: Exception on /localagent/v1/push_plate_no [POST]
Traceback (most recent call last):
  File "C:\Users\Abdul Hadi\PycharmProjects\LPRLA\venv\lib\site-packages\flask\app.py", line 2292, in wsgi_app
    response = self.full_dispatch_request()
  File "C:\Users\Abdul Hadi\PycharmProjects\LPRLA\venv\lib\site-packages\flask\app.py", line 1815, in full_dispatch_request
    rv = self.handle_user_exception(e)
  File "C:\Users\Abdul Hadi\PycharmProjects\LPRLA\venv\lib\site-packages\flask\app.py", line 1718, in handle_user_exception
    reraise(exc_type, exc_value, tb)
  File "C:\Users\Abdul Hadi\PycharmProjects\LPRLA\venv\lib\site-packages\flask\_compat.py", line 35, in reraise
    raise value
  File "C:\Users\Abdul Hadi\PycharmProjects\LPRLA\venv\lib\site-packages\flask\app.py", line 1813, in full_dispatch_request
    rv = self.dispatch_request()
  File "C:\Users\Abdul Hadi\PycharmProjects\LPRLA\venv\lib\site-packages\flask\app.py", line 1799, in dispatch_request
    return self.view_functions[rule.endpoint](**req.view_args)
  File "C:/Users/Abdul Hadi/PycharmProjects/LPRLA/lpr_localagent.py", line 412, in push_plate_no
    plate_no,maxpark_cam_id)
  File "C:\Users\Abdul Hadi\PycharmProjects\LPRLA\PUSH_plate_no.py", line 152, in push_plate_no
    chunk = s.recv(4096)
socket.timeout: timed out
2018-11-15 16:45:03,494 werkzeug:_log:88   > INFO: 127.0.0.1 - - [15/Nov/2018 16:45:03] "POST /localagent/v1/push_plate_no HTTP/1.1" 500 -
2018-11-15 16:45:39,428 root:main:195  > CRITICAL: 
 --- Application started & 'main' was called. This is not really Critical. --- 

2018-11-15 16:45:39,428 root:main:202  > INFO: PNS App Services IP Address White List:
2018-11-15 16:45:39,428 root:main:203  > INFO: ['35.162.219.50', '52.77.93.214', '13.228.1.86', '54.169.137.81', '127.0.0.1']
2018-11-15 16:45:40,475 werkzeug:_log:88   > INFO:  * Running on http://0.0.0.0:5001/ (Press CTRL+C to quit)
2018-11-15 16:45:43,399 root:push_plate_no:397  > ERROR: Failed to connect to ftp server using given info host=127.0.0.1 , username=hadi , password=hadi123 ,folder=vehicle_plate , 530-User cannot log in.
 Win32 error:   The user name or password is incorrect. 
 Error details: An error occurred during the authentication process.
530 End
2018-11-15 16:45:43,399 root:push_plate_no:402  > INFO: 
2018-11-15 16:45:43,399 root:push_plate_no:403  > INFO: --- v1_push plate no ---
2018-11-15 16:45:43,399 root:push_plate_no:404  > INFO: Plateno=PUTRAJAYA1231234<<>>Camera_sn=00000000-00000000<<>>Maxpark_camera_id=1000
2018-11-15 16:45:43,400 root:push_plate_no:406  > INFO: Communicating with Comms Module
2018-11-15 16:45:43,400 LA_Commons:calculate_checksum:43   > INFO: Checksum (numerical= 0x2d
2018-11-15 16:45:44,403 PUSH_plate_no:push_plate_no:128  > WARNING: Connection error: [WinError 10061] No connection could be made because the target machine actively refused it
2018-11-15 16:45:49,404 PUSH_plate_no:push_plate_no:149  > ERROR: failed to sent packet to comm module
2018-11-15 16:45:49,404 root:push_plate_no:413  > INFO: response : false
2018-11-15 16:45:49,405 werkzeug:_log:88   > INFO: 127.0.0.1 - - [15/Nov/2018 16:45:49] "POST /localagent/v1/push_plate_no HTTP/1.1" 400 -
2018-11-15 16:46:28,456 root:push_plate_no:397  > ERROR: Failed to connect to ftp server using given info host=127.0.0.1 , username=hadi , password=hadi123 ,folder=vehicle_plate , 530-User cannot log in.
 Win32 error:   The user name or password is incorrect. 
 Error details: An error occurred during the authentication process.
530 End
2018-11-15 16:46:28,456 root:push_plate_no:402  > INFO: 
2018-11-15 16:46:28,456 root:push_plate_no:403  > INFO: --- v1_push plate no ---
2018-11-15 16:46:28,456 root:push_plate_no:404  > INFO: Plateno=PUTRAJAYA1231234<<>>Camera_sn=00000000-00000000<<>>Maxpark_camera_id=1000
2018-11-15 16:46:28,456 root:push_plate_no:406  > INFO: Communicating with Comms Module
2018-11-15 16:46:28,456 LA_Commons:calculate_checksum:43   > INFO: Checksum (numerical= 0x2d
2018-11-15 16:46:33,468 PUSH_plate_no:push_plate_no:167  > WARNING: Timeout. Close connection
2018-11-15 16:46:33,468 root:push_plate_no:413  > INFO: response : None
2018-11-15 16:46:33,469 werkzeug:_log:88   > INFO: 127.0.0.1 - - [15/Nov/2018 16:46:33] "POST /localagent/v1/push_plate_no HTTP/1.1" 200 -
2018-11-15 16:46:59,127 root:main:195  > CRITICAL: 
 --- Application started & 'main' was called. This is not really Critical. --- 

2018-11-15 16:46:59,128 root:main:202  > INFO: PNS App Services IP Address White List:
2018-11-15 16:46:59,128 root:main:203  > INFO: ['35.162.219.50', '52.77.93.214', '13.228.1.86', '54.169.137.81', '127.0.0.1']
2018-11-15 16:47:00,159 werkzeug:_log:88   > INFO:  * Running on http://0.0.0.0:5001/ (Press CTRL+C to quit)
2018-11-15 16:47:02,820 root:push_plate_no:397  > ERROR: Failed to connect to ftp server using given info host=127.0.0.1 , username=hadi , password=hadi123 ,folder=vehicle_plate , 530-User cannot log in.
 Win32 error:   The user name or password is incorrect. 
 Error details: An error occurred during the authentication process.
530 End
2018-11-15 16:47:02,821 root:push_plate_no:402  > INFO: 
2018-11-15 16:47:02,821 root:push_plate_no:403  > INFO: --- v1_push plate no ---
2018-11-15 16:47:02,821 root:push_plate_no:404  > INFO: Plateno=PUTRAJAYA1231234<<>>Camera_sn=00000000-00000000<<>>Maxpark_camera_id=1000
2018-11-15 16:47:02,821 root:push_plate_no:406  > INFO: Communicating with Comms Module
2018-11-15 16:47:02,821 LA_Commons:calculate_checksum:43   > INFO: Checksum (numerical= 0x2b
2018-11-15 16:47:07,822 PUSH_plate_no:push_plate_no:167  > WARNING: Timeout. Close connection
2018-11-15 16:47:07,822 root:push_plate_no:413  > INFO: response : None
2018-11-15 16:47:07,823 werkzeug:_log:88   > INFO: 127.0.0.1 - - [15/Nov/2018 16:47:07] "POST /localagent/v1/push_plate_no HTTP/1.1" 200 -
2018-11-15 16:48:49,289 root:main:195  > CRITICAL: 
 --- Application started & 'main' was called. This is not really Critical. --- 

2018-11-15 16:48:49,290 root:main:202  > INFO: PNS App Services IP Address White List:
2018-11-15 16:48:49,290 root:main:203  > INFO: ['35.162.219.50', '52.77.93.214', '13.228.1.86', '54.169.137.81', '127.0.0.1']
2018-11-15 16:48:50,346 werkzeug:_log:88   > INFO:  * Running on http://0.0.0.0:5001/ (Press CTRL+C to quit)
2018-11-15 16:48:54,051 root:push_plate_no:397  > ERROR: Failed to connect to ftp server using given info host=127.0.0.1 , username=hadi , password=hadi123 ,folder=vehicle_plate , 530-User cannot log in.
 Win32 error:   The user name or password is incorrect. 
 Error details: An error occurred during the authentication process.
530 End
2018-11-15 16:48:54,051 root:push_plate_no:402  > INFO: 
2018-11-15 16:48:54,051 root:push_plate_no:403  > INFO: --- v1_push plate no ---
2018-11-15 16:48:54,052 root:push_plate_no:404  > INFO: Plateno=PUTRAJAYA1231234<<>>Camera_sn=00000000-00000000<<>>Maxpark_camera_id=1000
2018-11-15 16:48:54,052 root:push_plate_no:406  > INFO: Communicating with Comms Module
2018-11-15 16:48:54,052 LA_Commons:calculate_checksum:43   > INFO: Checksum (numerical= 0x6e
2018-11-15 16:48:59,054 PUSH_plate_no:push_plate_no:167  > WARNING: Timeout. Close connection
2018-11-15 16:48:59,054 root:push_plate_no:413  > INFO: response : None
2018-11-15 16:48:59,055 werkzeug:_log:88   > INFO: 127.0.0.1 - - [15/Nov/2018 16:48:59] "POST /localagent/v1/push_plate_no HTTP/1.1" 200 -
2018-11-15 17:12:06,323 root:main:195  > CRITICAL: 
 --- Application started & 'main' was called. This is not really Critical. --- 

2018-11-15 17:12:06,323 root:main:202  > INFO: PNS App Services IP Address White List:
2018-11-15 17:12:06,323 root:main:203  > INFO: ['35.162.219.50', '52.77.93.214', '13.228.1.86', '54.169.137.81', '127.0.0.1']
2018-11-15 17:12:06,588 werkzeug:_log:88   > INFO:  * Running on http://0.0.0.0:5001/ (Press CTRL+C to quit)
2018-11-15 17:12:26,439 root:push_plate_no:397  > ERROR: Failed to connect to ftp server using given info host=127.0.0.1 , username=hadi , password=hadi123 ,folder=vehicle_plate , 530-User cannot log in.
 Win32 error:   The user name or password is incorrect. 
 Error details: An error occurred during the authentication process.
530 End
2018-11-15 17:12:26,440 root:push_plate_no:402  > INFO: 
2018-11-15 17:12:26,440 root:push_plate_no:403  > INFO: --- v1_push plate no ---
2018-11-15 17:12:26,440 root:push_plate_no:404  > INFO: Plateno=PUTRAJAYA1231234<<>>Camera_sn=00000000-00000000<<>>Maxpark_camera_id=1000
2018-11-15 17:12:26,440 root:push_plate_no:406  > INFO: Communicating with Comms Module
2018-11-15 17:12:26,440 LA_Commons:calculate_checksum:43   > INFO: Checksum (numerical= 0x21
2018-11-15 17:12:26,446 root:push_plate_no:413  > INFO: response : None
2018-11-15 17:12:26,447 werkzeug:_log:88   > INFO: 127.0.0.1 - - [15/Nov/2018 17:12:26] "POST /localagent/v1/push_plate_no HTTP/1.1" 200 -
2018-11-15 17:13:57,122 root:main:195  > CRITICAL: 
 --- Application started & 'main' was called. This is not really Critical. --- 

2018-11-15 17:13:57,122 root:main:202  > INFO: PNS App Services IP Address White List:
2018-11-15 17:13:57,122 root:main:203  > INFO: ['35.162.219.50', '52.77.93.214', '13.228.1.86', '54.169.137.81', '127.0.0.1']
2018-11-15 17:13:57,390 werkzeug:_log:88   > INFO:  * Running on http://0.0.0.0:5001/ (Press CTRL+C to quit)
2018-11-15 17:14:00,118 root:push_plate_no:397  > ERROR: Failed to connect to ftp server using given info host=127.0.0.1 , username=hadi , password=hadi123 ,folder=vehicle_plate , 530-User cannot log in.
 Win32 error:   The user name or password is incorrect. 
 Error details: An error occurred during the authentication process.
530 End
2018-11-15 17:14:00,118 root:push_plate_no:402  > INFO: 
2018-11-15 17:14:00,118 root:push_plate_no:403  > INFO: --- v1_push plate no ---
2018-11-15 17:14:00,119 root:push_plate_no:404  > INFO: Plateno=PUTRAJAYA1231234<<>>Camera_sn=00000000-00000000<<>>Maxpark_camera_id=G1000
2018-11-15 17:14:00,119 root:push_plate_no:406  > INFO: Communicating with Comms Module
2018-11-15 17:14:00,119 LA_Commons:calculate_checksum:43   > INFO: Checksum (numerical= 0x6d
2018-11-15 17:14:00,123 root:push_plate_no:413  > INFO: response : None
2018-11-15 17:14:00,124 werkzeug:_log:88   > INFO: 127.0.0.1 - - [15/Nov/2018 17:14:00] "POST /localagent/v1/push_plate_no HTTP/1.1" 200 -
2018-11-15 17:14:36,651 root:main:195  > CRITICAL: 
 --- Application started & 'main' was called. This is not really Critical. --- 

2018-11-15 17:14:36,652 root:main:202  > INFO: PNS App Services IP Address White List:
2018-11-15 17:14:36,652 root:main:203  > INFO: ['35.162.219.50', '52.77.93.214', '13.228.1.86', '54.169.137.81', '127.0.0.1']
2018-11-15 17:14:36,871 werkzeug:_log:88   > INFO:  * Running on http://0.0.0.0:5001/ (Press CTRL+C to quit)
2018-11-15 17:14:48,352 root:push_plate_no:397  > ERROR: Failed to connect to ftp server using given info host=127.0.0.1 , username=hadi , password=hadi123 ,folder=vehicle_plate , 530-User cannot log in.
 Win32 error:   The user name or password is incorrect. 
 Error details: An error occurred during the authentication process.
530 End
2018-11-15 17:14:48,352 root:push_plate_no:402  > INFO: 
2018-11-15 17:14:48,352 root:push_plate_no:403  > INFO: --- v1_push plate no ---
2018-11-15 17:14:48,353 root:push_plate_no:404  > INFO: Plateno=PUTRAJAYA1231234<<>>Camera_sn=00000000-00000000<<>>Maxpark_camera_id=D1000
2018-11-15 17:14:48,353 root:push_plate_no:406  > INFO: Communicating with Comms Module
2018-11-15 17:14:48,353 LA_Commons:calculate_checksum:43   > INFO: Checksum (numerical= 0x6e
2018-11-15 17:14:53,355 PUSH_plate_no:push_plate_no:167  > WARNING: Timeout. Close connection
2018-11-15 17:14:53,355 root:push_plate_no:413  > INFO: response : None
2018-11-15 17:14:53,356 werkzeug:_log:88   > INFO: 127.0.0.1 - - [15/Nov/2018 17:14:53] "POST /localagent/v1/push_plate_no HTTP/1.1" 200 -
2018-11-15 17:15:26,935 root:main:195  > CRITICAL: 
 --- Application started & 'main' was called. This is not really Critical. --- 

2018-11-15 17:15:26,936 root:main:202  > INFO: PNS App Services IP Address White List:
2018-11-15 17:15:26,936 root:main:203  > INFO: ['35.162.219.50', '52.77.93.214', '13.228.1.86', '54.169.137.81', '127.0.0.1']
2018-11-15 17:15:27,294 werkzeug:_log:88   > INFO:  * Running on http://0.0.0.0:5001/ (Press CTRL+C to quit)
2018-11-15 17:15:30,075 root:push_plate_no:397  > ERROR: Failed to connect to ftp server using given info host=127.0.0.1 , username=hadi , password=hadi123 ,folder=vehicle_plate , 530-User cannot log in.
 Win32 error:   The user name or password is incorrect. 
 Error details: An error occurred during the authentication process.
530 End
2018-11-15 17:15:30,076 root:push_plate_no:402  > INFO: 
2018-11-15 17:15:30,076 root:push_plate_no:403  > INFO: --- v1_push plate no ---
2018-11-15 17:15:30,076 root:push_plate_no:404  > INFO: Plateno=PUTRAJAYA1231234<<>>Camera_sn=00000000-00000000<<>>Maxpark_camera_id=1000
2018-11-15 17:15:30,076 root:push_plate_no:406  > INFO: Communicating with Comms Module
2018-11-15 17:15:30,076 LA_Commons:calculate_checksum:43   > INFO: Checksum (numerical= 0x2a
2018-11-15 17:15:30,082 root:push_plate_no:413  > INFO: response : None
2018-11-15 17:15:30,082 werkzeug:_log:88   > INFO: 127.0.0.1 - - [15/Nov/2018 17:15:30] "POST /localagent/v1/push_plate_no HTTP/1.1" 200 -
2018-11-15 17:22:08,798 root:main:195  > CRITICAL: 
 --- Application started & 'main' was called. This is not really Critical. --- 

2018-11-15 17:22:08,798 root:main:202  > INFO: PNS App Services IP Address White List:
2018-11-15 17:22:08,798 root:main:203  > INFO: ['35.162.219.50', '52.77.93.214', '13.228.1.86', '54.169.137.81', '127.0.0.1']
2018-11-15 17:22:09,060 werkzeug:_log:88   > INFO:  * Running on http://0.0.0.0:5001/ (Press CTRL+C to quit)
2018-11-15 17:22:12,981 root:push_plate_no:397  > ERROR: Failed to connect to ftp server using given info host=127.0.0.1 , username=hadi , password=hadi123 ,folder=vehicle_plate , 530-User cannot log in.
 Win32 error:   The user name or password is incorrect. 
 Error details: An error occurred during the authentication process.
530 End
2018-11-15 17:22:12,981 root:push_plate_no:402  > INFO: 
2018-11-15 17:22:12,981 root:push_plate_no:403  > INFO: --- v1_push plate no ---
2018-11-15 17:22:12,981 root:push_plate_no:404  > INFO: Plateno=PUTRAJAYA1231234<<>>Camera_sn=00000000-00000000<<>>Maxpark_camera_id=1000
2018-11-15 17:22:12,982 root:push_plate_no:406  > INFO: Communicating with Comms Module
2018-11-15 17:22:12,982 LA_Commons:calculate_checksum_2chrcmd:71   > INFO: Checksum (numerical= 0x6e
2018-11-15 17:22:17,984 PUSH_plate_no:push_plate_no:167  > WARNING: Timeout. Close connection
2018-11-15 17:22:17,984 root:push_plate_no:413  > INFO: response : None
2018-11-15 17:22:17,985 werkzeug:_log:88   > INFO: 127.0.0.1 - - [15/Nov/2018 17:22:17] "POST /localagent/v1/push_plate_no HTTP/1.1" 200 -
2018-11-15 17:23:13,137 root:main:195  > CRITICAL: 
 --- Application started & 'main' was called. This is not really Critical. --- 

2018-11-15 17:23:13,138 root:main:202  > INFO: PNS App Services IP Address White List:
2018-11-15 17:23:13,138 root:main:203  > INFO: ['35.162.219.50', '52.77.93.214', '13.228.1.86', '54.169.137.81', '127.0.0.1']
2018-11-15 17:23:13,376 werkzeug:_log:88   > INFO:  * Running on http://0.0.0.0:5001/ (Press CTRL+C to quit)
2018-11-15 17:23:16,796 root:push_plate_no:397  > ERROR: Failed to connect to ftp server using given info host=127.0.0.1 , username=hadi , password=hadi123 ,folder=vehicle_plate , 530-User cannot log in.
 Win32 error:   The user name or password is incorrect. 
 Error details: An error occurred during the authentication process.
530 End
2018-11-15 17:23:16,796 root:push_plate_no:402  > INFO: 
2018-11-15 17:23:16,796 root:push_plate_no:403  > INFO: --- v1_push plate no ---
2018-11-15 17:23:16,798 root:push_plate_no:404  > INFO: Plateno=PUTRAJAYA1231234<<>>Camera_sn=00000000-00000000<<>>Maxpark_camera_id=1000
2018-11-15 17:23:16,798 root:push_plate_no:406  > INFO: Communicating with Comms Module
2018-11-15 17:23:16,798 LA_Commons:calculate_checksum_2chrcmd:73   > INFO: Checksum (numerical= 0x6e
2018-11-15 17:23:21,799 PUSH_plate_no:push_plate_no:167  > WARNING: Timeout. Close connection
2018-11-15 17:23:21,799 root:push_plate_no:413  > INFO: response : None
2018-11-15 17:23:21,799 werkzeug:_log:88   > INFO: 127.0.0.1 - - [15/Nov/2018 17:23:21] "POST /localagent/v1/push_plate_no HTTP/1.1" 200 -
2018-11-15 17:24:31,312 root:main:195  > CRITICAL: 
 --- Application started & 'main' was called. This is not really Critical. --- 

2018-11-15 17:24:31,312 root:main:202  > INFO: PNS App Services IP Address White List:
2018-11-15 17:24:31,313 root:main:203  > INFO: ['35.162.219.50', '52.77.93.214', '13.228.1.86', '54.169.137.81', '127.0.0.1']
2018-11-15 17:24:31,586 werkzeug:_log:88   > INFO:  * Running on http://0.0.0.0:5001/ (Press CTRL+C to quit)
2018-11-15 17:24:35,993 root:push_plate_no:397  > ERROR: Failed to connect to ftp server using given info host=127.0.0.1 , username=hadi , password=hadi123 ,folder=vehicle_plate , 530-User cannot log in.
 Win32 error:   The user name or password is incorrect. 
 Error details: An error occurred during the authentication process.
530 End
2018-11-15 17:24:35,993 root:push_plate_no:402  > INFO: 
2018-11-15 17:24:35,993 root:push_plate_no:403  > INFO: --- v1_push plate no ---
2018-11-15 17:24:35,993 root:push_plate_no:404  > INFO: Plateno=PUTRAJAYA1231234<<>>Camera_sn=00000000-00000000<<>>Maxpark_camera_id=1000
2018-11-15 17:24:35,993 root:push_plate_no:406  > INFO: Communicating with Comms Module
2018-11-15 17:24:35,993 LA_Commons:calculate_checksum_2chrcmd:73   > INFO: Checksum (numerical= 0x6e
2018-11-15 17:24:40,996 PUSH_plate_no:push_plate_no:167  > WARNING: Timeout. Close connection
2018-11-15 17:24:40,996 root:push_plate_no:413  > INFO: response : None
2018-11-15 17:24:40,997 werkzeug:_log:88   > INFO: 127.0.0.1 - - [15/Nov/2018 17:24:40] "POST /localagent/v1/push_plate_no HTTP/1.1" 200 -
2018-11-15 17:27:30,178 root:main:195  > CRITICAL: 
 --- Application started & 'main' was called. This is not really Critical. --- 

2018-11-15 17:27:30,178 root:main:202  > INFO: PNS App Services IP Address White List:
2018-11-15 17:27:30,178 root:main:203  > INFO: ['35.162.219.50', '52.77.93.214', '13.228.1.86', '54.169.137.81', '127.0.0.1']
2018-11-15 17:27:30,559 werkzeug:_log:88   > INFO:  * Running on http://0.0.0.0:5001/ (Press CTRL+C to quit)
2018-11-15 17:27:33,771 root:push_plate_no:397  > ERROR: Failed to connect to ftp server using given info host=127.0.0.1 , username=hadi , password=hadi123 ,folder=vehicle_plate , 530-User cannot log in.
 Win32 error:   The user name or password is incorrect. 
 Error details: An error occurred during the authentication process.
530 End
2018-11-15 17:27:33,771 root:push_plate_no:402  > INFO: 
2018-11-15 17:27:33,771 root:push_plate_no:403  > INFO: --- v1_push plate no ---
2018-11-15 17:27:33,771 root:push_plate_no:404  > INFO: Plateno=PUTRAJAYA1231234<<>>Camera_sn=00000000-00000000<<>>Maxpark_camera_id=1000
2018-11-15 17:27:33,772 root:push_plate_no:406  > INFO: Communicating with Comms Module
2018-11-15 17:27:33,772 flask.app:log_exception:1761 > ERROR: Exception on /localagent/v1/push_plate_no [POST]
Traceback (most recent call last):
  File "C:\Users\Abdul Hadi\PycharmProjects\LPRLA\venv\lib\site-packages\flask\app.py", line 2292, in wsgi_app
    response = self.full_dispatch_request()
  File "C:\Users\Abdul Hadi\PycharmProjects\LPRLA\venv\lib\site-packages\flask\app.py", line 1815, in full_dispatch_request
    rv = self.handle_user_exception(e)
  File "C:\Users\Abdul Hadi\PycharmProjects\LPRLA\venv\lib\site-packages\flask\app.py", line 1718, in handle_user_exception
    reraise(exc_type, exc_value, tb)
  File "C:\Users\Abdul Hadi\PycharmProjects\LPRLA\venv\lib\site-packages\flask\_compat.py", line 35, in reraise
    raise value
  File "C:\Users\Abdul Hadi\PycharmProjects\LPRLA\venv\lib\site-packages\flask\app.py", line 1813, in full_dispatch_request
    rv = self.dispatch_request()
  File "C:\Users\Abdul Hadi\PycharmProjects\LPRLA\venv\lib\site-packages\flask\app.py", line 1799, in dispatch_request
    return self.view_functions[rule.endpoint](**req.view_args)
  File "C:/Users/Abdul Hadi/PycharmProjects/LPRLA/lpr_localagent.py", line 412, in push_plate_no
    plate_no,maxpark_cam_id)
  File "C:\Users\Abdul Hadi\PycharmProjects\LPRLA\PUSH_plate_no.py", line 54, in push_plate_no
    num_CHECKSUM = LA_Commons.calculate_checksum_2chrcmd(CMD_L, DATA_list)
  File "C:\Users\Abdul Hadi\PycharmProjects\LPRLA\LA_Commons.py", line 64, in calculate_checksum_2chrcmd
    return_numerical_checksum = return_numerical_checksum ^ ord(command_byte[1])
IndexError: string index out of range
2018-11-15 17:27:33,775 werkzeug:_log:88   > INFO: 127.0.0.1 - - [15/Nov/2018 17:27:33] "POST /localagent/v1/push_plate_no HTTP/1.1" 500 -
2018-11-15 17:27:50,752 root:main:195  > CRITICAL: 
 --- Application started & 'main' was called. This is not really Critical. --- 

2018-11-15 17:27:50,752 root:main:202  > INFO: PNS App Services IP Address White List:
2018-11-15 17:27:50,752 root:main:203  > INFO: ['35.162.219.50', '52.77.93.214', '13.228.1.86', '54.169.137.81', '127.0.0.1']
2018-11-15 17:27:51,023 werkzeug:_log:88   > INFO:  * Running on http://0.0.0.0:5001/ (Press CTRL+C to quit)
2018-11-15 17:27:53,588 root:push_plate_no:397  > ERROR: Failed to connect to ftp server using given info host=127.0.0.1 , username=hadi , password=hadi123 ,folder=vehicle_plate , 530-User cannot log in.
 Win32 error:   The user name or password is incorrect. 
 Error details: An error occurred during the authentication process.
530 End
2018-11-15 17:27:53,589 root:push_plate_no:402  > INFO: 
2018-11-15 17:27:53,589 root:push_plate_no:403  > INFO: --- v1_push plate no ---
2018-11-15 17:27:53,589 root:push_plate_no:404  > INFO: Plateno=PUTRAJAYA1231234<<>>Camera_sn=00000000-00000000<<>>Maxpark_camera_id=1000
2018-11-15 17:27:53,589 root:push_plate_no:406  > INFO: Communicating with Comms Module
2018-11-15 17:27:53,589 LA_Commons:calculate_checksum_2chrcmd:73   > INFO: Checksum (numerical= 0x2a
2018-11-15 17:27:53,640 root:push_plate_no:413  > INFO: response : None
2018-11-15 17:27:53,641 werkzeug:_log:88   > INFO: 127.0.0.1 - - [15/Nov/2018 17:27:53] "POST /localagent/v1/push_plate_no HTTP/1.1" 200 -
2018-11-15 17:35:24,965 root:main:195  > CRITICAL: 
 --- Application started & 'main' was called. This is not really Critical. --- 

2018-11-15 17:35:24,965 root:main:202  > INFO: PNS App Services IP Address White List:
2018-11-15 17:35:24,965 root:main:203  > INFO: ['35.162.219.50', '52.77.93.214', '13.228.1.86', '54.169.137.81', '127.0.0.1']
2018-11-15 17:35:25,204 werkzeug:_log:88   > INFO:  * Running on http://0.0.0.0:5001/ (Press CTRL+C to quit)
2018-11-15 17:35:28,722 root:push_plate_no:397  > ERROR: Failed to connect to ftp server using given info host=127.0.0.1 , username=hadi , password=hadi123 ,folder=vehicle_plate , 530-User cannot log in.
 Win32 error:   The user name or password is incorrect. 
 Error details: An error occurred during the authentication process.
530 End
2018-11-15 17:35:28,722 root:push_plate_no:402  > INFO: 
2018-11-15 17:35:28,722 root:push_plate_no:403  > INFO: --- v1_push plate no ---
2018-11-15 17:35:28,722 root:push_plate_no:404  > INFO: Plateno=PUTRAJAYA1231234<<>>Camera_sn=00000000-00000000<<>>Maxpark_camera_id=1000
2018-11-15 17:35:28,722 root:push_plate_no:406  > INFO: Communicating with Comms Module
2018-11-15 17:35:28,723 flask.app:log_exception:1761 > ERROR: Exception on /localagent/v1/push_plate_no [POST]
Traceback (most recent call last):
  File "C:\Users\Abdul Hadi\PycharmProjects\LPRLA\venv\lib\site-packages\flask\app.py", line 2292, in wsgi_app
    response = self.full_dispatch_request()
  File "C:\Users\Abdul Hadi\PycharmProjects\LPRLA\venv\lib\site-packages\flask\app.py", line 1815, in full_dispatch_request
    rv = self.handle_user_exception(e)
  File "C:\Users\Abdul Hadi\PycharmProjects\LPRLA\venv\lib\site-packages\flask\app.py", line 1718, in handle_user_exception
    reraise(exc_type, exc_value, tb)
  File "C:\Users\Abdul Hadi\PycharmProjects\LPRLA\venv\lib\site-packages\flask\_compat.py", line 35, in reraise
    raise value
  File "C:\Users\Abdul Hadi\PycharmProjects\LPRLA\venv\lib\site-packages\flask\app.py", line 1813, in full_dispatch_request
    rv = self.dispatch_request()
  File "C:\Users\Abdul Hadi\PycharmProjects\LPRLA\venv\lib\site-packages\flask\app.py", line 1799, in dispatch_request
    return self.view_functions[rule.endpoint](**req.view_args)
  File "C:/Users/Abdul Hadi/PycharmProjects/LPRLA/lpr_localagent.py", line 412, in push_plate_no
    plate_no,maxpark_cam_id)
  File "C:\Users\Abdul Hadi\PycharmProjects\LPRLA\PUSH_plate_no.py", line 54, in push_plate_no
    num_CHECKSUM = LA_Commons.calculate_checksum_2chrcmd(CMD_L, DATA_list)
  File "C:\Users\Abdul Hadi\PycharmProjects\LPRLA\LA_Commons.py", line 65, in calculate_checksum_2chrcmd
    s=command_byte+list_of_data_bytes
TypeError: can only concatenate str (not "list") to str
2018-11-15 17:35:28,726 werkzeug:_log:88   > INFO: 127.0.0.1 - - [15/Nov/2018 17:35:28] "POST /localagent/v1/push_plate_no HTTP/1.1" 500 -
2018-11-15 17:36:58,138 root:main:195  > CRITICAL: 
 --- Application started & 'main' was called. This is not really Critical. --- 

2018-11-15 17:36:58,139 root:main:202  > INFO: PNS App Services IP Address White List:
2018-11-15 17:36:58,139 root:main:203  > INFO: ['35.162.219.50', '52.77.93.214', '13.228.1.86', '54.169.137.81', '127.0.0.1']
2018-11-15 17:36:58,404 werkzeug:_log:88   > INFO:  * Running on http://0.0.0.0:5001/ (Press CTRL+C to quit)
2018-11-15 17:37:02,166 root:push_plate_no:397  > ERROR: Failed to connect to ftp server using given info host=127.0.0.1 , username=hadi , password=hadi123 ,folder=vehicle_plate , 530-User cannot log in.
 Win32 error:   The user name or password is incorrect. 
 Error details: An error occurred during the authentication process.
530 End
2018-11-15 17:37:02,167 root:push_plate_no:402  > INFO: 
2018-11-15 17:37:02,167 root:push_plate_no:403  > INFO: --- v1_push plate no ---
2018-11-15 17:37:02,167 root:push_plate_no:404  > INFO: Plateno=PUTRAJAYA1231234<<>>Camera_sn=00000000-00000000<<>>Maxpark_camera_id=1000
2018-11-15 17:37:02,167 root:push_plate_no:406  > INFO: Communicating with Comms Module
2018-11-15 17:37:02,167 LA_Commons:calculate_checksum:43   > INFO: Checksum (numerical= 0x6e
2018-11-15 17:37:07,169 PUSH_plate_no:push_plate_no:167  > WARNING: Timeout. Close connection
2018-11-15 17:37:07,169 root:push_plate_no:413  > INFO: response : None
2018-11-15 17:37:07,170 werkzeug:_log:88   > INFO: 127.0.0.1 - - [15/Nov/2018 17:37:07] "POST /localagent/v1/push_plate_no HTTP/1.1" 200 -
2018-11-15 17:46:46,961 root:push_plate_no:397  > ERROR: Failed to connect to ftp server using given info host=127.0.0.1 , username=hadi , password=hadi123 ,folder=vehicle_plate , 530-User cannot log in.
 Win32 error:   The user name or password is incorrect. 
 Error details: An error occurred during the authentication process.
530 End
2018-11-15 17:46:46,961 root:push_plate_no:402  > INFO: 
2018-11-15 17:46:46,961 root:push_plate_no:403  > INFO: --- v1_push plate no ---
2018-11-15 17:46:46,962 root:push_plate_no:404  > INFO: Plateno=PUTRAJAYA1231234<<>>Camera_sn=00000000-00000000<<>>Maxpark_camera_id=1000
2018-11-15 17:46:46,962 root:push_plate_no:406  > INFO: Communicating with Comms Module
2018-11-15 17:46:46,962 LA_Commons:calculate_checksum:43   > INFO: Checksum (numerical= 0x6e
2018-11-15 17:46:51,964 PUSH_plate_no:push_plate_no:167  > WARNING: Timeout. Close connection
2018-11-15 17:46:51,964 root:push_plate_no:413  > INFO: response : None
2018-11-15 17:46:51,965 werkzeug:_log:88   > INFO: 127.0.0.1 - - [15/Nov/2018 17:46:51] "POST /localagent/v1/push_plate_no HTTP/1.1" 200 -
2018-11-15 17:46:56,116 root:push_plate_no:397  > ERROR: Failed to connect to ftp server using given info host=127.0.0.1 , username=hadi , password=hadi123 ,folder=vehicle_plate , 530-User cannot log in.
 Win32 error:   The user name or password is incorrect. 
 Error details: An error occurred during the authentication process.
530 End
2018-11-15 17:46:56,116 root:push_plate_no:402  > INFO: 
2018-11-15 17:46:56,116 root:push_plate_no:403  > INFO: --- v1_push plate no ---
2018-11-15 17:46:56,117 root:push_plate_no:404  > INFO: Plateno=PUTRAJAYA1231234<<>>Camera_sn=00000000-00000000<<>>Maxpark_camera_id=1000
2018-11-15 17:46:56,117 root:push_plate_no:406  > INFO: Communicating with Comms Module
2018-11-15 17:46:56,117 LA_Commons:calculate_checksum:43   > INFO: Checksum (numerical= 0x6e
2018-11-15 17:47:01,129 PUSH_plate_no:push_plate_no:167  > WARNING: Timeout. Close connection
2018-11-15 17:47:01,129 root:push_plate_no:413  > INFO: response : None
2018-11-15 17:47:01,130 werkzeug:_log:88   > INFO: 127.0.0.1 - - [15/Nov/2018 17:47:01] "POST /localagent/v1/push_plate_no HTTP/1.1" 200 -
2018-11-15 17:47:08,316 root:push_plate_no:397  > ERROR: Failed to connect to ftp server using given info host=127.0.0.1 , username=hadi , password=hadi123 ,folder=vehicle_plate , 530-User cannot log in.
 Win32 error:   The user name or password is incorrect. 
 Error details: An error occurred during the authentication process.
530 End
2018-11-15 17:47:08,316 root:push_plate_no:402  > INFO: 
2018-11-15 17:47:08,316 root:push_plate_no:403  > INFO: --- v1_push plate no ---
2018-11-15 17:47:08,316 root:push_plate_no:404  > INFO: Plateno=PUTRAJAYA1231235<<>>Camera_sn=00000000-00000000<<>>Maxpark_camera_id=1000
2018-11-15 17:47:08,316 root:push_plate_no:406  > INFO: Communicating with Comms Module
2018-11-15 17:47:08,317 LA_Commons:calculate_checksum:43   > INFO: Checksum (numerical= 0x6f
2018-11-15 17:47:13,318 PUSH_plate_no:push_plate_no:167  > WARNING: Timeout. Close connection
2018-11-15 17:47:13,318 root:push_plate_no:413  > INFO: response : None
2018-11-15 17:47:13,319 werkzeug:_log:88   > INFO: 127.0.0.1 - - [15/Nov/2018 17:47:13] "POST /localagent/v1/push_plate_no HTTP/1.1" 200 -
2018-11-15 17:47:15,698 root:push_plate_no:397  > ERROR: Failed to connect to ftp server using given info host=127.0.0.1 , username=hadi , password=hadi123 ,folder=vehicle_plate , 530-User cannot log in.
 Win32 error:   The user name or password is incorrect. 
 Error details: An error occurred during the authentication process.
530 End
2018-11-15 17:47:15,698 root:push_plate_no:402  > INFO: 
2018-11-15 17:47:15,698 root:push_plate_no:403  > INFO: --- v1_push plate no ---
2018-11-15 17:47:15,698 root:push_plate_no:404  > INFO: Plateno=PUTRAJAYA1231235<<>>Camera_sn=00000000-00000000<<>>Maxpark_camera_id=1000
2018-11-15 17:47:15,699 root:push_plate_no:406  > INFO: Communicating with Comms Module
2018-11-15 17:47:15,699 LA_Commons:calculate_checksum:43   > INFO: Checksum (numerical= 0x6f
2018-11-15 17:47:20,709 PUSH_plate_no:push_plate_no:167  > WARNING: Timeout. Close connection
2018-11-15 17:47:20,709 root:push_plate_no:413  > INFO: response : None
2018-11-15 17:47:20,710 werkzeug:_log:88   > INFO: 127.0.0.1 - - [15/Nov/2018 17:47:20] "POST /localagent/v1/push_plate_no HTTP/1.1" 200 -
